Workbook

Sheet Business Rules
A1: IREI MVP Build Template — Business Rules
A2: This sheet preserves the NGO B v12 workbook logic and states how it is simplified for the one-time MVP v1 build. Colour coding follows v12: blue=input, black=formula, purple=generated, orange=review, grey=legacy/reference, green=output.
A4: Colour | B4: Meaning | C4: Who may edit? | D4: MVP v1 treatment | E4: Example tabs | F4: Rule
A5: Blue | B5: Writable input zones | C5: Human / AI / analyst | D5: Manual or import data entry | E5: DATA_* input tabs | F5: Only blue cells are user-write zones.
A6: Black / no fill | B6: Live formula cells | C6: No direct edit | D6: Keep formulas live | E6: DATA_METRIC_LONG, DATA_QUALITY_CHECKS | F6: Do not overwrite formulas.
A7: Purple | B7: Generated bridge data | C7: No direct edit unless documented | D7: Formula-generated from inputs | E7: DATA_PROPERTY_MASTER, DATA_DEBT_MASTER | F7: Can be generated by future digital engine.
A8: Orange | B8: Review / unresolved / assumptions | C8: Analyst may update status/note | D8: Used for assumptions and flags | E8: ASSUMPTIONS_FLAGS | F8: Must include reviewer rationale.
A9: Grey | B9: Legacy / reference | C9: Reference only | D9: Not MVP engine | E9: NGO B v12 source workbook | F9: Do not build software from legacy tabs directly.
A10: Green | B10: Output | C10: No direct edit to formulas | D10: Dashboard/readiness output | E10: OUT_STAGE1_READINESS_SNAPSHOT | F10: Output pulls from data and checks.
A13: Rule ID | B13: Area | C13: Business Rule | D13: MVP v1 implementation
A14: BR-MVP-001 | B14: Purpose | C14: MVP v1 is a one-time, semi-manual demonstration product using NGO B / ENF as the pilot case. | D14: Keep scope narrow; do not build a full investor dashboard or SaaS product yet.
A15: BR-MVP-002 | B15: Source hierarchy | C15: NGO B v12 is the business-logic prototype. Tapestry / ENF July 7 is the latest demo source of truth where it supersedes generic NGO B assumptions. | D15: Log every source in STG_SOURCE_INTAKE.
A16: BR-MVP-003 | B16: Build principle | C16: Build the clean template from the MVP-ready parts of v12; do not ask Uygar to rebuild the full legacy workbook. | D16: This template is the build abstraction.
A17: BR-MVP-004 | B17: Input control | C17: Human / AI / analyst may write only in blue input cells or orange assumption-review cells. | D17: Formula cells remain black/no fill; generated bridge fields use purple.
A18: BR-MVP-005 | B18: Live calculations | C18: Metric rows, quality checks, and readiness snapshot must use formulas pulling from data tabs. | D18: No hardcoded output values unless clearly marked as demonstration input.
A19: BR-MVP-006 | B19: Original logic, simplified | C19: Preserve v12 logic pattern: input/source log → canonical DATA tables → checks/metrics → OUT readiness output. | D19: Investor distribution, NAV, IRR, and Stage 2/3 capital pathway logic are deferred.
A20: BR-MVP-007 | B20: Auditability | C20: Every source conflict or manual override must be recorded in ASSUMPTIONS_FLAGS. | D20: Port Moody 245 vs 328 remains a visible flag.
A21: BR-MVP-008 | B21: Outcome | C21: The MVP outcome is OUT_STAGE1_READINESS_SNAPSHOT, not a polished investor summary. | D21: Investor pages may be later presentation layer.
A22: BR-MVP-009 | B22: Template/demo structure | C22: This workbook combines Build 1 template structure and Build 2 NGO B / ENF demo rows. The 17 populated rows are examples, not the fixed future platform shape. | D22: Digital build must support additional organizations and properties using the same DATA_* structure.
A23: Preserved NGO B v12 business-rule excerpt
A24: Original row | B24: Original Business Rules text
A25: 1 | B25: IREI Underwriting Template Prototype
A26: 3 | B26: Business Rules Organized by Epics and User Stories
A27: 5 | B27: 1. Purpose of the Model
A28: 7 | B28: The model is designed to convert non-profit / Indigenous / mission-driven housing organization data into a standardized, auditable underwriting structure.
A29: 9 | B29: It has two purposes:
A30: 11 | B30: 1. Current use: underwrite NGO B’s portfolio using the existing live Excel calculation engine.
A31: 13 | B31: 2. Future platform use: establish the data architecture and business rules for an AI / analyst-assisted IREI underwriting platform.
A32: 15 | B32: The model is not yet a fully automated platform engine. The current financial calculations still rely on legacy NGO B tabs, while the new DATA and OUT layers define the future standardized model structure.
A33: 19 | B33: Epic 1 — Workbook Navigation and User Control
A34: 21 | B34: Business Objective
A35: 23 | B35: Ensure analysts and AI agents understand where to enter data, where formulas live, what not to overwrite, and how to follow the workbook structure.
A36: 25 | B36: Key Tabs
... A64: 81 | B64: Formula and output areas are clearly marked as non-editable.

Sheet 00_CHANGE_LOG
A1: CHANGE LOG — IREI MVP Build Template
A2: Audit trail for extracting/simplifying NGO B v12 into the MVP v1 build template. Keep this sheet current with every workbook revision.
A4: Change ID | B4: Date | C4: Type | D4: Sheet / Range | E4: Issue | F4: Change Made | G4: Assumption Changed? | H4: Calculation Impact | I4: Status | J4: Next Step
A5: CL-001 | B5: 2026-07-07 | C5: Governance | D5: 00_CHANGE_LOG | E5: No workbook-level audit trail existed. | F5: Added change log sheet with change IDs and affected ranges. | G5: No | H5: None; documentation only. | I5: Complete | J5: Use for every future model revision.
A6: CL-002 | B6: 2026-07-07 | C6: Governance | D6: 00_MODEL_CONTROL | E6: Portfolio inclusion logic was embedded in rollup row 8 only. | F6: Added central scope-control sheet and linked rollup toggles to it. | G6: No | H6: No intended output change; BLD_AB remains excluded and all other assets remain included. | I6: Complete | J6: Use this tab for future include/exclude decisions.
A7: CL-003 | B7: 2026-07-07 | C7: Governance | D7: 00_MODEL_CHECKS | E7: No live structural checks tab existed. | F7: Added live checks for scope, register totals, label references, and bucket reconciliation. | G7: No | H7: None; documentation/checking only. | I7: Complete | J7: Expand with debt and development checks in next pass.
A8: CL-004 | B8: 2026-07-07 | C8: Formula Fix | D8: 00_PORTFOLIO_REGISTER!C5:C21 | E8: City lookup matched BLD_ID against property name, causing #N/A results. | F8: Changed lookup to match BLD_ID against Property Summary Tab ID. | G8: No | H8: Register city field now calculates live from Property Summary. | I8: Complete | J8: Review other register columns for full institutionalization.
A9: CL-005 | B9: 2026-07-07 | C9: Formula Addition | D9: 00_PORTFOLIO_REGISTER!D5:I21 | E9: Register had blank units, NOI, lender, and debt-term fields. | F9: Added live formulas for units, 2025/2029/2035 NOI, lender/program, and debt term. | G9: No | H9: Register now ties to Property Summary, property tabs, and Debt Engine. | I9: Complete | J9: Later replace hardcoded bucket and issue narrative with formula-controlled classification.
A10: CL-006 | B10: 2026-07-07 | C10: Formula Fix | D10: 00_PORTFOLIO_REGISTER!E23:G23 | E10: Portfolio total formulas contained #REF!. | F10: Replaced with SUM formulas over live NOI detail rows. | G10: No | H10: Register totals now calculate live. | I10: Complete | J10: Cross-check against portfolio rollup inclusion logic if the register is meant to be scoped.
A11: CL-007 | B11: 2026-07-07 | C11: Formatting Fix | D11: 00_PORTFOLIO SUMMARY!C5 | E11: Current year formula displayed as an Excel serial date. | F11: Changed number format to year/number display. | G11: No | H11: Presentation only. | I11: Complete | J11: None.
A12: CL-008 | B12: 2026-07-07 | C12: Formula Fix | D12: 00_PORTFOLIO ROLLUP!C72 | E12: GAV label referenced rollup toggle instead of cap-rate assumption. | F12: Changed label to reference Exit Cap Rate and format as %. | G12: No | H12: Presentation only; GAV formulas unchanged. | I12: Complete | J12: None.
A13: CL-009 | B13: 2026-07-07 | C13: Formula Fix | D13: 00_PORTFOLIO ROLLUP!C79,E79:Y79,C86,E86:Y86 | E13: Yield labels/markers referenced wrong cells. | F13: Changed labels and STAB. YR. markers to reference stabilization year assumption. | G13: No | H13: Presentation only; yield formulas unchanged. | I13: Complete | J13: None.
A14: CL-010 | B14: 2026-07-07 | C14: Formula Fix | D14: 00_PORTFOLIO ROLLUP!E60:Y60,E75:Y75 | E14: Refi marker rows referenced payout ratio instead of actual event rows. | F14: Changed markers to flag when balloon, loan proceeds, or net refi/gap rows are non-zero. | G14: No | H14: Presentation only; underlying refi rows unchanged. | I14: Complete | J14: Later separate residual funding gaps from equity-return language.
A15: CL-011 | B15: 2026-07-07 | C15: Control Fix | D15: 00_PORTFOLIO SUMMARY!C5; 00_MODEL_CONTROL!B31 | E15: Current year used volatile TODAY() and displayed as a serial date. | F15: Moved selected current year to an explicit control input and linked the summary output to it. | G15: No | H15: Controls display-year selection only; formulas remain live off the selected year. | I15: Complete | J15: Change B31 if a different current-year test is required.
A16: CL-012 | B16: 2026-07-07 | C16: Platform Architecture | D16: 00_PLATFORM_INDEX | E16: No platform architecture layer existed. | F16: Added platform index and model-layer map. | G16: No | H16: Documentation/governance only.
A17: CL-013 | B17: 2026-07-07 | C17: Intake Architecture | D17: STG_SOURCE_INTAKE | E17: Future NGO/Yardi files had no intake log. | F17: Added source intake register. | G17: No | H17: No model output change.
A18: CL-014 | B18: 2026-07-07 | C18: Mapping Architecture | D18: MAP_FIELD_MAPPING | E18: No field mapping layer existed. | F18: Added source-to-canonical field map. | G18: No | H18: No model output change.
A19: CL-015 | B19: 2026-07-07 | C19: Data Architecture | D19: DATA_PROPERTY_MASTER | E19: Property identity was spread across tabs. | F19: Added live canonical property master. | G19: No | H19: Live links; assumptions unchanged.
A20: CL-016 | B20: 2026-07-07 | C20: Data Architecture | D20: DATA_DEBT_MASTER | E20: Debt profile was not normalized. | F20: Added live canonical debt master. | G20: No | H20: Live links; assumptions unchanged.
A21: CL-017 | B21: 2026-07-07 | C21: Model Architecture | D21: DATA_METRIC_LONG | E21: Outputs were property-tab driven. | F21: Added live long-format property-year-metric table for key years. | G21: No | H21: No intended output change.
A22: CL-018 | B22: 2026-07-07 | C22: Checks | D22: DATA_QUALITY_CHECKS | E22: No platform-readiness checks existed. | F22: Added live checks for platform migration. | G22: No | H22: Flags open migration items.
A23: CL-019 | B23: 2026-07-07 | C23: Output | D23: OUT_PLATFORM_READINESS | E23: No readiness dashboard existed. | F23: Added live platform-readiness dashboard. | G23: No | H23: No model output change.
A24: CL-020 | B24: 2026-07-07 | C24: Calculation Control | D24: Workbook calculation settings | E24: New sheets contain formulas. | F24: Confirmed automatic full recalculation on open. | G24: No | H24: Keeps formulas live.
A25: CL-021 | B25: 2026-07-07 | C25: Model Architecture | D25: DATA_ASSET_CLASSIFICATION | E25: No single authoritative asset-classification table existed. | F25: Added live authoritative classification table for Excluded / Stable / Refi Watch / Workout / New Build. | G25: No | H25: No assumption changes; classification is formula-linked to existing model data. | I25: Complete | J25: Use as single source of truth for classification.
A26: CL-022 | B26: 2026-07-07 | C26: Formula Link | D26: 00_PORTFOLIO SUMMARY!C10:C26 | E26: Portfolio Summary classified assets independently. | F26: Redirected Bucket column to Final Classification from DATA_ASSET_CLASSIFICATION. | G26: No | H26: Output classification now uses single source of truth. | I26: Complete | J26: Do not hardcode classification in Summary.
A27: CL-023 | B27: 2026-07-07 | C27: Formula Link | D27: 00_MODEL_CONTROL!F5:F21 | E27: Model Control Summary Bucket was not authoritative. | F27: Linked Summary Bucket to DATA_ASSET_CLASSIFICATION final classification. | G27: No | H27: Control sheet now uses classification authority. | I27: Complete | J27: Use F for final classification.
A28: CL-024 | B28: 2026-07-07 | C28: Formula Link | D28: 00_PORTFOLIO_REGISTER!J5:J21 | E28: Register Bucket was hardcoded manual text and remained a second source. | F28: Replaced manual bucket text with formula pulling final classification and mapping it to controlled register buckets. | G28: No | H28: Register now follows authority table; no model assumptions changed. | I28: Complete | J28: Protect from manual overwrite.
A29: CL-025 | B29: 2026-07-07 | C29: Governance | D29: DATA_ASSET_CLASSIFICATION!AA7:AB13 | E29: Register bucket mapping was embedded in text rather than governed. | F29: Added visible classification-to-register-bucket mapping table used by Register formulas. | G29: No | H29: Improves auditability; classification values stay live. | I29: Complete | J29: Edit mapping table only if bucket taxonomy changes.
A30: CL-MVP-001 | B30: 2026-07-10 | C30: MVP Extraction | D30: Workbook | E30: Previous MVP template did not preserve v12 build rules, colour coding, live calculations, or change log sufficiently. | F30: Rebuilt as a clean v12-aligned template with Business Rules, input-control map, source log, canonical DATA tabs, formulas, quality checks, and readiness output. | G30: No | H30: Architecture and presentation only; formulas remain live. | I30: Complete | J30: Use this v0.2 template for Uygar handoff.
A31: CL-MVP-002 | B31: 2026-07-10 | C31: Governance | D31: Business Rules | E31: MVP scope needed to be clearly separated from investor dashboard scope. | F31: Added MVP-specific rules while preserving original v12 business-rule excerpt. | G31: No | H31: Documentation only. | I31: Complete | J31: Keep this sheet as first-read tab.
A32: CL-MVP-003 | B32: 2026-07-10 | C32: Input Control | D32: INPUT_CONTROL_MAP; DATA_* | E32: Writable versus generated cells needed to match v12 colour discipline. | F32: Applied blue input zones, purple generated bridge cells, orange review flags, green output, grey legacy/reference indicators. | G32: No | H32: Improves auditability; no calculation logic change. | I32: Complete | J32: Use blue cells for analyst/AI input.
A33: CL-MVP-004 | B33: 2026-07-10 | C33: Live Calculation | D33: DATA_METRIC_LONG; DATA_QUALITY_CHECKS; OUT_STAGE1_READINESS_SNAPSHOT | E33: Output needed to be formula-driven, not static. | F33: Added live formulas for property count, included count, units, new projects, source flags, revenue, expenses, NOI, debt service, AFFO, DSCR, and readiness status. | G33: No | H33: Output updates when input tabs change. | I33: Complete | J33: Review formulas before digital translation.
A34: CL-MVP-005 | B34: 2026-07-10 | C34: Source Conflict | D34: ASSUMPTIONS_FLAGS | E34: Port Moody unit count remains 245 vs 328. | F34: Added explicit unresolved issue flag for Port Moody. | G34: No | H34: Does not change final source assumption; flag remains open. | I34: Open | J34: Confirm with ENF before final demo.
A35: 2026-07-10 | B35: v0.3 | C35: DATA_DEBT_MASTER | D35: Fixed omission | E35: Restored legacy mortgage principal/rate/amortization/source annual debt service from v12/v0.1 extraction for included existing properties. | F35: Kelly review / ChatGPT | G35: OpenAI | H35: High | I35: Completed | J35: Corrects DSCR/AFFO blind spot.
A36: 2026-07-10 | B36: v0.3 | C36: DATA_QUALITY_CHECKS | D36: Formula control | E36: Tightened QC-MVP-006 to count included rows still marked Partial instead of passing when any debt row is Ready. | F36: Kelly review / ChatGPT | G36: OpenAI | H36: High | I36: Completed | J36: Prevents silent debt completeness gaps.
... A40: 38 | B40: 2026-07-10 | C40: v0.4 | D40: DATA_QUALITY_CHECKS!C7:E7 | E40: QC-MVP-001 type mismatch risk | F40: Changed expected property count to numeric 17 and made the status formula compare D7 against VALUE(C7), so the row-count check does not show REVIEW because of text-vs-number typing. | G40: No | H40: No calculation logic change; prevents a false REVIEW flag on a clean property count. | I40: Completed | J40: Use v0.4 for Uygar handoff.

Sheet 00_PLATFORM_INDEX
A1: 00_PLATFORM_INDEX — IREI MVP v1 Build Map
A2: Use this index to understand which tabs are inputs, generated bridge data, checks, and output. This preserves the v12 layer logic in a simplified MVP form.
A4: Layer | B4: Tab | C4: Role | D4: Edit rule | E4: Colour | F4: Feeds / Uses | G4: MVP status | H4: Notes
A5: Governance | B5: Business Rules | C5: Business rules and colour-code standard | D5: Read only except rule updates | E5: Grey | F5: All tabs | G5: Required | H5: Start here.
A6: Governance | B6: 00_CHANGE_LOG | C6: Audit trail | D6: Update on every revision | E6: Grey | F6: Workbook governance | G6: Required | H6: Preserved from v12 plus MVP changes.
A7: Governance | B7: INPUT_CONTROL_MAP | C7: Where analyst/AI may write | D7: Read before editing | E7: Grey | F7: All DATA tabs | G7: Required | H7: Defines blue cells.
A8: Source intake | B8: STG_SOURCE_INTAKE | C8: Source file log | D8: Blue input | E8: Blue | F8: Data confidence / source hierarchy | G8: Required | H8: Tapestry and v12 logged.
A9: Mapping | B9: MAP_FIELD_MAPPING | C9: Source-to-canonical mapping | D9: Review/update as needed | E9: Orange/Purple | F9: Digital build schema | G9: Required | H9: Shows future platform fields.
A10: Canonical data | B10: DATA_PROPERTY_MASTER | C10: One row per property/project | D10: Blue input + purple generated checks | E10: Blue/Purple | F10: Metrics and snapshot | G10: Required | H10: v12 property list extracted.
A11: Canonical data | B11: DATA_UNIT_MIX | C11: Unit mix and affordability bands | D11: Blue input | E11: Blue | F11: Affordability metrics | G11: Required | H11: Blank/template + demo-ready.
A12: Canonical data | B12: DATA_OPERATING_ACTUALS | C12: Operating budgets/actuals/projections | D12: Blue input | E12: Blue | F12: Financial metrics | G12: Required | H12: Keep line items standardized.
A13: Canonical data | B13: DATA_DEBT_MASTER | C13: Debt/mortgage/financing records | D13: Blue input + formula checks | E13: Blue/Purple | F13: DSCR / debt snapshot | G13: Required | H13: New project assumptions can use Tapestry.
A14: Canonical data | B14: DATA_CASH_RESERVES | C14: Cash/reserve availability | D14: Blue input | E14: Blue | F14: Readiness flags | G14: Required | H14: Restricted cash remains review item.
A15: Canonical data | B15: DATA_AGREEMENTS | C15: Agreements/covenants/restrictions | D15: Blue input | E15: Blue | F15: Mission/restriction review | G15: Required placeholder | H15: May be incomplete in MVP.
... A19: Quality layer | B19: DATA_QUALITY_CHECKS | C19: Live checks and status | D19: Formula-driven | E19: Black/Purple | F19: Snapshot | G19: Required | H19: Open items are roadmap/checks.
A20: BUILD NOTE | B20: Workbook-level instruction | C20: Template + demo combined | D20: The 17 NGO B / ENF rows are demo seed data only. Digital product must treat the DATA_* tabs as reusable template structures, not fixed ENF-only tables.

Sheet INPUT_CONTROL_MAP
A1: INPUT_CONTROL_MAP — MVP v1 analyst / AI write map
A2: Rule: blue cells are writable input zones. Black/no fill cells are formulas. Purple = generated bridge data. Orange = review/assumption. Green = output. Grey = legacy/reference.
A4: Zone | B4: Tab | C4: Range / Columns | D4: Field / Purpose | E4: Write Permission | F4: Table Exists? | G4: Feeds To | H4: Notes
A5: PRIMARY INPUT | B5: STG_SOURCE_INTAKE | C5: A7:J206 | D5: Source file log: file name, version, role, source priority, review status | E5: Human / AI may write blue cells | F5: Yes | G5: SOURCE_LOG and readiness snapshot | H5: First place to document NGO package.
A6: PRIMARY INPUT | B6: DATA_PROPERTY_MASTER | C6: A7:J206; N:Q | D6: Property identity, status, units, source confidence, notes | E6: Human / AI may write blue cells | F6: Yes | G6: DATA_METRIC_LONG; snapshot | H6: In v12 this was generated; in MVP template this is the primary property-entry table.
A7: PRIMARY INPUT | B7: DATA_UNIT_MIX | C7: A7:O206 | D7: Unit mix / affordability bands / rent categories | E7: Human / AI may write blue cells | F7: Yes | G7: Mission/affordability metrics | H7: May remain partial for MVP.
A8: PRIMARY INPUT | B8: DATA_RENT_ROLL | C8: A7:M206 | D8: Rent roll / unit group rent detail | E8: Human / AI may write blue cells | F8: Yes | G8: Future rent engine | H8: Optional for MVP if operating forecast is enough.
A9: PRIMARY INPUT | B9: DATA_OPERATING_ACTUALS | C9: A7:M306 | D9: Operating budgets/actuals by property-year-line item | E9: Human / AI may write blue cells | F9: Yes | G9: Financial snapshot | H9: Core MVP input.
A10: PRIMARY INPUT | B10: DATA_DEBT_MASTER | C10: A7:O206 | D10: Debt, mortgage, financing, annual debt service | E10: Human / AI may write blue cells; formula checks in generated columns | F10: Yes | G10: DSCR/debt metrics | H10: Use Tapestry for four new/future projects.
A11: PRIMARY INPUT | B11: DATA_CASH_RESERVES | C11: A7:L206 | D11: Opening/closing cash, restricted/unrestricted, reserve availability | E11: Human / AI may write blue cells | F11: Yes | G11: Readiness flags and cash metrics | H11: Restricted cash can remain unknown.
A12: PRIMARY INPUT | B12: DATA_AGREEMENTS | C12: A7:N206 | D12: Operating agreements, covenants, affordability and refinance restrictions | E12: Human / AI may write blue cells | F12: Yes | G12: Mission/restriction review | H12: Placeholder acceptable in MVP.
A13: PRIMARY INPUT | B13: DATA_CAPITAL_NEEDS | C13: A7:N206 | D13: Capital repairs, reserves, deferred maintenance, funded/unfunded amount | E13: Human / AI may write blue cells | F13: Yes | G13: Capital needs readiness | H13: Placeholder acceptable in MVP.
A14: CONTROLLED REVIEW | B14: ASSUMPTIONS_FLAGS | C14: A7:J206 | D14: Assumptions, source conflicts, unresolved issues, reviewer notes | E14: Human / AI may write orange review cells | F14: Yes | G14: Quality checks and snapshot | H14: Every override/conflict must be logged.
A15: GENERATED DATA | B15: DATA_METRIC_LONG | C15: A7:H100 | D15: Standardized metrics calculated from DATA tabs | E15: Do not manually edit formula cells | F15: Yes | G15: OUT_STAGE1_READINESS_SNAPSHOT | H15: Live formulas translate source data into IREI metrics.
... A18: LEGACY REFERENCE | B18: NGO B v12 workbook | C18: External file | D18: Business logic prototype and original calculation engine | E18: Reference only | F18: Yes | G18: Build logic reference | H18: Do not build the digital product directly from v12.

Sheet STG_SOURCE_INTAKE
A1: STG_SOURCE_INTAKE — Source Package Log
A2: Blue cells are writable. Log source files before entering data. Source hierarchy matters for auditability.
A4: Source_ID | B4: File / Source Name | C4: Source Type | D4: Version / Date | E4: Priority | F4: Used For | G4: Review Status | H4: Owner | I4: Notes | J4: Supersedes / Related
A5: SRC-001 | B5: NGO_B_Modeling_2026-07-07 Structural change v12 final(2).xlsx | C5: IREI prototype workbook | D5: 2026-07-07 | E5: Reference / architecture | F5: Business logic, property structure, DATA/OUT layer pattern | G5: Reviewed for MVP extraction | H5: Kelly / IREI | I5: Use as source workbook, not as digital build architecture. | J5: Earlier v12 working model
A6: SRC-002 | B6: 260707 ENFHS 800 CD Tapestry Financial Model v.7.xlsx | C6: ENF / Tapestry source model | D6: 2026-07-07 | E6: Primary demo source | F6: Latest ENF assumptions for demonstration case | G6: Partial review | H6: Kelly / IREI | I6: Primary source where it supersedes generic NGO B assumptions. | J6: Earlier generic assumptions
A7: SRC-003 | B7: 260707 ENFHS Building Amortization and Mortgage Schedule v.4.xlsx | C7: Debt schedule | D7: 2026-07-07 | E7: Supporting debt detail | F7: Principal/interest timing, amortization, mortgage schedule | G7: Partial review | H7: Kelly / IREI | I7: Use for debt timing where Tapestry needs support. | J7: Debt assumptions in v12
A8: SRC-004 | B8: 260707 ENFHS 10 YR FINANCIAL PROJECT BOND VERSION V. 15.xlsx | C8: Project bond model | D8: 2026-07-07 | E8: Supporting reference | F8: Project/bond/cash flow context | G8: Partial review | H8: Kelly / IREI | I8: Reference only unless source hierarchy says otherwise. | J8: Tapestry detail
A9: SRC-005 | B9: ENF confirmation email | C9: External confirmation | D9: Pending | E9: Targeted confirmation only | F9: Port Moody 245 vs 328 unit count | G9: Open | H9: ENF | I9: Ask only targeted question; do not ask ENF to rebuild model. | J9: Source conflict flag

Sheet MAP_FIELD_MAPPING
A1: MAP_FIELD_MAPPING — Source to Canonical MVP Fields
A2: Shows how NGO source material maps into the simplified digital MVP template. Purple rows are generated/structured fields; orange rows require review.
A4: Map_ID | B4: Source / Document Field | C4: Canonical Tab | D4: Canonical Field | E4: Required for MVP? | F4: Current MVP Source | G4: Status | H4: Notes
A5: MAP-001 | B5: Property name / project name | C5: DATA_PROPERTY_MASTER | D5: Property_Name | E5: Yes | F5: NGO B v12 property master | G5: Live | H5: One row per property/project.
A6: MAP-002 | B6: Property ID / tab ID | C6: DATA_PROPERTY_MASTER | D6: Property_ID | E6: Yes | F6: NGO B v12 | G6: Live | H6: Preserves v12 BLD_* identifiers for traceability.
A7: MAP-003 | B7: Included / excluded scope | C7: DATA_PROPERTY_MASTER | D7: Included? | E7: Yes | F7: v12 model control | G7: Live | H7: Alma Blackwell remains excluded unless changed.
A8: MAP-004 | B8: Unit count | C8: DATA_PROPERTY_MASTER | D8: Modeled_Unit_Count | E8: Yes | F8: v12 + Tapestry where updated | G8: Review | H8: Port Moody 245 vs 328 unresolved; 800 Commercial source update should be documented.
A9: MAP-005 | B9: Affordability / unit bands | C9: DATA_UNIT_MIX | D9: Affordability_Band; Unit_Count | E9: Yes, if available | F9: Tapestry / rent roll / NGO data | G9: Partial | H9: Can be partial in MVP.
A10: MAP-006 | B10: Operating budget / actuals | C10: DATA_OPERATING_ACTUALS | D10: IREI_Category; Amount | E10: Yes | F10: Tapestry / budgets | G10: Partial | H10: Core financial snapshot input.
A11: MAP-007 | B11: Mortgage / debt schedule | C11: DATA_DEBT_MASTER | D11: Principal; Rate; Amortization; Debt Service | E11: Yes | F11: Tapestry + amortization schedule | G11: Partial | H11: Use latest Tapestry assumptions for four projects.
A12: MAP-008 | B12: Cash balance / reserves | C12: DATA_CASH_RESERVES | D12: Restricted / unrestricted / available flags | E12: Yes | F12: Tapestry / financials | G12: Review | H12: Restricted cash may remain unknown.
A13: MAP-009 | B13: Capital plan / BCA | C13: DATA_CAPITAL_NEEDS | D13: Estimated cost; timing; funded status | E13: Placeholder | F13: Not fully available | G13: Open | H13: MVP should flag the gap, not hide it.
A14: MAP-010 | B14: Operating agreements / covenants | C14: DATA_AGREEMENTS | D14: Restriction fields | E14: Placeholder | F14: Not fully reviewed | G14: Open | H14: Mission/restriction review remains partial.
A15: MAP-011 | B15: Quality checks | C15: DATA_QUALITY_CHECKS | D15: Status | E15: Yes | F15: Formulas | G15: Live | H15: Calculates from source logs and flags.
A16: MAP-012 | B16: Readiness outcome | C16: OUT_STAGE1_READINESS_SNAPSHOT | D16: Overall status | E16: Yes | F16: Formulas | G16: Live | H16: MVP final output.

Sheet DATA_PROPERTY_MASTER
A1: DATA_PROPERTY_MASTER — MVP Property / Project Master
A2: Blue cells are analyst/AI input. Purple columns are generated checks. Extracted from NGO B v12 and simplified for the MVP template.
A6: Property_ID | B6: Property_Name | C6: City | D6: Status | E6: Included? | F6: Final Classification | G6: Register Bucket Mapping | H6: Total Units | I6: Modeled Unit Count | J6: Alternate Unit Count | K6: Unit Conflict? | L6: Start Year | M6: Lender / Program | N6: Source Confidence | O6: Source Document ID | P6: Review Note | Q6: Data Status
A7: BLD_AB | B7: Alma Blackwell | C7: Vancouver | D7: Active | E7: No | F7: Excluded | G7: Bucket 0 · Excluded | H7: 46 | I7: 46 | K7: =IF(J7="","No",IF(I7=J7,"No","Yes")) -> No | L7: 2025 | M7: N/A | N7: High | O7: SRC-001 | Q7: =IF(A7="","",IF(K7="Yes","Review",IF(COUNTA(A7:I7)>=8,"Ready","Partial"))) -> Ready
A8: BLD_AC | B8: Antkiw Court | C8: Vancouver | D8: Active | E8: Yes | F8: Stable | G8: Bucket 2 · Legacy | H8: 21 | I8: 21 | K8: =IF(J8="","No",IF(I8=J8,"No","Yes")) -> No | L8: 2025 | M8: BCHMC/NPAT | N8: High | O8: SRC-001 | Q8: =IF(A8="","",IF(K8="Yes","Review",IF(COUNTA(A8:I8)>=8,"Ready","Partial"))) -> Ready
A9: BLD_BT | B9: Beatrice Terrace | C9: Vancouver | D9: Active | E9: Yes | F9: Stable | G9: Bucket 2 · Legacy | H9: 18 | I9: 18 | K9: =IF(J9="","No",IF(I9=J9,"No","Yes")) -> No | L9: 2025 | M9: BCHMC/NPAT | N9: High | O9: SRC-001 | Q9: =IF(A9="","",IF(K9="Yes","Review",IF(COUNTA(A9:I9)>=8,"Ready","Partial"))) -> Ready
A10: BLD_CH | B10: Capilano House | C10: DNV | D10: Active | E10: Yes | F10: Stable | G10: Bucket 2 · Legacy | H10: 64 | I10: 64 | K10: =IF(J10="","No",IF(I10=J10,"No","Yes")) -> No | L10: 2025 | M10: N/A | N10: High | O10: SRC-001 | Q10: =IF(A10="","",IF(K10="Yes","Review",IF(COUNTA(A10:I10)>=8,"Ready","Partial"))) -> Ready
A11: BLD_CC | B11: Constance Court | C11: Vancouver | D11: Active | E11: Yes | F11: Refi Watch | G11: Bucket 2 · Legacy | H11: 34 | I11: 34 | K11: =IF(J11="","No",IF(I11=J11,"No","Yes")) -> No | L11: 2025 | M11: BCHMC | N11: High | O11: SRC-001 | Q11: =IF(A11="","",IF(K11="Yes","Review",IF(COUNTA(A11:I11)>=8,"Ready","Partial"))) -> Ready
A12: BLD_EA | B12: Evergreen Apartments | C12: New Westminster | D12: Active | E12: Yes | F12: Refi Watch | G12: Bucket 2 · Legacy | H12: 61 | I12: 61 | K12: =IF(J12="","No",IF(I12=J12,"No","Yes")) -> No | L12: 2025 | M12: Vancity | N12: High | O12: SRC-001 | Q12: =IF(A12="","",IF(K12="Yes","Review",IF(COUNTA(A12:I12)>=8,"Ready","Partial"))) -> Ready
A13: BLD_EE | B13: Evelyn Estates | C13: Surrey | D13: Active | E13: Yes | F13: Refi Watch | G13: Bucket 2 · Legacy | H13: 36 | I13: 36 | K13: =IF(J13="","No",IF(I13=J13,"No","Yes")) -> No | L13: 2025 | M13: BCHMC | N13: High | O13: SRC-001 | Q13: =IF(A13="","",IF(K13="Yes","Review",IF(COUNTA(A13:I13)>=8,"Ready","Partial"))) -> Ready
A14: BLD_JP | B14: Jessica Place | C14: Surrey | D14: Active | E14: Yes | F14: Refi Watch | G14: Bucket 2 · Legacy | H14: 40 | I14: 40 | K14: =IF(J14="","No",IF(I14=J14,"No","Yes")) -> No | L14: 2025 | M14: BCHMC | N14: High | O14: SRC-001 | Q14: =IF(A14="","",IF(K14="Yes","Review",IF(COUNTA(A14:I14)>=8,"Ready","Partial"))) -> Ready
A15: BLD_MH | B15: Margaret Heights | C15: CNV | D15: Active | E15: Yes | F15: Refi Watch | G15: Bucket 2 · Legacy | H15: 19 | I15: 19 | K15: =IF(J15="","No",IF(I15=J15,"No","Yes")) -> No | L15: 2025 | M15: BCHMC | N15: High | O15: SRC-001 | Q15: =IF(A15="","",IF(K15="Yes","Review",IF(COUNTA(A15:I15)>=8,"Ready","Partial"))) -> Ready
A16: BLD_MM | B16: Murray Manor | C16: Burnaby | D16: Active | E16: Yes | F16: Refi Watch | G16: Bucket 2 · Legacy | H16: 47 | I16: 47 | K16: =IF(J16="","No",IF(I16=J16,"No","Yes")) -> No | L16: 2025 | M16: Vancity | N16: High | O16: SRC-001 | Q16: =IF(A16="","",IF(K16="Yes","Review",IF(COUNTA(A16:I16)>=8,"Ready","Partial"))) -> Ready
A17: BLD_NT | B17: Natalia Terrace | C17: Vancouver | D17: Active | E17: Yes | F17: Refi Watch | G17: Bucket 2 · Legacy | H17: 40 | I17: 40 | K17: =IF(J17="","No",IF(I17=J17,"No","Yes")) -> No | L17: 2025 | M17: BCHMC | N17: High | O17: SRC-001 | Q17: =IF(A17="","",IF(K17="Yes","Review",IF(COUNTA(A17:I17)>=8,"Ready","Partial"))) -> Ready
A18: BLD_NG | B18: Newton Green | C18: Surrey | D18: Active | E18: Yes | F18: Refi Watch | G18: Bucket 2 · Legacy | H18: 49 | I18: 49 | K18: =IF(J18="","No",IF(I18=J18,"No","Yes")) -> No | L18: 2025 | M18: CMLS | N18: High | O18: SRC-001 | Q18: =IF(A18="","",IF(K18="Yes","Review",IF(COUNTA(A18:I18)>=8,"Ready","Partial"))) -> Ready
... A21: BLD_PS | B21: 450 Pacific Street | C21: Vancouver | D21: New Dev | E21: Yes | F21: New Build | G21: Bucket 1 · New Build | H21: 91 | I21: 91 | K21: =IF(J21="","No",IF(I21=J21,"No","Yes")) -> No | L21: 2028 | M21: BCH CHF | N21: High | O21: SRC-001 | Q21: =IF(A21="","",IF(K21="Yes","Review",IF(COUNTA(A21:I21)>=8,"Ready","Partial"))) -> Ready
A22: BLD_PM | B22: The Creek, Port Moody | C22: Port Moody | D22: New Dev | E22: Yes | F22: New Build | G22: Bucket 1 · New Build | H22: 328 | I22: 328 | J22: 245 | K22: =IF(J22="","No",IF(I22=J22,"No","Yes")) -> Yes | L22: 2027 | M22: CMHC | N22: Conflict | O22: SRC-001 | P22: Port Moody source conflict: v12 shows 328; Tapestry/ENF appears to show 245 modeled rental units. Confirm with ENF. | Q22: =IF(A22="","",IF(K22="Yes","Review",IF(COUNTA(A22:I22)>=8,"Ready","Partial"))) -> Review
A23: BLD_CD | B23: 800 Commercial Drive | C23: Vancouver | D23: New Dev | E23: Yes | F23: New Build | G23: Bucket 1 · New Build | H23: 93 | I23: 93 | J23: 108 | K23: =IF(J23="","No",IF(I23=J23,"No","Yes")) -> Yes | L23: 2029 | M23: BCH CHF | N23: Review | O23: SRC-001 | P23: Tapestry/ENF appears to show 108 total units / 107 residential + 1 commercial; v12 shows 93. Use source hierarchy before final demo. | Q23: =IF(A23="","",IF(K23="Yes","Review",IF(COUNTA(A23:I23)>=8,"Ready","Partial"))) -> Review

Sheet DATA_UNIT_MIX
A1: DATA_UNIT_MIX — Unit Mix / Affordability Inputs
A2: Blue cells are writable input zones. This tab mirrors v12 canonical input logic and remains separate from live calculations until mapped.
A6: Record_ID | B6: Property_ID | C6: Property_Name | D6: Unit_Group_ID | E6: Bedroom_Type | F6: Unit_Type | G6: Affordability_Band | H6: Unit_Count | I6: Affordable_Units | J6: Market_Units | K6: Supportive_Units | L6: Avg_Current_Rent | M6: Avg_Market_Rent | N6: Source_File_ID | O6: Review_Status
A7: UM-001 | B7: BLD_CD | C7: 800 Commercial Drive | D7: CD-Deep | E7: Mixed | F7: Residential | G7: Deep Subsidy | H7: 21 | I7: 21 | J7: 0 | K7: 0 | N7: SRC-002 | O7: Partial
A8: UM-002 | B8: BLD_CD | C8: 800 Commercial Drive | D8: CD-Subsidy | E8: Mixed | F8: Residential | G8: Subsidized | H8: 54 | I8: 54 | J8: 0 | K8: 0 | N8: SRC-002 | O8: Partial
A9: UM-003 | B9: BLD_CD | C9: 800 Commercial Drive | D9: CD-Market | E9: Mixed | F9: Residential | G9: Market | H9: 32 | I9: 0 | J9: 32 | K9: 0 | N9: SRC-002 | O9: Partial
A10: UM-004 | B10: BLD_CD | C10: 800 Commercial Drive | D10: CD-Commercial | E10: Commercial | F10: Commercial | G10: Commercial | H10: 1 | I10: 0 | J10: 1 | K10: 0 | N10: SRC-002 | O10: Partial
A11: UM-005 | B11: BLD_PM | C11: The Creek, Port Moody | D11: PM-SourceConflict | E11: Mixed | F11: Residential | G11: TBD | H11: 245 | N11: SRC-002 | O11: Conflict: confirm 245 vs 328

Sheet DATA_RENT_ROLL
A1: DATA_RENT_ROLL — Optional Rent Roll Detail
A2: Blue cells are writable. MVP v1 can work from operating forecast if detailed rent roll is unavailable.
A6: Record_ID | B6: Property_ID | C6: Property_Name | D6: Rent_Record_Level | E6: Unit_ID_or_Group | F6: Bedroom_Type | G6: Unit_Type | H6: Unit_Count | I6: Tenant_Status | J6: Vacancy_Status | K6: Current_Monthly_Rent | L6: Market_Monthly_Rent | M6: Source_File_ID

Sheet DATA_OPERATING_ACTUALS
A1: DATA_OPERATING_ACTUALS — Operating Budgets / Actuals / Forecasts
A2: Blue cells are writable. Standardize source lines into IREI categories for live MVP metrics.
A6: Record_ID | B6: Property_ID | C6: Property_Name | D6: Fiscal_Year | E6: Period | F6: Scenario | G6: Actual_Budget_Projection | H6: Source_Line_Item | I6: IREI_Category | J6: Amount | K6: Cash_or_Accrual | L6: Source_File_ID | M6: Review_Status
A7: OP-001 | B7: PORTFOLIO | C7: Portfolio-level | D7: 2026 | E7: Annual | F7: Base | G7: Projection | H7: Total operating revenue | I7: Revenue | J7: 17600000 | K7: Accrual | L7: SRC-002 | M7: Demo
A8: OP-002 | B8: PORTFOLIO | C8: Portfolio-level | D8: 2026 | E8: Annual | F8: Base | G8: Projection | H8: Total operating expenses | I8: Operating Expense | J8: 8300000 | K8: Accrual | L8: SRC-002 | M8: Demo
A9: OP-003 | B9: PORTFOLIO | C9: Portfolio-level | D9: 2026 | E9: Annual | F9: Base | G9: Projection | H9: Replacement reserve / reserve deduction | I9: Reserve Deduction | J9: 0 | K9: Accrual | L9: SRC-002 | M9: Placeholder

Sheet DATA_DEBT_MASTER
A1: DATA_DEBT_MASTER — Debt / Mortgage / Financing Inputs
A2: Blue cells are writable. Purple columns are formula checks. Use Tapestry / ENF for updated demo assumptions where it supersedes v12 generic assumptions.
A6: Debt_ID | B6: Property_ID | C6: Property_Name | D6: Included? | E6: Debt_Type | F6: Lender / Program | G6: Principal_Amount | H6: Interest_Rate | I6: Term_Years | J6: Amortization_Years | K6: Annual_Principal_Calc | L6: Annual_Interest_Calc | M6: Annual_Debt_Service | N6: Source_Annual_Debt_Service | O6: Source_File_ID | P6: Review_Status | Q6: Debt_Status | R6: Notes
A7: DEBT-001 | B7: BLD_AB | C7: Alma Blackwell | D7: No | E7: Mortgage / Financing | F7: N/A | K7: =IF(N7<>"","",IF(AND(G7<>"",H7<>"",J7<>""),ROUND(PPMT(H7,1,J7,-G7),0),"")) | L7: =IF(N7<>"","",IF(AND(G7<>"",H7<>""),ROUND(G7*H7,0),"")) | M7: =IF(N7<>"",N7,IF(AND(G7<>"",H7<>"",J7<>""),ROUND(PMT(H7,J7,-G7),0),"")) | O7: SRC-001 | P7: From v12 / review | Q7: =IF(A7="","",IF(D7="No","Excluded",IF(AND(OR(F7="N/A",E7="No Debt / N/A"),G7=""),"No Debt / N/A",IF(M7<>"","Ready","Partial")))) -> Excluded | R7: Excluded from analysis.
A8: DEBT-002 | B8: BLD_AC | C8: Antkiw Court | D8: Yes | E8: Mortgage / Financing | F8: BCHMC/NPAT | G8: 794745.17 | H8: 0.04024 | J8: 22 | K8: =IF(N8<>"","",IF(AND(G8<>"",H8<>"",J8<>""),ROUND(PPMT(H8,1,J8,-G8),0),"")) | L8: =IF(N8<>"","",IF(AND(G8<>"",H8<>""),ROUND(G8*H8,0),"")) | M8: =IF(N8<>"",N8,IF(AND(G8<>"",H8<>"",J8<>""),ROUND(PMT(H8,J8,-G8),0),"")) -> 54330.12 | N8: 54330.12 | O8: SRC-001 | P8: From v12 Property Summary | Q8: =IF(A8="","",IF(D8="No","Excluded",IF(AND(OR(F8="N/A",E8="No Debt / N/A"),G8=""),"No Debt / N/A",IF(M8<>"","Ready","Partial")))) -> Ready | R8: Legacy mortgage data restored from v12 / v0.1 extraction.
A9: DEBT-003 | B9: BLD_BT | C9: Beatrice Terrace | D9: Yes | E9: Mortgage / Financing | F9: BCHMC/NPAT | G9: 1617334.9 | H9: 0.04024 | J9: 22 | K9: =IF(N9<>"","",IF(AND(G9<>"",H9<>"",J9<>""),ROUND(PPMT(H9,1,J9,-G9),0),"")) | L9: =IF(N9<>"","",IF(AND(G9<>"",H9<>""),ROUND(G9*H9,0),"")) | M9: =IF(N9<>"",N9,IF(AND(G9<>"",H9<>"",J9<>""),ROUND(PMT(H9,J9,-G9),0),"")) -> 110563.68 | N9: 110563.68 | O9: SRC-001 | P9: From v12 Property Summary | Q9: =IF(A9="","",IF(D9="No","Excluded",IF(AND(OR(F9="N/A",E9="No Debt / N/A"),G9=""),"No Debt / N/A",IF(M9<>"","Ready","Partial")))) -> Ready | R9: Legacy mortgage data restored from v12 / v0.1 extraction.
A10: DEBT-004 | B10: BLD_CH | C10: Capilano House | D10: Yes | E10: No Debt / N/A | F10: N/A | K10: =IF(N10<>"","",IF(AND(G10<>"",H10<>"",J10<>""),ROUND(PPMT(H10,1,J10,-G10),0),"")) | L10: =IF(N10<>"","",IF(AND(G10<>"",H10<>""),ROUND(G10*H10,0),"")) | M10: =IF(N10<>"",N10,IF(AND(G10<>"",H10<>"",J10<>""),ROUND(PMT(H10,J10,-G10),0),"")) | O10: SRC-001 | P10: From v12 / review | Q10: =IF(A10="","",IF(D10="No","Excluded",IF(AND(OR(F10="N/A",E10="No Debt / N/A"),G10=""),"No Debt / N/A",IF(M10<>"","Ready","Partial")))) -> No Debt / N/A | R10: No mortgage terms in v12 source extract; marked No Debt / N/A rather than missing.
A11: DEBT-005 | B11: BLD_CC | C11: Constance Court | D11: Yes | E11: Mortgage / Financing | F11: BCHMC | G11: 274036.81 | H11: 0.0423 | J11: 3 | K11: =IF(N11<>"","",IF(AND(G11<>"",H11<>"",J11<>""),ROUND(PPMT(H11,1,J11,-G11),0),"")) | L11: =IF(N11<>"","",IF(AND(G11<>"",H11<>""),ROUND(G11*H11,0),"")) | M11: =IF(N11<>"",N11,IF(AND(G11<>"",H11<>"",J11<>""),ROUND(PMT(H11,J11,-G11),0),"")) -> 178507.8 | N11: 178507.8 | O11: SRC-001 | P11: From v12 Property Summary | Q11: =IF(A11="","",IF(D11="No","Excluded",IF(AND(OR(F11="N/A",E11="No Debt / N/A"),G11=""),"No Debt / N/A",IF(M11<>"","Ready","Partial")))) -> Ready | R11: Legacy mortgage data restored from v12 / v0.1 extraction.
A12: DEBT-006 | B12: BLD_EA | C12: Evergreen Apartments | D12: Yes | E12: Mortgage / Financing | F12: Vancity | G12: 5475821.3 | H12: 0.0421 | J12: 35 | K12: =IF(N12<>"","",IF(AND(G12<>"",H12<>"",J12<>""),ROUND(PPMT(H12,1,J12,-G12),0),"")) | L12: =IF(N12<>"","",IF(AND(G12<>"",H12<>""),ROUND(G12*H12,0),"")) | M12: =IF(N12<>"",N12,IF(AND(G12<>"",H12<>"",J12<>""),ROUND(PMT(H12,J12,-G12),0),"")) -> 297840 | N12: 297840 | O12: SRC-001 | P12: From v12 Property Summary | Q12: =IF(A12="","",IF(D12="No","Excluded",IF(AND(OR(F12="N/A",E12="No Debt / N/A"),G12=""),"No Debt / N/A",IF(M12<>"","Ready","Partial")))) -> Ready | R12: Legacy mortgage data restored from v12 / v0.1 extraction.
A13: DEBT-007 | B13: BLD_EE | C13: Evelyn Estates | D13: Yes | E13: Mortgage / Financing | F13: BCHMC | G13: 639949.69 | H13: 0.0374 | J13: 4 | K13: =IF(N13<>"","",IF(AND(G13<>"",H13<>"",J13<>""),ROUND(PPMT(H13,1,J13,-G13),0),"")) | L13: =IF(N13<>"","",IF(AND(G13<>"",H13<>""),ROUND(G13*H13,0),"")) | M13: =IF(N13<>"",N13,IF(AND(G13<>"",H13<>"",J13<>""),ROUND(PMT(H13,J13,-G13),0),"")) -> 244376.04 | N13: 244376.04 | O13: SRC-001 | P13: From v12 Property Summary | Q13: =IF(A13="","",IF(D13="No","Excluded",IF(AND(OR(F13="N/A",E13="No Debt / N/A"),G13=""),"No Debt / N/A",IF(M13<>"","Ready","Partial")))) -> Ready | R13: Legacy mortgage data restored from v12 / v0.1 extraction.
A14: DEBT-008 | B14: BLD_JP | C14: Jessica Place | D14: Yes | E14: Mortgage / Financing | F14: BCHMC | G14: 176698.83 | H14: 0.0101 | J14: 4 | K14: =IF(N14<>"","",IF(AND(G14<>"",H14<>"",J14<>""),ROUND(PPMT(H14,1,J14,-G14),0),"")) | L14: =IF(N14<>"","",IF(AND(G14<>"",H14<>""),ROUND(G14*H14,0),"")) | M14: =IF(N14<>"",N14,IF(AND(G14<>"",H14<>"",J14<>""),ROUND(PMT(H14,J14,-G14),0),"")) -> 176698.83 | N14: 176698.83 | O14: SRC-001 | P14: From v12 Property Summary | Q14: =IF(A14="","",IF(D14="No","Excluded",IF(AND(OR(F14="N/A",E14="No Debt / N/A"),G14=""),"No Debt / N/A",IF(M14<>"","Ready","Partial")))) -> Ready | R14: Legacy mortgage data restored from v12 / v0.1 extraction.
A15: DEBT-009 | B15: BLD_MH | C15: Margaret Heights | D15: Yes | E15: Mortgage / Financing | F15: BCHMC | G15: 145670.52 | H15: 0.0101 | J15: 5 | K15: =IF(N15<>"","",IF(AND(G15<>"",H15<>"",J15<>""),ROUND(PPMT(H15,1,J15,-G15),0),"")) | L15: =IF(N15<>"","",IF(AND(G15<>"",H15<>""),ROUND(G15*H15,0),"")) | M15: =IF(N15<>"",N15,IF(AND(G15<>"",H15<>"",J15<>""),ROUND(PMT(H15,J15,-G15),0),"")) -> 125540.52 | N15: 125540.52 | O15: SRC-001 | P15: From v12 Property Summary | Q15: =IF(A15="","",IF(D15="No","Excluded",IF(AND(OR(F15="N/A",E15="No Debt / N/A"),G15=""),"No Debt / N/A",IF(M15<>"","Ready","Partial")))) -> Ready | R15: Legacy mortgage data restored from v12 / v0.1 extraction.
A16: DEBT-010 | B16: BLD_MM | C16: Murray Manor | D16: Yes | E16: Mortgage / Financing | F16: Vancity | G16: 4992966 | H16: 0.0421 | J16: 35 | K16: =IF(N16<>"","",IF(AND(G16<>"",H16<>"",J16<>""),ROUND(PPMT(H16,1,J16,-G16),0),"")) | L16: =IF(N16<>"","",IF(AND(G16<>"",H16<>""),ROUND(G16*H16,0),"")) | M16: =IF(N16<>"",N16,IF(AND(G16<>"",H16<>"",J16<>""),ROUND(PMT(H16,J16,-G16),0),"")) -> 271563.84 | N16: 271563.84 | O16: SRC-001 | P16: From v12 Property Summary | Q16: =IF(A16="","",IF(D16="No","Excluded",IF(AND(OR(F16="N/A",E16="No Debt / N/A"),G16=""),"No Debt / N/A",IF(M16<>"","Ready","Partial")))) -> Ready | R16: Legacy mortgage data restored from v12 / v0.1 extraction.
A17: DEBT-011 | B17: BLD_NT | C17: Natalia Terrace | D17: Yes | E17: Mortgage / Financing | F17: BCHMC | G17: 485006.87 | H17: 0.0424 | J17: 3 | K17: =IF(N17<>"","",IF(AND(G17<>"",H17<>"",J17<>""),ROUND(PPMT(H17,1,J17,-G17),0),"")) | L17: =IF(N17<>"","",IF(AND(G17<>"",H17<>""),ROUND(G17*H17,0),"")) | M17: =IF(N17<>"",N17,IF(AND(G17<>"",H17<>"",J17<>""),ROUND(PMT(H17,J17,-G17),0),"")) -> 274351.8 | N17: 274351.8 | O17: SRC-001 | P17: From v12 Property Summary | Q17: =IF(A17="","",IF(D17="No","Excluded",IF(AND(OR(F17="N/A",E17="No Debt / N/A"),G17=""),"No Debt / N/A",IF(M17<>"","Ready","Partial")))) -> Ready | R17: Legacy mortgage data restored from v12 / v0.1 extraction.
A18: DEBT-012 | B18: BLD_NG | C18: Newton Green | D18: Yes | E18: Mortgage / Financing | F18: CMLS | G18: 3432387.1 | H18: 0.04465 | J18: 9 | K18: =IF(N18<>"","",IF(AND(G18<>"",H18<>"",J18<>""),ROUND(PPMT(H18,1,J18,-G18),0),"")) | L18: =IF(N18<>"","",IF(AND(G18<>"",H18<>""),ROUND(G18*H18,0),"")) | M18: =IF(N18<>"",N18,IF(AND(G18<>"",H18<>"",J18<>""),ROUND(PMT(H18,J18,-G18),0),"")) -> 443187 | N18: 443187 | O18: SRC-001 | P18: From v12 Property Summary | Q18: =IF(A18="","",IF(D18="No","Excluded",IF(AND(OR(F18="N/A",E18="No Debt / N/A"),G18=""),"No Debt / N/A",IF(M18<>"","Ready","Partial")))) -> Ready | R18: Legacy mortgage data restored from v12 / v0.1 extraction.
A19: DEBT-013 | B19: BLD_RG | C19: Rosemary Green | D19: Yes | E19: Mortgage / Financing | F19: Peoples Group | G19: 1976761.2 | H19: 0.024 | J19: 10 | K19: =IF(N19<>"","",IF(AND(G19<>"",H19<>"",J19<>""),ROUND(PPMT(H19,1,J19,-G19),0),"")) | L19: =IF(N19<>"","",IF(AND(G19<>"",H19<>""),ROUND(G19*H19,0),"")) | M19: =IF(N19<>"",N19,IF(AND(G19<>"",H19<>"",J19<>""),ROUND(PMT(H19,J19,-G19),0),"")) -> 291146.28 | N19: 291146.28 | O19: SRC-001 | P19: From v12 Property Summary | Q19: =IF(A19="","",IF(D19="No","Excluded",IF(AND(OR(F19="N/A",E19="No Debt / N/A"),G19=""),"No Debt / N/A",IF(M19<>"","Ready","Partial")))) -> Ready | R19: Legacy mortgage data restored from v12 / v0.1 extraction.
A20: DEBT-014 | B20: BLD_AS | C20: 1656 Adanac Street | D20: Yes | E20: Mortgage / Financing | F20: BCH CHF | G20: 26374193 | H20: 0.0497 | I20: 10 | J20: 35 | K20: =IF(N20<>"","",IF(AND(G20<>"",H20<>"",J20<>""),ROUND(PPMT(H20,1,J20,-G20),0),"")) -> 293827 | L20: =IF(N20<>"","",IF(AND(G20<>"",H20<>""),ROUND(G20*H20,0),"")) -> 1310797 | M20: =IF(N20<>"",N20,IF(AND(G20<>"",H20<>"",J20<>""),ROUND(PMT(H20,J20,-G20),0),"")) -> 1604624 | O20: SRC-002/SRC-003 | P20: Updated source assumption | Q20: =IF(A20="","",IF(D20="No","Excluded",IF(AND(OR(F20="N/A",E20="No Debt / N/A"),G20=""),"No Debt / N/A",IF(M20<>"","Ready","Partial")))) -> Ready | R20: Tapestry/ENF project-specific financing; replaces v12 generic assumption.
A21: DEBT-015 | B21: BLD_PS | C21: 450 Pacific Street | D21: Yes | E21: Mortgage / Financing | F21: BCH CHF | G21: 38826068 | H21: 0.0473 | I21: 10 | J21: 40 | K21: =IF(N21<>"","",IF(AND(G21<>"",H21<>"",J21<>""),ROUND(PPMT(H21,1,J21,-G21),0),"")) -> 343200 | L21: =IF(N21<>"","",IF(AND(G21<>"",H21<>""),ROUND(G21*H21,0),"")) -> 1836473 | M21: =IF(N21<>"",N21,IF(AND(G21<>"",H21<>"",J21<>""),ROUND(PMT(H21,J21,-G21),0),"")) -> 2179673 | O21: SRC-002/SRC-003 | P21: Updated source assumption | Q21: =IF(A21="","",IF(D21="No","Excluded",IF(AND(OR(F21="N/A",E21="No Debt / N/A"),G21=""),"No Debt / N/A",IF(M21<>"","Ready","Partial")))) -> Ready | R21: Tapestry/ENF project-specific financing; replaces v12 generic assumption.
A22: DEBT-016 | B22: BLD_PM | C22: The Creek, Port Moody | D22: Yes | E22: Mortgage / Financing | F22: CMHC | G22: 105080576 | H22: 0.0425 | I22: 10 | J22: 50 | K22: =IF(N22<>"","",IF(AND(G22<>"",H22<>"",J22<>""),ROUND(PPMT(H22,1,J22,-G22),0),"")) -> 636793 | L22: =IF(N22<>"","",IF(AND(G22<>"",H22<>""),ROUND(G22*H22,0),"")) -> 4465924 | M22: =IF(N22<>"",N22,IF(AND(G22<>"",H22<>"",J22<>""),ROUND(PMT(H22,J22,-G22),0),"")) -> 5102718 | O22: SRC-002/SRC-003 | P22: Updated source assumption | Q22: =IF(A22="","",IF(D22="No","Excluded",IF(AND(OR(F22="N/A",E22="No Debt / N/A"),G22=""),"No Debt / N/A",IF(M22<>"","Ready","Partial")))) -> Ready | R22: Tapestry/ENF project-specific financing; unit count conflict remains separate.
A23: DEBT-017 | B23: BLD_CD | C23: 800 Commercial Drive | D23: Yes | E23: Mortgage / Financing | F23: BCH CHF | G23: 58887021 | H23: 0.0455 | I23: 10 | J23: 35 | K23: =IF(N23<>"","",IF(AND(G23<>"",H23<>"",J23<>""),ROUND(PPMT(H23,1,J23,-G23),0),"")) -> 715230 | L23: =IF(N23<>"","",IF(AND(G23<>"",H23<>""),ROUND(G23*H23,0),"")) -> 2679359 | M23: =IF(N23<>"",N23,IF(AND(G23<>"",H23<>"",J23<>""),ROUND(PMT(H23,J23,-G23),0),"")) -> 3394590 | O23: SRC-002/SRC-003 | P23: Updated source assumption | Q23: =IF(A23="","",IF(D23="No","Excluded",IF(AND(OR(F23="N/A",E23="No Debt / N/A"),G23=""),"No Debt / N/A",IF(M23<>"","Ready","Partial")))) -> Ready | R23: Includes senior/other financing + community bond; confirm separate vs combined stack if needed.
K24: =IF(N24<>"","",IF(AND(G24<>"",H24<>"",J24<>""),ROUND(PPMT(H24,1,J24,-G24),0),"")) | L24: =IF(N24<>"","",IF(AND(G24<>"",H24<>""),ROUND(G24*H24,0),"")) | M24: =IF(N24<>"",N24,IF(AND(G24<>"",H24<>"",J24<>""),ROUND(PMT(H24,J24,-G24),0),"")) | Q24: =IF(A24="","",IF(D24="No","Excluded",IF(AND(OR(F24="N/A",E24="No Debt / N/A"),G24=""),"No Debt / N/A",IF(M24<>"","Ready","Partial"))))
K25: =IF(N25<>"","",IF(AND(G25<>"",H25<>"",J25<>""),ROUND(PPMT(H25,1,J25,-G25),0),"")) | L25: =IF(N25<>"","",IF(AND(G25<>"",H25<>""),ROUND(G25*H25,0),"")) | M25: =IF(N25<>"",N25,IF(AND(G25<>"",H25<>"",J25<>""),ROUND(PMT(H25,J25,-G25),0),"")) | Q25: =IF(A25="","",IF(D25="No","Excluded",IF(AND(OR(F25="N/A",E25="No Debt / N/A"),G25=""),"No Debt / N/A",IF(M25<>"","Ready","Partial"))))
K26: =IF(N26<>"","",IF(AND(G26<>"",H26<>"",J26<>""),ROUND(PPMT(H26,1,J26,-G26),0),"")) | L26: =IF(N26<>"","",IF(AND(G26<>"",H26<>""),ROUND(G26*H26,0),"")) | M26: =IF(N26<>"",N26,IF(AND(G26<>"",H26<>"",J26<>""),ROUND(PMT(H26,J26,-G26),0),"")) | Q26: =IF(A26="","",IF(D26="No","Excluded",IF(AND(OR(F26="N/A",E26="No Debt / N/A"),G26=""),"No Debt / N/A",IF(M26<>"","Ready","Partial"))))
K27: =IF(N27<>"","",IF(AND(G27<>"",H27<>"",J27<>""),ROUND(PPMT(H27,1,J27,-G27),0),"")) | L27: =IF(N27<>"","",IF(AND(G27<>"",H27<>""),ROUND(G27*H27,0),"")) | M27: =IF(N27<>"",N27,IF(AND(G27<>"",H27<>"",J27<>""),ROUND(PMT(H27,J27,-G27),0),"")) | Q27: =IF(A27="","",IF(D27="No","Excluded",IF(AND(OR(F27="N/A",E27="No Debt / N/A"),G27=""),"No Debt / N/A",IF(M27<>"","Ready","Partial"))))
K28: =IF(N28<>"","",IF(AND(G28<>"",H28<>"",J28<>""),ROUND(PPMT(H28,1,J28,-G28),0),"")) | L28: =IF(N28<>"","",IF(AND(G28<>"",H28<>""),ROUND(G28*H28,0),"")) | M28: =IF(N28<>"",N28,IF(AND(G28<>"",H28<>"",J28<>""),ROUND(PMT(H28,J28,-G28),0),"")) | Q28: =IF(A28="","",IF(D28="No","Excluded",IF(AND(OR(F28="N/A",E28="No Debt / N/A"),G28=""),"No Debt / N/A",IF(M28<>"","Ready","Partial"))))
K29: =IF(N29<>"","",IF(AND(G29<>"",H29<>"",J29<>""),ROUND(PPMT(H29,1,J29,-G29),0),"")) | L29: =IF(N29<>"","",IF(AND(G29<>"",H29<>""),ROUND(G29*H29,0),"")) | M29: =IF(N29<>"",N29,IF(AND(G29<>"",H29<>"",J29<>""),ROUND(PMT(H29,J29,-G29),0),"")) | Q29: =IF(A29="","",IF(D29="No","Excluded",IF(AND(OR(F29="N/A",E29="No Debt / N/A"),G29=""),"No Debt / N/A",IF(M29<>"","Ready","Partial"))))
K30: =IF(N30<>"","",IF(AND(G30<>"",H30<>"",J30<>""),ROUND(PPMT(H30,1,J30,-G30),0),"")) | L30: =IF(N30<>"","",IF(AND(G30<>"",H30<>""),ROUND(G30*H30,0),"")) | M30: =IF(N30<>"",N30,IF(AND(G30<>"",H30<>"",J30<>""),ROUND(PMT(H30,J30,-G30),0),"")) | Q30: =IF(A30="","",IF(D30="No","Excluded",IF(AND(OR(F30="N/A",E30="No Debt / N/A"),G30=""),"No Debt / N/A",IF(M30<>"","Ready","Partial"))))
K31: =IF(N31<>"","",IF(AND(G31<>"",H31<>"",J31<>""),ROUND(PPMT(H31,1,J31,-G31),0),"")) | L31: =IF(N31<>"","",IF(AND(G31<>"",H31<>""),ROUND(G31*H31,0),"")) | M31: =IF(N31<>"",N31,IF(AND(G31<>"",H31<>"",J31<>""),ROUND(PMT(H31,J31,-G31),0),"")) | Q31: =IF(A31="","",IF(D31="No","Excluded",IF(AND(OR(F31="N/A",E31="No Debt / N/A"),G31=""),"No Debt / N/A",IF(M31<>"","Ready","Partial"))))
K32: =IF(N32<>"","",IF(AND(G32<>"",H32<>"",J32<>""),ROUND(PPMT(H32,1,J32,-G32),0),"")) | L32: =IF(N32<>"","",IF(AND(G32<>"",H32<>""),ROUND(G32*H32,0),"")) | M32: =IF(N32<>"",N32,IF(AND(G32<>"",H32<>"",J32<>""),ROUND(PMT(H32,J32,-G32),0),"")) | Q32: =IF(A32="","",IF(D32="No","Excluded",IF(AND(OR(F32="N/A",E32="No Debt / N/A"),G32=""),"No Debt / N/A",IF(M32<>"","Ready","Partial"))))
K33: =IF(N33<>"","",IF(AND(G33<>"",H33<>"",J33<>""),ROUND(PPMT(H33,1,J33,-G33),0),"")) | L33: =IF(N33<>"","",IF(AND(G33<>"",H33<>""),ROUND(G33*H33,0),"")) | M33: =IF(N33<>"",N33,IF(AND(G33<>"",H33<>"",J33<>""),ROUND(PMT(H33,J33,-G33),0),"")) | Q33: =IF(A33="","",IF(D33="No","Excluded",IF(AND(OR(F33="N/A",E33="No Debt / N/A"),G33=""),"No Debt / N/A",IF(M33<>"","Ready","Partial"))))
K34: =IF(N34<>"","",IF(AND(G34<>"",H34<>"",J34<>""),ROUND(PPMT(H34,1,J34,-G34),0),"")) | L34: =IF(N34<>"","",IF(AND(G34<>"",H34<>""),ROUND(G34*H34,0),"")) | M34: =IF(N34<>"",N34,IF(AND(G34<>"",H34<>"",J34<>""),ROUND(PMT(H34,J34,-G34),0),"")) | Q34: =IF(A34="","",IF(D34="No","Excluded",IF(AND(OR(F34="N/A",E34="No Debt / N/A"),G34=""),"No Debt / N/A",IF(M34<>"","Ready","Partial"))))
K35: =IF(N35<>"","",IF(AND(G35<>"",H35<>"",J35<>""),ROUND(PPMT(H35,1,J35,-G35),0),"")) | L35: =IF(N35<>"","",IF(AND(G35<>"",H35<>""),ROUND(G35*H35,0),"")) | M35: =IF(N35<>"",N35,IF(AND(G35<>"",H35<>"",J35<>""),ROUND(PMT(H35,J35,-G35),0),"")) | Q35: =IF(A35="","",IF(D35="No","Excluded",IF(AND(OR(F35="N/A",E35="No Debt / N/A"),G35=""),"No Debt / N/A",IF(M35<>"","Ready","Partial"))))
... K206: =IF(N206<>"","",IF(AND(G206<>"",H206<>"",J206<>""),ROUND(PPMT(H206,1,J206,-G206),0),"")) | L206: =IF(N206<>"","",IF(AND(G206<>"",H206<>""),ROUND(G206*H206,0),"")) | M206: =IF(N206<>"",N206,IF(AND(G206<>"",H206<>"",J206<>""),ROUND(PMT(H206,J206,-G206),0),"")) | Q206: =IF(A206="","",IF(D206="No","Excluded",IF(AND(OR(F206="N/A",E206="No Debt / N/A"),G206=""),"No Debt / N/A",IF(M206<>"","Ready","Partial"))))

Sheet DATA_CASH_RESERVES
A1: DATA_CASH_RESERVES — Cash / Reserve Availability Inputs
A2: Blue cells are writable. Restricted cash treatment is a key MVP flag if not confirmed.
A6: Cash_ID | B6: Organization_ID | C6: Property_ID | D6: Year | E6: Opening_Cash | F6: Closing_Cash | G6: Restricted_Cash | H6: Unrestricted_Cash | I6: Available_for_Operations | J6: Available_for_Debt_Service | K6: Source_File_ID | L6: Review_Status
A7: CASH-001 | B7: ORG-001 | C7: PORTFOLIO | D7: 2026 | I7: Unknown | J7: Unknown | K7: SRC-002 | L7: Restricted cash treatment not confirmed

Sheet DATA_AGREEMENTS
A1: DATA_AGREEMENTS — Agreements / Restrictions Inputs
A2: Blue cells are writable. This tab tracks mission-lock, affordability, covenant, cash, refinance, and disposition restrictions. Placeholder is acceptable in MVP v1.
A6: Agreement_ID | B6: Property_ID | C6: Property_Name | D6: Agreement_Type | E6: Counterparty | F6: Start_Date | G6: End_Date | H6: Affordability_Requirement | I6: Rent_Restriction | J6: Use_Restriction | K6: Refinance_Restriction | L6: Disposition_Restriction | M6: Source_File_ID | N6: Review_Status

Sheet DATA_CAPITAL_NEEDS
A1: DATA_CAPITAL_NEEDS — Capital Needs / Deferred Maintenance Inputs
A2: Blue cells are writable. Purple unfunded amount formula remains live. Missing capital plan should be flagged, not hidden.
A6: Capital_Item_ID | B6: Property_ID | C6: Property_Name | D6: Capital_Item | E6: Capital_Category | F6: Required_or_Discretionary | G6: Year_Needed | H6: Estimated_Cost | I6: Funded_Amount | J6: Unfunded_Amount | K6: Funding_Source | L6: Deferred_Maintenance_Flag | M6: Source_File_ID | N6: Review_Status
A7: CN-001 | B7: PORTFOLIO | C7: Portfolio-level | D7: Capital needs plan not fully reviewed | E7: TBD | F7: Required | J7: =IF(H7="","",MAX(H7-I7,0)) | K7: TBD | L7: Unknown | M7: SRC-002 | N7: Open
J8: =IF(H8="","",MAX(H8-I8,0))
J9: =IF(H9="","",MAX(H9-I9,0))
J10: =IF(H10="","",MAX(H10-I10,0))
J11: =IF(H11="","",MAX(H11-I11,0))
J12: =IF(H12="","",MAX(H12-I12,0))
J13: =IF(H13="","",MAX(H13-I13,0))
J14: =IF(H14="","",MAX(H14-I14,0))
J15: =IF(H15="","",MAX(H15-I15,0))
J16: =IF(H16="","",MAX(H16-I16,0))
J17: =IF(H17="","",MAX(H17-I17,0))
J18: =IF(H18="","",MAX(H18-I18,0))
J19: =IF(H19="","",MAX(H19-I19,0))
... J206: =IF(H206="","",MAX(H206-I206,0))

Sheet ASSUMPTIONS_FLAGS
A1: ASSUMPTIONS_FLAGS — Review Flags / Source Conflicts / Assumptions
A2: Orange cells are controlled review areas. Keep unresolved issues visible until confirmed.
A6: Flag_ID | B6: Category | C6: Property_ID | D6: Issue / Assumption | E6: Current Treatment | F6: Severity | G6: Requires Confirmation? | H6: Owner | I6: Status | J6: Reviewer Note
A7: FLAG-001 | B7: Unit count | C7: BLD_PM | D7: Port Moody unit count conflict: 245 vs 328 | E7: Show both values in DATA_PROPERTY_MASTER; do not finalize until ENF confirms. | F7: High | G7: Yes | H7: Kelly / ENF | I7: Open | J7: Ask ENF targeted question only.
A8: FLAG-002 | B8: Cash / reserves | C8: PORTFOLIO | D8: Restricted vs unrestricted cash not confirmed | E8: Treat cash availability as unknown / conditional in MVP output. | F8: Medium | G8: Yes | H8: Kelly / ENF | I8: Open | J8: Do not assume all cash supports debt service.
A9: FLAG-003 | B9: Capital needs | C9: PORTFOLIO | D9: Capital needs plan not fully reviewed | E9: Keep DATA_CAPITAL_NEEDS placeholder and readiness flag conditional. | F9: Medium | G9: Yes | H9: Kelly / ENF | I9: Open | J9: Need future BCA/reserve/capital plan review.
A10: FLAG-004 | B10: Agreements / restrictions | C10: PORTFOLIO | D10: Affordability/covenant/refinance restrictions pending review | E10: Keep agreement review status partial. | F10: Medium | G10: Yes | H10: Kelly / ENF | I10: Open | J10: Future legal/agreement review item.
A11: FLAG-005 | B11: Source hierarchy | C11: PORTFOLIO | D11: Tapestry / ENF source data supersedes generic v12 assumptions where more current | E11: Use Tapestry for demo assumptions; retain v12 architecture as build logic. | F11: Medium | G11: No | H11: Kelly / IREI | I11: Active | J11: Documented in Business Rules and SOURCE_LOG.
A12: FLAG-006 | B12: 800 Commercial units | C12: BLD_CD | D12: 800 Commercial unit count differs between v12 and Tapestry indication | E12: Show v12 unit count and alternate Tapestry count; decide in demo data update. | F12: Medium | G12: Yes | H12: Kelly / ENF | I12: Review | J12: Not as urgent as Port Moody but should be logged.

Sheet DATA_METRIC_LONG
A1: DATA_METRIC_LONG — Live MVP Metrics
A2: Formula-driven output metrics. Column D intentionally mirrors the live formula output for QA; Column E is the output value used by the snapshot. Plain-English documentation belongs in CALC_RULES / Notes.
A6: Metric_ID | B6: Metric_Name | C6: Metric_Category | D6: Live Formula Mirror | E6: Metric_Value | F6: Metric_Status | G6: Source_Confidence | H6: Notes
A7: MET-001 | B7: Total Properties | C7: Portfolio | D7: =COUNTA(DATA_PROPERTY_MASTER!A7:A206) -> 17 | E7: =COUNTA(DATA_PROPERTY_MASTER!A7:A206) -> 17 | F7: Live | G7: Formula-linked | H7: One row per property/project.
A8: MET-002 | B8: Included Properties | C8: Portfolio | D8: =COUNTIF(DATA_PROPERTY_MASTER!E7:E206,"Yes") -> 16 | E8: =COUNTIF(DATA_PROPERTY_MASTER!E7:E206,"Yes") -> 16 | F8: Live | G8: Formula-linked | H8: Excludes properties marked No.
A9: MET-003 | B9: Existing Assets | C9: Portfolio | D9: =COUNTIFS(DATA_PROPERTY_MASTER!D7:D206,"Active",DATA_PROPERTY_MASTER!E7:E206,"Yes") -> 12 | E9: =COUNTIFS(DATA_PROPERTY_MASTER!D7:D206,"Active",DATA_PROPERTY_MASTER!E7:E206,"Yes") -> 12 | F9: Live | G9: Formula-linked | H9: Active/included assets.
A10: MET-004 | B10: New / Future Projects | C10: Portfolio | D10: =COUNTIFS(DATA_PROPERTY_MASTER!D7:D206,"New Dev",DATA_PROPERTY_MASTER!E7:E206,"Yes") -> 4 | E10: =COUNTIFS(DATA_PROPERTY_MASTER!D7:D206,"New Dev",DATA_PROPERTY_MASTER!E7:E206,"Yes") -> 4 | F10: Live | G10: Formula-linked | H10: New dev/future projects.
A11: MET-005 | B11: Modeled Units | C11: Portfolio | D11: =SUMIFS(DATA_PROPERTY_MASTER!I7:I206,DATA_PROPERTY_MASTER!E7:E206,"Yes") -> 1076 | E11: =SUMIFS(DATA_PROPERTY_MASTER!I7:I206,DATA_PROPERTY_MASTER!E7:E206,"Yes") -> 1076 | F11: Review | G11: Source conflict | H11: Includes v12 unit counts unless updated.
A12: MET-006 | B12: Unit Count Conflicts | C12: Data Readiness | D12: =COUNTIF(DATA_PROPERTY_MASTER!K7:K206,"Yes") -> 2 | E12: =COUNTIF(DATA_PROPERTY_MASTER!K7:K206,"Yes") -> 2 | F12: Review | G12: Formula-linked | H12: Shows source conflicts.
