Workbook

Sheet Business Rules
A1: IREI Underwriting Template Prototype
A3: Business Rules Organized by Epics and User Stories
A5: 1. Purpose of the Model
A7: The model is designed to convert non-profit / Indigenous / mission-driven housing organization data into a standardized, auditable underwriting structure.
A9: It has two purposes:
A11: 1. Current use: underwrite NGO B’s portfolio using the existing live Excel calculation engine.
A13: 2. Future platform use: establish the data architecture and business rules for an AI / analyst-assisted IREI underwriting platform.
A15: The model is not yet a fully automated platform engine. The current financial calculations still rely on legacy NGO B tabs, while the new DATA and OUT layers define the future standardized model structure.
A19: Epic 1 — Workbook Navigation and User Control
A21: Business Objective
A23: Ensure analysts and AI agents understand where to enter data, where formulas live, what not to overwrite, and how to follow the workbook structure.
A25: Key Tabs
... A1167: BR-16.5 — Any future audit-summary change must be logged in 00_CHANGE_LOG.

Sheet 00_PLATFORM_INDEX
A1: IREI PLATFORM TEMPLATE LAYER — v10 colour-controlled working master
A2: Purpose | B2: Adds platform-ready bridge, authoritative classification, capital-flow separation, property-level traceability, reconciliation controls, and a live investor summary while preserving live calculations.
A3: Core rule | B3: Future NGOs provide messy source files; IREI/AI maps them into canonical DATA sheets, then model outputs are generated.
A4: Layer | B4: Sheet | C4: Role | D4: Live / Manual | E4: Status | G4: COLOUR / EDITING STANDARD — v10
A5: 1 Intake | B5: STG_SOURCE_INTAKE | C5: Log source files and review status. | D5: Manual / future AI-populated | E5: New | G5: Style | H5: Meaning | I5: Control Rule | J5: Example | K5: Owner
A6: 2 Mapping | B6: MAP_FIELD_MAPPING | C6: Translate messy source fields into IREI canonical fields. | D6: Standard / AI-assisted | E6: New | G6: Blue fill / blue font | H6: Analyst / AI input cell | I6: Allowed to write only in mapped input ranges | J6: STG_SOURCE_INTAKE rows | K6: Analyst / AI
A7: 3 Property master | B7: DATA_PROPERTY_MASTER | C7: One row per property linked to current model. | D7: Live formulas | E7: New | G7: Black font | H7: Live formula / calculated output | I7: Do not overwrite | J7: DATA_CAPITAL_FLOW formulas | K7: Model / Excel
A8: 4 Classification | B8: DATA_ASSET_CLASSIFICATION | C8: Classify every property once using formula-driven rules and controlled override governance. | D8: Live formulas / controlled manual override | E8: New in v4 | G8: Purple fill / tab | H8: Generated or normalized DATA layer | I8: Generated from current model today; future AI/Python output | J8: DATA_PROPERTY_MASTER | K8: AI / model generator
A9: 5 Debt master | B9: DATA_DEBT_MASTER | C9: One row per property debt profile. | D9: Live formulas | E9: New | G9: Orange fill | H9: Warning / required review | I9: Resolve before external use | J9: DATA_QUALITY_CHECKS | K9: Analyst reviewer
A10: 6 Metric long table | B10: DATA_METRIC_LONG | C10: Property-year-metric rows linked to BLD_* tabs. | D10: Live formulas | E10: New | G10: Grey tab / grey header | H10: Legacy NGO B calculation engine | I10: Do not edit unless rebuilding the engine | J10: BLD_* tabs | K10: Model maintainer
A11: 7 Checks | B11: DATA_QUALITY_CHECKS | C11: Live platform-readiness checks. | D11: Live formulas | E11: New | G11: Green tab/header | H11: Output / summary page | I11: Output only; formulas should source from authority layers | J11: 00_INVESTOR SUMMARY | K11: Reader / reviewer
A12: 8 Output | B12: OUT_PLATFORM_READINESS | C12: Dashboard for migration readiness. | D12: Live formulas | E12: New
A14: Total properties | B14: =COUNTA(DATA_PROPERTY_MASTER!$A$5:$A$21) -> 17
A15: Included properties | B15: =COUNTIF(DATA_PROPERTY_MASTER!$E$5:$E$21,"Yes") -> 16
A16: Metric rows | B16: =COUNTA(DATA_METRIC_LONG!$A$5:$A$10000) -> 816
A17: 9 Capital-flow authority | B17: DATA_CAPITAL_FLOW | C17: Separates operating cash, debt service, refinance surplus, and residual funding gap into live canonical rows. | D17: Live formulas from existing rollup | E17: New in v5
A18: 10 Capital-flow output | B18: OUT_CAPITAL_FLOW_SUMMARY | C18: Provides clean year-by-year output and reconciliation against the legacy rollup total. | D18: Live formulas from existing rollup | E18: New in v5
A19: 11 Aggregation audit | B19: DATA_AGGREGATION_AUDIT | C19: Tracks included/excluded source errors suppressed by guarded rollup aggregation formulas. | D19: Live formulas | E19: New in v6
A20: 12 Property-level capital-flow | B20: DATA_CAPITAL_FLOW | C20: Adds Level = Property rows by BLD_ID/year/metric, linked to property tabs and scope-adjusted to reconcile to portfolio totals. | D20: Live formulas from BLD_* tabs | E20: New in v7
A21: 13 Capital-flow reconciliation | B21: DATA_CAPITAL_FLOW_RECON | C21: Checks that property-level sums equal the portfolio-level capital-flow rows for each year and metric. | D21: Live SUMIFS formulas | E21: New in v7
A22: 8 Output | B22: 00_INVESTOR SUMMARY | C22: Investor-facing summary rebuilt from DATA_ASSET_CLASSIFICATION, DATA_CAPITAL_FLOW, and DATA_CAPITAL_FLOW_RECON. | D22: Live formulas | E22: New in v8
A23: v9 governance additions
A24: INPUT_CONTROL_MAP | B24: Human/AI write map | C24: Centralized map of writable inputs, generated outputs, and legacy engine zones. | D24: Active | E24: Use this as analyst/AI operating guide.
A25: MAP_FIELD_MAPPING | B25: Current-vs-future field map | C25: Updated to distinguish live current sources from future canonical target tables. | D25: Active | E25: Prevents the map from promising non-live tables.
A26: DATA_AGGREGATION_AUDIT | B26: Dynamic audit formulas | C26: Removed chained BLD_AB + BLD_AC style formulas; now references DATA_PROPERTY_MASTER dynamically. | D26: Active | E26: Better survives changing property counts.
A27: Remaining manual scaling item | B27: Underlying engine | C27: 01/02/BLD tabs remain NGO B-specific calculation engine. | D27: Open | E27: Future Python should generate/replace engine from canonical DATA tables.
A28: 11 Colour control | B28: INPUT_CONTROL_MAP / 00_PLATFORM_INDEX | C28: Adds explicit colour/editing convention: blue inputs, black formulas, purple generated data, orange warnings, grey legacy engine, green outputs. | D28: Visual governance | E28: New in v10
A30: v11 Canonical input layer
A31: Layer | B31: Sheet | C31: Role | D31: Live / Manual | E31: Status
A32: Canonical input | B32: DATA_UNIT_MIX | C32: Unit mix and affordability/rent restriction evidence | D32: Blue inputs + live formula checks | E32: New in v11
A33: Canonical input | B33: DATA_RENT_ROLL | C33: Unit-level or summarized rent roll evidence | D33: Blue inputs + live formula checks | E33: New in v11
A34: Canonical input | B34: DATA_OPERATING_ACTUALS | C34: Long-format operating actual/budget/projection rows | D34: Blue inputs + live formula checks | E34: New in v11
A35: Canonical input | B35: DATA_AGREEMENTS | C35: Legal/funding/affordability restriction evidence | D35: Blue inputs + live formula checks | E35: New in v11
A36: Canonical input | B36: DATA_CAPITAL_NEEDS | C36: Capital needs, fixed assets, funded/unfunded gap | D36: Blue inputs + live formula checks | E36: New in v11

Sheet INPUT_CONTROL_MAP
A1: INPUT_CONTROL_MAP — v11 analyst / AI write map
A2: Purpose | B2: One centralized instruction layer showing where humans or AI may write, what is generated, and what remains legacy NGO B calculation engine.
A3: Rule | B3: Do not write into generated DATA/OUT tabs except in designated override/input columns. Future AI ingestion should write to intake/canonical input zones first, then generate the model.
A5: Zone | B5: Tab | C5: Range / Columns | D5: Field / Purpose | E5: Write Permission | F5: Table Exists? | G5: Engine Repoint Status / Feeds To | H5: Notes
A6: PRIMARY INPUT | B6: STG_SOURCE_INTAKE | C6: A5:H25 | D6: Source file log: NGO files, Yardi/CSV exports, fiscal year, received status | E6: Human / AI may write | F6: Yes | G6: Feeds evidence tracking and future ingestion | H6: This is the first place analysts should document files received.
A7: PRIMARY INPUT | B7: 00_MODEL_CONTROL | C7: A5:E21; B31 | D7: Property ID, inclusion flag, selected current year | E7: Human / AI may write controlled cells | F7: Yes | G7: Feeds rollup scope, property master, classification | H7: Do not manually edit generated columns F:H.
A8: CONTROLLED OVERRIDE | B8: DATA_ASSET_CLASSIFICATION | C8: T8:T24 and Y8:Y24 | D8: Human classification override and required reason | E8: Human / AI may write only if justified | F8: Yes | G8: Feeds final classification U and all summaries | H8: If T is used, Y must be filled; QC flags missing reasons.
A9: GENERATED DATA | B9: DATA_PROPERTY_MASTER | C9: A5:O21 | D9: Canonical property master bridge | E9: Do not manually edit | F9: Yes | G9: Generated from current model; future generated from AI/source files | H9: Rows are still sized to NGO B; future Python should extend rows.
A10: GENERATED DATA | B10: DATA_DEBT_MASTER | C10: A5:L21 | D10: Canonical debt bridge | E10: Do not manually edit | F10: Yes | G10: Generated from current 02_Debt Engine / property tabs | H10: Not yet the source of calculations.
A11: GENERATED DATA | B11: DATA_METRIC_LONG | C11: A5:H10000 | D11: Long-format property metrics | E11: Do not manually edit | F11: Yes | G11: Generated from BLD_* tabs | H11: Future engine should generate directly from canonical data tables.
A12: GENERATED DATA | B12: DATA_CAPITAL_FLOW | C12: A5:Q5206 | D12: Portfolio and property-level capital flow | E12: Do not manually edit | F12: Yes | G12: Generated from rollup + property tabs | H12: Property-level rows reconcile to portfolio-level rows.
A13: GENERATED DATA | B13: DATA_CAPITAL_FLOW_RECON | C13: A5:H400 | D13: Capital flow reconciliation | E13: Do not manually edit | F13: Yes | G13: Generated from DATA_CAPITAL_FLOW | H13: Use to catch drift between property and portfolio totals.
A14: GENERATED DATA | B14: DATA_AGGREGATION_AUDIT | C14: A6:Y80 | D14: Suppressed source-error audit | E14: Do not manually edit | F14: Yes | G14: Generated from DATA_PROPERTY_MASTER + BLD_* tabs | H14: v9 formulas are dynamic; no BLD_AB + BLD_AC chaining.
A15: OUTPUT | B15: 00_INVESTOR SUMMARY | C15: A1:L60 | D15: Investor/funder-facing summary | E15: Do not manually edit core formulas | F15: Yes | G15: Generated from DATA_ASSET_CLASSIFICATION, DATA_CAPITAL_FLOW, audit/recon | H15: Text edits should be handled carefully; formula cells stay live.
A16: OUTPUT | B16: OUT_CAPITAL_FLOW_SUMMARY | C16: A1:R35 | D16: Capital-flow summary | E16: Do not manually edit | F16: Yes | G16: Generated from DATA_CAPITAL_FLOW | H16: Clean output view.
... A29: PRIMARY CANONICAL INPUT | B29: DATA_CAPITAL_NEEDS | C29: DATA_CAPITAL_NEEDS!B7:S206 | D29: Capital repairs, lifecycle, deferred maintenance, funding source | E29: Human / AI may write blue cells | F29: Yes - table exists | G29: Not repointed; future feed to capital plan and funding-gap analysis | H29: Canonical table exists in v11; not yet read by capital-flow engine.
A83: COLOUR / EDITING STANDARD — v10
A84: Style | B84: Meaning | C84: Where Used | D84: Who Can Edit | E84: Formula Rule | F84: Notes | G84: Status | H84: Version
A85: Blue | B85: Hardcoded input / controlled override | C85: STG_SOURCE_INTAKE; 00_MODEL_CONTROL A:E/B31; DATA_ASSET_CLASSIFICATION T/Y | D85: Analyst / AI | E85: Not formula-driven | F85: Only mapped blue cells should be written to. | G85: Live | H85: v10
A86: Black | B86: Formula / calculated output | C86: DATA/OUT sheets and generated fields | D86: Do not edit | E86: Formula cells remain black font | F86: Overwrite only if intentionally rebuilding the model. | G86: Live | H86: v10
A87: Purple | B87: Generated / normalized DATA layer | C87: DATA_PROPERTY_MASTER, DATA_DEBT_MASTER, DATA_METRIC_LONG, DATA_CAPITAL_FLOW | D87: Model / future AI generator | E87: May contain formulas today | F87: Future Python engine should generate these tables directly. | G87: Live bridge | H87: v10
A88: Orange | B88: Warning / review required | C88: DATA_QUALITY_CHECKS, DATA_ASSET_CLASSIFICATION X, recon/audit status fields | D88: Analyst reviewer | E88: May be formula-driven | F88: Resolve before external sharing. | G88: Live | H88: v10
A89: Grey | B89: Legacy NGO B engine / do-not-edit zone | C89: 01_/02_/BLD_* and legacy outputs | D89: Model maintainer only | E89: Existing formulas preserved | F89: Still bespoke to NGO B until canonical engines replace it. | G89: Open roadmap | H89: v10
A90: Green | B90: Output only | C90: 00_INVESTOR SUMMARY, OUT_PLATFORM_READINESS, OUT_CAPITAL_FLOW_SUMMARY | D90: Do not edit | E90: Formula-linked to authority layers | F90: Use for review, not input. | G90: Live | H90: v10
A92: PRIMARY CANONICAL INPUT | B92: DATA_UNIT_MIX | C92: B7:U206 | D92: Unit mix, rent restriction, source confidence and review fields | E92: Human / AI may write blue cells | F92: Yes | G92: Feeds future rent / affordability engine; not yet repointed | H92: Formula columns A,C,M,N,V remain live.
A93: PRIMARY CANONICAL INPUT | B93: DATA_RENT_ROLL | C93: B7:V206 | D93: Unit-level or summarized rent roll | E93: Human / AI may write blue cells | F93: Yes | G93: Feeds future rent engine; not yet repointed | H93: Formula columns A,C,P:R,W remain live.
A94: PRIMARY CANONICAL INPUT | B94: DATA_OPERATING_ACTUALS | C94: B7:Q206 | D94: Operating actuals / budget / projection long-format rows | E94: Human / AI may write blue cells | F94: Yes | G94: Feeds future base-year inputs and operating engine; not yet repointed | H94: Formula columns A,C,P,R remain live.
A95: PRIMARY CANONICAL INPUT | B95: DATA_AGREEMENTS | C95: B7:T206 | D95: Agreements, restrictions, subsidy and mission-protection evidence | E95: Human / AI may write blue cells | F95: Yes | G95: Feeds future classification/agreement risk logic; not yet repointed | H95: Formula columns A,C,S,U remain live.
A96: PRIMARY CANONICAL INPUT | B96: DATA_CAPITAL_NEEDS | C96: B7:S206 | D96: Capital needs, funded/unfunded gap, fixed asset/depreciation link | E96: Human / AI may write blue cells | F96: Yes | G96: Feeds future capital plan / capital flow; not yet repointed | H96: Formula columns A,C,J,R,T remain live.

Sheet STG_SOURCE_INTAKE
A1: STG_SOURCE_INTAKE
A2: Purpose | B2: Tracks source files received before AI extraction and human validation.
A3: Rule | B3: Does not change calculations until source data is mapped into DATA sheets.
A4: Source_File_ID | B4: NGO / Entity | C4: File Name / Export | D4: Source System | E4: File Type | F4: Fiscal Year / Period | G4: Received Status | H4: AI Extraction Status | I4: Human Review Status | J4: Maps To | K4: Notes
A5: SRC-001 | B5: Future NGO | C5: Yardi rent roll export | D5: Yardi | E5: CSV | F5: YYYY-MM | G5: Not Provided | H5: Not Started | I5: Not Started | J5: DATA_UNIT_MIX / DATA_RENT_ROLL | K5: Example only
A6: SRC-002 | B6: Future NGO | C6: General ledger export | D6: Yardi / Sage / QuickBooks | E6: CSV/XLSX | F6: YYYY | G6: Not Provided | H6: Not Started | I6: Not Started | J6: DATA_OPERATING_ACTUALS | K6: Example only
A7: SRC-003 | B7: Future NGO | C7: Debt schedule | D7: Bank / lender / internal | E7: XLSX/PDF | F7: As of date | G7: Not Provided | H7: Not Started | I7: Not Started | J7: DATA_DEBT_MASTER | K7: Example only
A8: SRC-004 | B8: Future NGO | C8: Property summary workbook | D8: Internal Excel | E8: XLSX | F8: Current | G8: Not Provided | H8: Not Started | I8: Not Started | J8: DATA_PROPERTY_MASTER | K8: Example only
A9: SRC-005 | B9: Future NGO | C9: Operating agreements / covenants | D9: Legal / funder | E9: PDF/DOCX | F9: Active | G9: Not Provided | H9: Not Started | I9: Not Started | J9: DATA_AGREEMENTS | K9: Example only
A102: v11 source-type note | B102: Classify source files as Operating Projection, Rent Roll/Yardi, Operating Actuals/GL, Agreement/Restriction, Capital Needs/FCA, Debt/Amortization, or Capital Product/Bond before mapping to canonical DATA tabs.

Sheet MAP_FIELD_MAPPING
A1: MAP_FIELD_MAPPING — v11 canonical input map
A2: Purpose | B2: Shows what the workbook actually uses today, plus the future canonical source-table target. Prevents the mapping table from promising a system that is not yet wired.
A3: Rule | B3: Current calculation source remains authoritative until the engine is repointed. Canonical tables may exist before they feed calculations; track table existence separately from repoint status.
A5: Source Field / Concept | B5: Current Calculation Source / Live Today | C5: Current Range | D5: Generated Target / Canonical Table | E5: Canonical Field | F5: Write Permission | G5: Repoint Status | H5: Notes
A6: Property ID | B6: 00_MODEL_CONTROL / 01_Property Summary | C6: 00_MODEL_CONTROL!A5:A21; 01_Property Summary!B4:R4 | D6: DATA_PROPERTY_MASTER | E6: Property_ID | F6: Generated from current model | G6: Live bridge | H6: Future NGO: AI should generate DATA_PROPERTY_MASTER rows first.
A7: Property Name | B7: 01_Property Summary | C7: 01_Property Summary!B5:R5 | D7: DATA_PROPERTY_MASTER | E7: Property_Name | F7: Generated from current model | G7: Live bridge | H7: Do not retype names in output tabs.
A8: Included in Model | B8: 00_MODEL_CONTROL | C8: 00_MODEL_CONTROL!E5:E21 | D8: DATA_PROPERTY_MASTER | E8: Included_In_Model | F8: Human / AI input control | G8: Live bridge | H8: This is a controlled input today.
A9: Asset Classification | B9: DATA_ASSET_CLASSIFICATION | C9: DATA_ASSET_CLASSIFICATION!U8:U24 | D9: DATA_ASSET_CLASSIFICATION | E9: Final_Classification | F9: Generated, with controlled override | G9: Live | H9: Human override only via T + Y reason.
A10: Register Bucket | B10: DATA_ASSET_CLASSIFICATION mapping | C10: DATA_ASSET_CLASSIFICATION!AA:AB -> 00_PORTFOLIO_REGISTER!J5:J21 | D10: DATA_ASSET_CLASSIFICATION | E10: Register_Bucket | F10: Generated | G10: Live | H10: Register is no longer an independent source.
A11: Unit Count | B11: 01_Property Summary | C11: 01_Property Summary!B6:R6 | D11: DATA_UNIT_MIX | E11: Unit_Count | F11: Human / AI may write blue cells | G11: Table exists; not engine-repointed | H11: v11 canonical DATA_UNIT_MIX exists; 01_Property Summary still drives calculations.
A12: Rent Roll | B12: BLD_* property tabs / 02_Rent Engine | C12: BLD_* rows 13:36; 02_Rent Engine | D12: DATA_RENT_ROLL | E12: Rent / Occupancy / Program Unit Fields | F12: Human / AI may write blue cells | G12: Table exists; not engine-repointed | H12: v11 canonical DATA_RENT_ROLL exists; rent engine/property tabs still drive calculations.
A13: Operating Actuals | B13: 01_Base Yr. Inputs / BLD_* tabs | C13: 01_Base Yr. Inputs; BLD_* rows 41:55 | D13: DATA_OPERATING_ACTUALS | E13: Revenue / Expense / NOI / AFFO | F13: Human / AI may write blue cells | G13: Table exists; not engine-repointed | H13: v11 canonical DATA_OPERATING_ACTUALS exists; calculations remain property-tab driven.
A14: Debt Terms | B14: 02_Debt Engine / 02A_Debt Schedule | C14: 02_Debt Engine; 02A_Debt Schedule | D14: DATA_DEBT_MASTER | E14: Loan Terms / Maturity / Balance / DS | F14: Generated from current model | G14: Live bridge | H14: Debt master is a bridge, not yet the source engine.
A15: Agreements / Covenants | B15: 01_Property Summary / manual notes | C15: Agreement expiry/status fields where available | D15: DATA_AGREEMENTS | E15: Agreement Type / Expiry / Restriction | F15: Human / AI may write blue cells | G15: Table exists; not engine-repointed | H15: v11 canonical DATA_AGREEMENTS exists; source evidence and downstream logic not fully wired yet.
A16: Capital Needs | B16: 00_CAPITAL_PLAN / BLD_* tabs | C16: 00_CAPITAL_PLAN; BLD_* capital rows where applicable | D16: DATA_CAPITAL_NEEDS | E16: Capex Item / Year / Amount / Funding Source | F16: Human / AI may write blue cells | G16: Table exists; not engine-repointed | H16: v11 canonical DATA_CAPITAL_NEEDS exists; not yet fed to capital plan/capital-flow engine.
... A106: Capital needs / fixed assets | B106: Current model uses capital plan and property/debt outputs | C106: 00_CAPITAL_PLAN; ENF amortization/FCA source files | D106: DATA_CAPITAL_NEEDS | E106: Estimated_Cost, Funded_Amount, Unfunded_Amount, Year_Needed | F106: Human / AI blue input | G106: Canonical table created; not repointed | H106: Connects future capital needs to capital-flow layer.

Sheet DATA_UNIT_MIX
A1: DATA_UNIT_MIX — canonical unit-mix intake
A2: Purpose | B2: One row per property/unit group. Supports NGO-level summaries or AI/Yardi normalized unit mix.
A3: Rule | B3: Created as a canonical intake table only; existing NGO B calculations are not repointed in v11.
A4: Input colour | B4: Blue cells are the only analyst / AI write zones. Black-font cells are live formulas and should not be overwritten.
A6: Record_ID | B6: Property_ID | C6: Property_Name | D6: Unit_Group_ID | E6: Bedroom_Type | F6: Unit_Type | G6: Unit_Count | H6: Affordable_Units | I6: Market_Units | J6: Supportive_Units | K6: Avg_Current_Rent | L6: Avg_Market_Rent | M6: Monthly_Rent_Potential | N6: Below_Market_% | O6: Rent_Restriction_Type | P6: Program_Type | Q6: Rent_Source | R6: Source_File_ID | S6: Source_Confidence | T6: Review_Status | U6: Notes | V6: Row_Status
A7: =IF($B7="","","UM-"&TEXT(ROW()-6,"0000")) | C7: =IFERROR(INDEX(DATA_PROPERTY_MASTER!$B:$B,MATCH($B7,DATA_PROPERTY_MASTER!$A:$A,0)),"") | M7: =IFERROR($G7*$K7,"") -> 0 | N7: =IFERROR(IF($L7>0,1-($K7/$L7),""),"") | V7: =IF($B7="","Blank",IF(OR($G7="",$K7=""),"Review","OK")) -> Blank
A8: =IF($B8="","","UM-"&TEXT(ROW()-6,"0000")) | C8: =IFERROR(INDEX(DATA_PROPERTY_MASTER!$B:$B,MATCH($B8,DATA_PROPERTY_MASTER!$A:$A,0)),"") | M8: =IFERROR($G8*$K8,"") -> 0 | N8: =IFERROR(IF($L8>0,1-($K8/$L8),""),"") | V8: =IF($B8="","Blank",IF(OR($G8="",$K8=""),"Review","OK")) -> Blank
A9: =IF($B9="","","UM-"&TEXT(ROW()-6,"0000")) | C9: =IFERROR(INDEX(DATA_PROPERTY_MASTER!$B:$B,MATCH($B9,DATA_PROPERTY_MASTER!$A:$A,0)),"") | M9: =IFERROR($G9*$K9,"") -> 0 | N9: =IFERROR(IF($L9>0,1-($K9/$L9),""),"") | V9: =IF($B9="","Blank",IF(OR($G9="",$K9=""),"Review","OK")) -> Blank
A10: =IF($B10="","","UM-"&TEXT(ROW()-6,"0000")) | C10: =IFERROR(INDEX(DATA_PROPERTY_MASTER!$B:$B,MATCH($B10,DATA_PROPERTY_MASTER!$A:$A,0)),"") | M10: =IFERROR($G10*$K10,"") -> 0 | N10: =IFERROR(IF($L10>0,1-($K10/$L10),""),"") | V10: =IF($B10="","Blank",IF(OR($G10="",$K10=""),"Review","OK")) -> Blank
A11: =IF($B11="","","UM-"&TEXT(ROW()-6,"0000")) | C11: =IFERROR(INDEX(DATA_PROPERTY_MASTER!$B:$B,MATCH($B11,DATA_PROPERTY_MASTER!$A:$A,0)),"") | M11: =IFERROR($G11*$K11,"") -> 0 | N11: =IFERROR(IF($L11>0,1-($K11/$L11),""),"") | V11: =IF($B11="","Blank",IF(OR($G11="",$K11=""),"Review","OK")) -> Blank
A12: =IF($B12="","","UM-"&TEXT(ROW()-6,"0000")) | C12: =IFERROR(INDEX(DATA_PROPERTY_MASTER!$B:$B,MATCH($B12,DATA_PROPERTY_MASTER!$A:$A,0)),"") | M12: =IFERROR($G12*$K12,"") -> 0 | N12: =IFERROR(IF($L12>0,1-($K12/$L12),""),"") | V12: =IF($B12="","Blank",IF(OR($G12="",$K12=""),"Review","OK")) -> Blank
A13: =IF($B13="","","UM-"&TEXT(ROW()-6,"0000")) | C13: =IFERROR(INDEX(DATA_PROPERTY_MASTER!$B:$B,MATCH($B13,DATA_PROPERTY_MASTER!$A:$A,0)),"") | M13: =IFERROR($G13*$K13,"") -> 0 | N13: =IFERROR(IF($L13>0,1-($K13/$L13),""),"") | V13: =IF($B13="","Blank",IF(OR($G13="",$K13=""),"Review","OK")) -> Blank
A14: =IF($B14="","","UM-"&TEXT(ROW()-6,"0000")) | C14: =IFERROR(INDEX(DATA_PROPERTY_MASTER!$B:$B,MATCH($B14,DATA_PROPERTY_MASTER!$A:$A,0)),"") | M14: =IFERROR($G14*$K14,"") -> 0 | N14: =IFERROR(IF($L14>0,1-($K14/$L14),""),"") | V14: =IF($B14="","Blank",IF(OR($G14="",$K14=""),"Review","OK")) -> Blank
A15: =IF($B15="","","UM-"&TEXT(ROW()-6,"0000")) | C15: =IFERROR(INDEX(DATA_PROPERTY_MASTER!$B:$B,MATCH($B15,DATA_PROPERTY_MASTER!$A:$A,0)),"") | M15: =IFERROR($G15*$K15,"") -> 0 | N15: =IFERROR(IF($L15>0,1-($K15/$L15),""),"") | V15: =IF($B15="","Blank",IF(OR($G15="",$K15=""),"Review","OK")) -> Blank
A16: =IF($B16="","","UM-"&TEXT(ROW()-6,"0000")) | C16: =IFERROR(INDEX(DATA_PROPERTY_MASTER!$B:$B,MATCH($B16,DATA_PROPERTY_MASTER!$A:$A,0)),"") | M16: =IFERROR($G16*$K16,"") -> 0 | N16: =IFERROR(IF($L16>0,1-($K16/$L16),""),"") | V16: =IF($B16="","Blank",IF(OR($G16="",$K16=""),"Review","OK")) -> Blank
A17: =IF($B17="","","UM-"&TEXT(ROW()-6,"0000")) | C17: =IFERROR(INDEX(DATA_PROPERTY_MASTER!$B:$B,MATCH($B17,DATA_PROPERTY_MASTER!$A:$A,0)),"") | M17: =IFERROR($G17*$K17,"") -> 0 | N17: =IFERROR(IF($L17>0,1-($K17/$L17),""),"") | V17: =IF($B17="","Blank",IF(OR($G17="",$K17=""),"Review","OK")) -> Blank
A18: =IF($B18="","","UM-"&TEXT(ROW()-6,"0000")) | C18: =IFERROR(INDEX(DATA_PROPERTY_MASTER!$B:$B,MATCH($B18,DATA_PROPERTY_MASTER!$A:$A,0)),"") | M18: =IFERROR($G18*$K18,"") -> 0 | N18: =IFERROR(IF($L18>0,1-($K18/$L18),""),"") | V18: =IF($B18="","Blank",IF(OR($G18="",$K18=""),"Review","OK")) -> Blank
... A206: =IF($B206="","","UM-"&TEXT(ROW()-6,"0000")) | C206: =IFERROR(INDEX(DATA_PROPERTY_MASTER!$B:$B,MATCH($B206,DATA_PROPERTY_MASTER!$A:$A,0)),"") | M206: =IFERROR($G206*$K206,"") -> 0 | N206: =IFERROR(IF($L206>0,1-($K206/$L206),""),"") | V206: =IF($B206="","Blank",IF(OR($G206="",$K206=""),"Review","OK")) -> Blank

Sheet DATA_RENT_ROLL
A1: DATA_RENT_ROLL — canonical rent-roll intake
A2: Purpose | B2: Captures either unit-level rent roll or summarized rent by unit group.
A3: Rule | B3: Optional/recommended canonical table; if unavailable, DATA_UNIT_MIX and operating revenue can still support the model.
A4: Input colour | B4: Blue cells are the only analyst / AI write zones. Black-font cells are live formulas and should not be overwritten.
A6: Record_ID | B6: Property_ID | C6: Property_Name | D6: Rent_Record_Level | E6: Unit_ID_or_Group | F6: Bedroom_Type | G6: Unit_Type | H6: Unit_Count | I6: Tenant_Status | J6: Vacancy_Status | K6: Current_Monthly_Rent | L6: Market_Monthly_Rent | M6: Subsidy_Amount | N6: Utility_Allowance | O6: Effective_Date | P6: Annual_Current_Rent | Q6: Annual_Market_Rent | R6: Below_Market_% | S6: Source_File_ID | T6: Source_Confidence | U6: Review_Status | V6: Notes | W6: Row_Status
A7: =IF($B7="","","RR-"&TEXT(ROW()-6,"0000")) | C7: =IFERROR(INDEX(DATA_PROPERTY_MASTER!$B:$B,MATCH($B7,DATA_PROPERTY_MASTER!$A:$A,0)),"") | P7: =IFERROR($H7*$K7*12,"") -> 0 | Q7: =IFERROR($H7*$L7*12,"") -> 0 | R7: =IFERROR(IF($L7>0,1-($K7/$L7),""),"") | W7: =IF($B7="","Blank",IF(OR($K7="",$H7=""),"Review","OK")) -> Blank
A8: =IF($B8="","","RR-"&TEXT(ROW()-6,"0000")) | C8: =IFERROR(INDEX(DATA_PROPERTY_MASTER!$B:$B,MATCH($B8,DATA_PROPERTY_MASTER!$A:$A,0)),"") | P8: =IFERROR($H8*$K8*12,"") -> 0 | Q8: =IFERROR($H8*$L8*12,"") -> 0 | R8: =IFERROR(IF($L8>0,1-($K8/$L8),""),"") | W8: =IF($B8="","Blank",IF(OR($K8="",$H8=""),"Review","OK")) -> Blank
A9: =IF($B9="","","RR-"&TEXT(ROW()-6,"0000")) | C9: =IFERROR(INDEX(DATA_PROPERTY_MASTER!$B:$B,MATCH($B9,DATA_PROPERTY_MASTER!$A:$A,0)),"") | P9: =IFERROR($H9*$K9*12,"") -> 0 | Q9: =IFERROR($H9*$L9*12,"") -> 0 | R9: =IFERROR(IF($L9>0,1-($K9/$L9),""),"") | W9: =IF($B9="","Blank",IF(OR($K9="",$H9=""),"Review","OK")) -> Blank
A10: =IF($B10="","","RR-"&TEXT(ROW()-6,"0000")) | C10: =IFERROR(INDEX(DATA_PROPERTY_MASTER!$B:$B,MATCH($B10,DATA_PROPERTY_MASTER!$A:$A,0)),"") | P10: =IFERROR($H10*$K10*12,"") -> 0 | Q10: =IFERROR($H10*$L10*12,"") -> 0 | R10: =IFERROR(IF($L10>0,1-($K10/$L10),""),"") | W10: =IF($B10="","Blank",IF(OR($K10="",$H10=""),"Review","OK")) -> Blank
A11: =IF($B11="","","RR-"&TEXT(ROW()-6,"0000")) | C11: =IFERROR(INDEX(DATA_PROPERTY_MASTER!$B:$B,MATCH($B11,DATA_PROPERTY_MASTER!$A:$A,0)),"") | P11: =IFERROR($H11*$K11*12,"") -> 0 | Q11: =IFERROR($H11*$L11*12,"") -> 0 | R11: =IFERROR(IF($L11>0,1-($K11/$L11),""),"") | W11: =IF($B11="","Blank",IF(OR($K11="",$H11=""),"Review","OK")) -> Blank
A12: =IF($B12="","","RR-"&TEXT(ROW()-6,"0000")) | C12: =IFERROR(INDEX(DATA_PROPERTY_MASTER!$B:$B,MATCH($B12,DATA_PROPERTY_MASTER!$A:$A,0)),"") | P12: =IFERROR($H12*$K12*12,"") -> 0 | Q12: =IFERROR($H12*$L12*12,"") -> 0 | R12: =IFERROR(IF($L12>0,1-($K12/$L12),""),"") | W12: =IF($B12="","Blank",IF(OR($K12="",$H12=""),"Review","OK")) -> Blank
A13: =IF($B13="","","RR-"&TEXT(ROW()-6,"0000")) | C13: =IFERROR(INDEX(DATA_PROPERTY_MASTER!$B:$B,MATCH($B13,DATA_PROPERTY_MASTER!$A:$A,0)),"") | P13: =IFERROR($H13*$K13*12,"") -> 0 | Q13: =IFERROR($H13*$L13*12,"") -> 0 | R13: =IFERROR(IF($L13>0,1-($K13/$L13),""),"") | W13: =IF($B13="","Blank",IF(OR($K13="",$H13=""),"Review","OK")) -> Blank
A14: =IF($B14="","","RR-"&TEXT(ROW()-6,"0000")) | C14: =IFERROR(INDEX(DATA_PROPERTY_MASTER!$B:$B,MATCH($B14,DATA_PROPERTY_MASTER!$A:$A,0)),"") | P14: =IFERROR($H14*$K14*12,"") -> 0 | Q14: =IFERROR($H14*$L14*12,"") -> 0 | R14: =IFERROR(IF($L14>0,1-($K14/$L14),""),"") | W14: =IF($B14="","Blank",IF(OR($K14="",$H14=""),"Review","OK")) -> Blank
A15: =IF($B15="","","RR-"&TEXT(ROW()-6,"0000")) | C15: =IFERROR(INDEX(DATA_PROPERTY_MASTER!$B:$B,MATCH($B15,DATA_PROPERTY_MASTER!$A:$A,0)),"") | P15: =IFERROR($H15*$K15*12,"") -> 0 | Q15: =IFERROR($H15*$L15*12,"") -> 0 | R15: =IFERROR(IF($L15>0,1-($K15/$L15),""),"") | W15: =IF($B15="","Blank",IF(OR($K15="",$H15=""),"Review","OK")) -> Blank
A16: =IF($B16="","","RR-"&TEXT(ROW()-6,"0000")) | C16: =IFERROR(INDEX(DATA_PROPERTY_MASTER!$B:$B,MATCH($B16,DATA_PROPERTY_MASTER!$A:$A,0)),"") | P16: =IFERROR($H16*$K16*12,"") -> 0 | Q16: =IFERROR($H16*$L16*12,"") -> 0 | R16: =IFERROR(IF($L16>0,1-($K16/$L16),""),"") | W16: =IF($B16="","Blank",IF(OR($K16="",$H16=""),"Review","OK")) -> Blank
A17: =IF($B17="","","RR-"&TEXT(ROW()-6,"0000")) | C17: =IFERROR(INDEX(DATA_PROPERTY_MASTER!$B:$B,MATCH($B17,DATA_PROPERTY_MASTER!$A:$A,0)),"") | P17: =IFERROR($H17*$K17*12,"") -> 0 | Q17: =IFERROR($H17*$L17*12,"") -> 0 | R17: =IFERROR(IF($L17>0,1-($K17/$L17),""),"") | W17: =IF($B17="","Blank",IF(OR($K17="",$H17=""),"Review","OK")) -> Blank
A18: =IF($B18="","","RR-"&TEXT(ROW()-6,"0000")) | C18: =IFERROR(INDEX(DATA_PROPERTY_MASTER!$B:$B,MATCH($B18,DATA_PROPERTY_MASTER!$A:$A,0)),"") | P18: =IFERROR($H18*$K18*12,"") -> 0 | Q18: =IFERROR($H18*$L18*12,"") -> 0 | R18: =IFERROR(IF($L18>0,1-($K18/$L18),""),"") | W18: =IF($B18="","Blank",IF(OR($K18="",$H18=""),"Review","OK")) -> Blank
... A206: =IF($B206="","","RR-"&TEXT(ROW()-6,"0000")) | C206: =IFERROR(INDEX(DATA_PROPERTY_MASTER!$B:$B,MATCH($B206,DATA_PROPERTY_MASTER!$A:$A,0)),"") | P206: =IFERROR($H206*$K206*12,"") -> 0 | Q206: =IFERROR($H206*$L206*12,"") -> 0 | R206: =IFERROR(IF($L206>0,1-($K206/$L206),""),"") | W206: =IF($B206="","Blank",IF(OR($K206="",$H206=""),"Review","OK")) -> Blank

Sheet DATA_OPERATING_ACTUALS
A1: DATA_OPERATING_ACTUALS — canonical operating actuals / budget / projection intake
A2: Purpose | B2: Long-format operating data by property, year, period, scenario, and standardized IREI category.
A3: Rule | B3: This is the future replacement path for 01_Base Yr. Inputs; v11 does not repoint the live engine yet.
A4: Input colour | B4: Blue cells are the only analyst / AI write zones. Black-font cells are live formulas and should not be overwritten.
A6: Record_ID | B6: Property_ID | C6: Property_Name | D6: Fiscal_Year | E6: Period | F6: Scenario | G6: Actual_Budget_Projection | H6: Source_Line_Item | I6: IREI_Category | J6: Amount | K6: Cash_or_Accrual | L6: Source_File_ID | M6: Source_Confidence | N6: Mapping_Confidence | O6: Review_Status | P6: Standardized_Key | Q6: Notes | R6: Row_Status
A7: =IF($B7="","","OA-"&TEXT(ROW()-6,"0000")) | C7: =IFERROR(INDEX(DATA_PROPERTY_MASTER!$B:$B,MATCH($B7,DATA_PROPERTY_MASTER!$A:$A,0)),"") | P7: =IF($B7="","",$B7&"|"&$D7&"|"&$F7&"|"&$I7) | R7: =IF($B7="","Blank",IF(OR($D7="",$I7="",$J7=""),"Review","OK")) -> Blank
A8: =IF($B8="","","OA-"&TEXT(ROW()-6,"0000")) | C8: =IFERROR(INDEX(DATA_PROPERTY_MASTER!$B:$B,MATCH($B8,DATA_PROPERTY_MASTER!$A:$A,0)),"") | P8: =IF($B8="","",$B8&"|"&$D8&"|"&$F8&"|"&$I8) | R8: =IF($B8="","Blank",IF(OR($D8="",$I8="",$J8=""),"Review","OK")) -> Blank
A9: =IF($B9="","","OA-"&TEXT(ROW()-6,"0000")) | C9: =IFERROR(INDEX(DATA_PROPERTY_MASTER!$B:$B,MATCH($B9,DATA_PROPERTY_MASTER!$A:$A,0)),"") | P9: =IF($B9="","",$B9&"|"&$D9&"|"&$F9&"|"&$I9) | R9: =IF($B9="","Blank",IF(OR($D9="",$I9="",$J9=""),"Review","OK")) -> Blank
A10: =IF($B10="","","OA-"&TEXT(ROW()-6,"0000")) | C10: =IFERROR(INDEX(DATA_PROPERTY_MASTER!$B:$B,MATCH($B10,DATA_PROPERTY_MASTER!$A:$A,0)),"") | P10: =IF($B10="","",$B10&"|"&$D10&"|"&$F10&"|"&$I10) | R10: =IF($B10="","Blank",IF(OR($D10="",$I10="",$J10=""),"Review","OK")) -> Blank
A11: =IF($B11="","","OA-"&TEXT(ROW()-6,"0000")) | C11: =IFERROR(INDEX(DATA_PROPERTY_MASTER!$B:$B,MATCH($B11,DATA_PROPERTY_MASTER!$A:$A,0)),"") | P11: =IF($B11="","",$B11&"|"&$D11&"|"&$F11&"|"&$I11) | R11: =IF($B11="","Blank",IF(OR($D11="",$I11="",$J11=""),"Review","OK")) -> Blank
A12: =IF($B12="","","OA-"&TEXT(ROW()-6,"0000")) | C12: =IFERROR(INDEX(DATA_PROPERTY_MASTER!$B:$B,MATCH($B12,DATA_PROPERTY_MASTER!$A:$A,0)),"") | P12: =IF($B12="","",$B12&"|"&$D12&"|"&$F12&"|"&$I12) | R12: =IF($B12="","Blank",IF(OR($D12="",$I12="",$J12=""),"Review","OK")) -> Blank
A13: =IF($B13="","","OA-"&TEXT(ROW()-6,"0000")) | C13: =IFERROR(INDEX(DATA_PROPERTY_MASTER!$B:$B,MATCH($B13,DATA_PROPERTY_MASTER!$A:$A,0)),"") | P13: =IF($B13="","",$B13&"|"&$D13&"|"&$F13&"|"&$I13) | R13: =IF($B13="","Blank",IF(OR($D13="",$I13="",$J13=""),"Review","OK")) -> Blank
A14: =IF($B14="","","OA-"&TEXT(ROW()-6,"0000")) | C14: =IFERROR(INDEX(DATA_PROPERTY_MASTER!$B:$B,MATCH($B14,DATA_PROPERTY_MASTER!$A:$A,0)),"") | P14: =IF($B14="","",$B14&"|"&$D14&"|"&$F14&"|"&$I14) | R14: =IF($B14="","Blank",IF(OR($D14="",$I14="",$J14=""),"Review","OK")) -> Blank
A15: =IF($B15="","","OA-"&TEXT(ROW()-6,"0000")) | C15: =IFERROR(INDEX(DATA_PROPERTY_MASTER!$B:$B,MATCH($B15,DATA_PROPERTY_MASTER!$A:$A,0)),"") | P15: =IF($B15="","",$B15&"|"&$D15&"|"&$F15&"|"&$I15) | R15: =IF($B15="","Blank",IF(OR($D15="",$I15="",$J15=""),"Review","OK")) -> Blank
A16: =IF($B16="","","OA-"&TEXT(ROW()-6,"0000")) | C16: =IFERROR(INDEX(DATA_PROPERTY_MASTER!$B:$B,MATCH($B16,DATA_PROPERTY_MASTER!$A:$A,0)),"") | P16: =IF($B16="","",$B16&"|"&$D16&"|"&$F16&"|"&$I16) | R16: =IF($B16="","Blank",IF(OR($D16="",$I16="",$J16=""),"Review","OK")) -> Blank
A17: =IF($B17="","","OA-"&TEXT(ROW()-6,"0000")) | C17: =IFERROR(INDEX(DATA_PROPERTY_MASTER!$B:$B,MATCH($B17,DATA_PROPERTY_MASTER!$A:$A,0)),"") | P17: =IF($B17="","",$B17&"|"&$D17&"|"&$F17&"|"&$I17) | R17: =IF($B17="","Blank",IF(OR($D17="",$I17="",$J17=""),"Review","OK")) -> Blank
A18: =IF($B18="","","OA-"&TEXT(ROW()-6,"0000")) | C18: =IFERROR(INDEX(DATA_PROPERTY_MASTER!$B:$B,MATCH($B18,DATA_PROPERTY_MASTER!$A:$A,0)),"") | P18: =IF($B18="","",$B18&"|"&$D18&"|"&$F18&"|"&$I18) | R18: =IF($B18="","Blank",IF(OR($D18="",$I18="",$J18=""),"Review","OK")) -> Blank
... A206: =IF($B206="","","OA-"&TEXT(ROW()-6,"0000")) | C206: =IFERROR(INDEX(DATA_PROPERTY_MASTER!$B:$B,MATCH($B206,DATA_PROPERTY_MASTER!$A:$A,0)),"") | P206: =IF($B206="","",$B206&"|"&$D206&"|"&$F206&"|"&$I206) | R206: =IF($B206="","Blank",IF(OR($D206="",$I206="",$J206=""),"Review","OK")) -> Blank

Sheet DATA_AGREEMENTS
A1: DATA_AGREEMENTS — canonical agreements / restrictions intake
A2: Purpose | B2: Captures operating agreements, covenants, affordability restrictions, subsidies, leases, and mission-protection constraints.
A3: Rule | B3: This is a key IREI table; v11 creates the evidence structure without repointing calculations.
A4: Input colour | B4: Blue cells are the only analyst / AI write zones. Black-font cells are live formulas and should not be overwritten.
A6: Agreement_ID | B6: Property_ID | C6: Property_Name | D6: Agreement_Type | E6: Counterparty | F6: Start_Date | G6: End_Date | H6: Affordability_Requirement | I6: Rent_Restriction | J6: Use_Restriction | K6: Refinance_Restriction | L6: Disposition_Restriction | M6: Subsidy_Linked | N6: Renewal_Risk | O6: Mission_Protection_Flag | P6: Source_File_ID | Q6: Source_Confidence | R6: Review_Status | S6: Agreement_Status | T6: Notes | U6: Row_Status
A7: =IF($B7="","","AGR-"&TEXT(ROW()-6,"0000")) | C7: =IFERROR(INDEX(DATA_PROPERTY_MASTER!$B:$B,MATCH($B7,DATA_PROPERTY_MASTER!$A:$A,0)),"") | S7: =IF($B7="","",IF($G7="","No end date",IF($G7<TODAY(),"Expired / Review","Active / Future"))) | U7: =IF($B7="","Blank",IF(OR($D7="",$H7=""),"Review","OK")) -> Blank
A8: =IF($B8="","","AGR-"&TEXT(ROW()-6,"0000")) | C8: =IFERROR(INDEX(DATA_PROPERTY_MASTER!$B:$B,MATCH($B8,DATA_PROPERTY_MASTER!$A:$A,0)),"") | S8: =IF($B8="","",IF($G8="","No end date",IF($G8<TODAY(),"Expired / Review","Active / Future"))) | U8: =IF($B8="","Blank",IF(OR($D8="",$H8=""),"Review","OK")) -> Blank
A9: =IF($B9="","","AGR-"&TEXT(ROW()-6,"0000")) | C9: =IFERROR(INDEX(DATA_PROPERTY_MASTER!$B:$B,MATCH($B9,DATA_PROPERTY_MASTER!$A:$A,0)),"") | S9: =IF($B9="","",IF($G9="","No end date",IF($G9<TODAY(),"Expired / Review","Active / Future"))) | U9: =IF($B9="","Blank",IF(OR($D9="",$H9=""),"Review","OK")) -> Blank
A10: =IF($B10="","","AGR-"&TEXT(ROW()-6,"0000")) | C10: =IFERROR(INDEX(DATA_PROPERTY_MASTER!$B:$B,MATCH($B10,DATA_PROPERTY_MASTER!$A:$A,0)),"") | S10: =IF($B10="","",IF($G10="","No end date",IF($G10<TODAY(),"Expired / Review","Active / Future"))) | U10: =IF($B10="","Blank",IF(OR($D10="",$H10=""),"Review","OK")) -> Blank
A11: =IF($B11="","","AGR-"&TEXT(ROW()-6,"0000")) | C11: =IFERROR(INDEX(DATA_PROPERTY_MASTER!$B:$B,MATCH($B11,DATA_PROPERTY_MASTER!$A:$A,0)),"") | S11: =IF($B11="","",IF($G11="","No end date",IF($G11<TODAY(),"Expired / Review","Active / Future"))) | U11: =IF($B11="","Blank",IF(OR($D11="",$H11=""),"Review","OK")) -> Blank
A12: =IF($B12="","","AGR-"&TEXT(ROW()-6,"0000")) | C12: =IFERROR(INDEX(DATA_PROPERTY_MASTER!$B:$B,MATCH($B12,DATA_PROPERTY_MASTER!$A:$A,0)),"") | S12: =IF($B12="","",IF($G12="","No end date",IF($G12<TODAY(),"Expired / Review","Active / Future"))) | U12: =IF($B12="","Blank",IF(OR($D12="",$H12=""),"Review","OK")) -> Blank
A13: =IF($B13="","","AGR-"&TEXT(ROW()-6,"0000")) | C13: =IFERROR(INDEX(DATA_PROPERTY_MASTER!$B:$B,MATCH($B13,DATA_PROPERTY_MASTER!$A:$A,0)),"") | S13: =IF($B13="","",IF($G13="","No end date",IF($G13<TODAY(),"Expired / Review","Active / Future"))) | U13: =IF($B13="","Blank",IF(OR($D13="",$H13=""),"Review","OK")) -> Blank
A14: =IF($B14="","","AGR-"&TEXT(ROW()-6,"0000")) | C14: =IFERROR(INDEX(DATA_PROPERTY_MASTER!$B:$B,MATCH($B14,DATA_PROPERTY_MASTER!$A:$A,0)),"") | S14: =IF($B14="","",IF($G14="","No end date",IF($G14<TODAY(),"Expired / Review","Active / Future"))) | U14: =IF($B14="","Blank",IF(OR($D14="",$H14=""),"Review","OK")) -> Blank
A15: =IF($B15="","","AGR-"&TEXT(ROW()-6,"0000")) | C15: =IFERROR(INDEX(DATA_PROPERTY_MASTER!$B:$B,MATCH($B15,DATA_PROPERTY_MASTER!$A:$A,0)),"") | S15: =IF($B15="","",IF($G15="","No end date",IF($G15<TODAY(),"Expired / Review","Active / Future"))) | U15: =IF($B15="","Blank",IF(OR($D15="",$H15=""),"Review","OK")) -> Blank
A16: =IF($B16="","","AGR-"&TEXT(ROW()-6,"0000")) | C16: =IFERROR(INDEX(DATA_PROPERTY_MASTER!$B:$B,MATCH($B16,DATA_PROPERTY_MASTER!$A:$A,0)),"") | S16: =IF($B16="","",IF($G16="","No end date",IF($G16<TODAY(),"Expired / Review","Active / Future"))) | U16: =IF($B16="","Blank",IF(OR($D16="",$H16=""),"Review","OK")) -> Blank
A17: =IF($B17="","","AGR-"&TEXT(ROW()-6,"0000")) | C17: =IFERROR(INDEX(DATA_PROPERTY_MASTER!$B:$B,MATCH($B17,DATA_PROPERTY_MASTER!$A:$A,0)),"") | S17: =IF($B17="","",IF($G17="","No end date",IF($G17<TODAY(),"Expired / Review","Active / Future"))) | U17: =IF($B17="","Blank",IF(OR($D17="",$H17=""),"Review","OK")) -> Blank
A18: =IF($B18="","","AGR-"&TEXT(ROW()-6,"0000")) | C18: =IFERROR(INDEX(DATA_PROPERTY_MASTER!$B:$B,MATCH($B18,DATA_PROPERTY_MASTER!$A:$A,0)),"") | S18: =IF($B18="","",IF($G18="","No end date",IF($G18<TODAY(),"Expired / Review","Active / Future"))) | U18: =IF($B18="","Blank",IF(OR($D18="",$H18=""),"Review","OK")) -> Blank
... A206: =IF($B206="","","AGR-"&TEXT(ROW()-6,"0000")) | C206: =IFERROR(INDEX(DATA_PROPERTY_MASTER!$B:$B,MATCH($B206,DATA_PROPERTY_MASTER!$A:$A,0)),"") | S206: =IF($B206="","",IF($G206="","No end date",IF($G206<TODAY(),"Expired / Review","Active / Future"))) | U206: =IF($B206="","Blank",IF(OR($D206="",$H206=""),"Review","OK")) -> Blank

Sheet DATA_CAPITAL_NEEDS
A1: DATA_CAPITAL_NEEDS — canonical capital needs / fixed-asset intake
A2: Purpose | B2: Captures repairs, replacements, deferred maintenance, redevelopment, fixed-asset additions, and funded/unfunded capital needs.
A3: Rule | B3: Created as canonical intake; future versions can feed DATA_CAPITAL_FLOW and capital planning outputs.
A4: Input colour | B4: Blue cells are the only analyst / AI write zones. Black-font cells are live formulas and should not be overwritten.
A6: Capital_Item_ID | B6: Property_ID | C6: Property_Name | D6: Capital_Item | E6: Capital_Category | F6: Required_or_Discretionary | G6: Year_Needed | H6: Estimated_Cost | I6: Funded_Amount | J6: Unfunded_Amount | K6: Funding_Source | L6: Deferred_Maintenance_Flag | M6: Development_Related | N6: Fixed_Asset_or_Depreciation_Link | O6: Source_File_ID | P6: Source_Confidence | Q6: Review_Status | R6: Funding_Gap_Flag | S6: Notes | T6: Row_Status
A7: =IF($B7="","","CN-"&TEXT(ROW()-6,"0000")) | C7: =IFERROR(INDEX(DATA_PROPERTY_MASTER!$B:$B,MATCH($B7,DATA_PROPERTY_MASTER!$A:$A,0)),"") | J7: =IFERROR(MAX($H7-$I7,0),"") -> 0 | R7: =IF($B7="","",IF($J7>0,"Funding Gap","Funded / No Gap")) | T7: =IF($B7="","Blank",IF(OR($D7="",$G7="",$H7=""),"Review","OK")) -> Blank
A8: =IF($B8="","","CN-"&TEXT(ROW()-6,"0000")) | C8: =IFERROR(INDEX(DATA_PROPERTY_MASTER!$B:$B,MATCH($B8,DATA_PROPERTY_MASTER!$A:$A,0)),"") | J8: =IFERROR(MAX($H8-$I8,0),"") -> 0 | R8: =IF($B8="","",IF($J8>0,"Funding Gap","Funded / No Gap")) | T8: =IF($B8="","Blank",IF(OR($D8="",$G8="",$H8=""),"Review","OK")) -> Blank
A9: =IF($B9="","","CN-"&TEXT(ROW()-6,"0000")) | C9: =IFERROR(INDEX(DATA_PROPERTY_MASTER!$B:$B,MATCH($B9,DATA_PROPERTY_MASTER!$A:$A,0)),"") | J9: =IFERROR(MAX($H9-$I9,0),"") -> 0 | R9: =IF($B9="","",IF($J9>0,"Funding Gap","Funded / No Gap")) | T9: =IF($B9="","Blank",IF(OR($D9="",$G9="",$H9=""),"Review","OK")) -> Blank
A10: =IF($B10="","","CN-"&TEXT(ROW()-6,"0000")) | C10: =IFERROR(INDEX(DATA_PROPERTY_MASTER!$B:$B,MATCH($B10,DATA_PROPERTY_MASTER!$A:$A,0)),"") | J10: =IFERROR(MAX($H10-$I10,0),"") -> 0 | R10: =IF($B10="","",IF($J10>0,"Funding Gap","Funded / No Gap")) | T10: =IF($B10="","Blank",IF(OR($D10="",$G10="",$H10=""),"Review","OK")) -> Blank
A11: =IF($B11="","","CN-"&TEXT(ROW()-6,"0000")) | C11: =IFERROR(INDEX(DATA_PROPERTY_MASTER!$B:$B,MATCH($B11,DATA_PROPERTY_MASTER!$A:$A,0)),"") | J11: =IFERROR(MAX($H11-$I11,0),"") -> 0 | R11: =IF($B11="","",IF($J11>0,"Funding Gap","Funded / No Gap")) | T11: =IF($B11="","Blank",IF(OR($D11="",$G11="",$H11=""),"Review","OK")) -> Blank
A12: =IF($B12="","","CN-"&TEXT(ROW()-6,"0000")) | C12: =IFERROR(INDEX(DATA_PROPERTY_MASTER!$B:$B,MATCH($B12,DATA_PROPERTY_MASTER!$A:$A,0)),"") | J12: =IFERROR(MAX($H12-$I12,0),"") -> 0 | R12: =IF($B12="","",IF($J12>0,"Funding Gap","Funded / No Gap")) | T12: =IF($B12="","Blank",IF(OR($D12="",$G12="",$H12=""),"Review","OK")) -> Blank
A13: =IF($B13="","","CN-"&TEXT(ROW()-6,"0000")) | C13: =IFERROR(INDEX(DATA_PROPERTY_MASTER!$B:$B,MATCH($B13,DATA_PROPERTY_MASTER!$A:$A,0)),"") | J13: =IFERROR(MAX($H13-$I13,0),"") -> 0 | R13: =IF($B13="","",IF($J13>0,"Funding Gap","Funded / No Gap")) | T13: =IF($B13="","Blank",IF(OR($D13="",$G13="",$H13=""),"Review","OK")) -> Blank
A14: =IF($B14="","","CN-"&TEXT(ROW()-6,"0000")) | C14: =IFERROR(INDEX(DATA_PROPERTY_MASTER!$B:$B,MATCH($B14,DATA_PROPERTY_MASTER!$A:$A,0)),"") | J14: =IFERROR(MAX($H14-$I14,0),"") -> 0 | R14: =IF($B14="","",IF($J14>0,"Funding Gap","Funded / No Gap")) | T14: =IF($B14="","Blank",IF(OR($D14="",$G14="",$H14=""),"Review","OK")) -> Blank
A15: =IF($B15="","","CN-"&TEXT(ROW()-6,"0000")) | C15: =IFERROR(INDEX(DATA_PROPERTY_MASTER!$B:$B,MATCH($B15,DATA_PROPERTY_MASTER!$A:$A,0)),"") | J15: =IFERROR(MAX($H15-$I15,0),"") -> 0 | R15: =IF($B15="","",IF($J15>0,"Funding Gap","Funded / No Gap")) | T15: =IF($B15="","Blank",IF(OR($D15="",$G15="",$H15=""),"Review","OK")) -> Blank
A16: =IF($B16="","","CN-"&TEXT(ROW()-6,"0000")) | C16: =IFERROR(INDEX(DATA_PROPERTY_MASTER!$B:$B,MATCH($B16,DATA_PROPERTY_MASTER!$A:$A,0)),"") | J16: =IFERROR(MAX($H16-$I16,0),"") -> 0 | R16: =IF($B16="","",IF($J16>0,"Funding Gap","Funded / No Gap")) | T16: =IF($B16="","Blank",IF(OR($D16="",$G16="",$H16=""),"Review","OK")) -> Blank
A17: =IF($B17="","","CN-"&TEXT(ROW()-6,"0000")) | C17: =IFERROR(INDEX(DATA_PROPERTY_MASTER!$B:$B,MATCH($B17,DATA_PROPERTY_MASTER!$A:$A,0)),"") | J17: =IFERROR(MAX($H17-$I17,0),"") -> 0 | R17: =IF($B17="","",IF($J17>0,"Funding Gap","Funded / No Gap")) | T17: =IF($B17="","Blank",IF(OR($D17="",$G17="",$H17=""),"Review","OK")) -> Blank
A18: =IF($B18="","","CN-"&TEXT(ROW()-6,"0000")) | C18: =IFERROR(INDEX(DATA_PROPERTY_MASTER!$B:$B,MATCH($B18,DATA_PROPERTY_MASTER!$A:$A,0)),"") | J18: =IFERROR(MAX($H18-$I18,0),"") -> 0 | R18: =IF($B18="","",IF($J18>0,"Funding Gap","Funded / No Gap")) | T18: =IF($B18="","Blank",IF(OR($D18="",$G18="",$H18=""),"Review","OK")) -> Blank
... A206: =IF($B206="","","CN-"&TEXT(ROW()-6,"0000")) | C206: =IFERROR(INDEX(DATA_PROPERTY_MASTER!$B:$B,MATCH($B206,DATA_PROPERTY_MASTER!$A:$A,0)),"") | J206: =IFERROR(MAX($H206-$I206,0),"") -> 0 | R206: =IF($B206="","",IF($J206>0,"Funding Gap","Funded / No Gap")) | T206: =IF($B206="","Blank",IF(OR($D206="",$G206="",$H206=""),"Review","OK")) -> Blank

Sheet 01_Property Summary
B2: PROPERTY SUMMARY (2026) — RAW DATA (USER-TOGGLE)
B3: Property | I3: Ownership / Operating Agreements | L3: Mortgage | S3: Unit Count
B4: Tab ID | C4: Property | D4: Address | E4: City | F4: Start Yr. (Current Yr. if Active) | G4: Status | I4: Lease Type | J4: Lease Expiry | K4: Operating Agreement Expiry | L4: Mortgage | M4: Interest Rate | N4: Term Date (Month/Yr.) | O4: Amortizing Years | P4: Annual Mortgage Payment | Q4: Annual Mortgage Subsidy | R4: Mortgage Balance Outstanding 2025 | S4: Total Units | T4: Studios | U4: 1 Bedroom | V4: 2 Bedroom | W4: 3 Bedroom | X4: 4 Bedroom
B5: BLD_AB | C5: Alma Blackwell | D5: 1656 Adanac Street | E5: Vancouver | F5: 2025 | G5: Active | I5: Owned | J5: N/A | K5: 2027 | L5: N/A | S5: 46 | T5: 0 | U5: 6 | V5: 24 | W5: 14 | X5: 2
B6: BLD_AC | C6: Antkiw Court | D6: 1534 E. 4th Avenue | E6: Vancouver | F6: 2025 | G6: Active | I6: Owned | J6: N/A | K6: 2028 | L6: BCHMC/NPAT | M6: 0.04024 | N6: 49461 | O6: 22 | P6: 54330.12 | Q6: 54330.12 | R6: 794745.17 | S6: 21 | T6: 0 | U6: 0 | V6: 13 | W6: 6 | X6: 2
B7: BLD_BT | C7: Beatrice Terrace | D7: 1877 E. Georgia Street | E7: Vancouver | F7: 2025 | G7: Active | I7: Owned | J7: N/A | K7: 2028 | L7: BCHMC/NPAT | M7: 0.04024 | N7: 49491 | O7: 22 | P7: 110563.68 | Q7: 110563.68 | R7: 1617334.9 | S7: 18 | T7: 0 | U7: 0 | V7: 9 | W7: 9 | X7: 0
B8: BLD_CH | C8: Capilano House | D8: 1551 Bridgman Avenue | E8: DNV | F8: 2025 | G8: Active | I8: DNV | J8: 2048 | K8: 2027 | L8: N/A | S8: 64 | T8: 63 | U8: 1 | V8: 0 | W8: 0 | X8: 0
B9: BLD_CC | C9: Constance Court | D9: 2518 E. Hastings Street | E9: Vancouver | F9: 2025 | G9: Active | I9: Vancity | J9: 2032 | K9: 2027 | L9: BCHMC | M9: 0.0423 | N9: 46419 | O9: 3 | P9: 178507.8 | Q9: 178507.8 | R9: 274036.81 | S9: 34 | T9: 0 | U9: 18 | V9: 14 | W9: 2 | X9: 0
B10: BLD_EA | C10: Evergreen Apartments | D10: 815 5th Avenue | E10: New Westminster | F10: 2025 | G10: Active | I10: Owned | J10: N/A | K10: N/A | L10: Vancity | M10: 0.0421 | N10: 48976 | O10: 35 | P10: 297840 | Q10: 0 | R10: 5475821.3 | S10: 61 | T10: 3 | U10: 48 | V10: 7 | W10: 3 | X10: 0
B11: BLD_EE | C11: Evelyn Estates | D11: 9155 136A Street | E11: Surrey | F11: 2025 | G11: Active | I11: Owned | J11: N/A | K11: 2028 | L11: BCHMC | M11: 0.0374 | N11: 46844 | O11: 4 | P11: 244376.04 | Q11: 0 | R11: 639949.69 | S11: 36 | T11: 0 | U11: 0 | V11: 18 | W11: 14 | X11: 4
B12: BLD_JP | C12: Jessica Place | D12: 9883 140th Street | E12: Surrey | F12: 2025 | G12: Active | I12: Owned | J12: N/A | K12: 2026 | L12: BCHMC | M12: 0.0101 | N12: 46143 | O12: 4 | P12: 176698.83 | Q12: 0 | R12: 176698.83 | S12: 40 | T12: 0 | U12: 0 | V12: 17 | W12: 17 | X12: 6
B13: BLD_MH | C13: Margaret Heights | D13: 1800 Rufus Drive | E13: CNV | F13: 2025 | G13: Active | I13: CNV | J13: 2046 | K13: 2026 | L13: BCHMC | M13: 0.0101 | N13: 46266 | O13: 5 | P13: 125540.52 | Q13: 0 | R13: 145670.52 | S13: 19 | T13: 0 | U13: 0 | V13: 10 | W13: 5 | X13: 4
B14: BLD_MM | C14: Murray Manor | D14: 6435 Royal Oak Avenue | E14: Burnaby | F14: 2025 | G14: Active | I14: Owned | J14: N/A | K14: N/A | L14: Vancity | M14: 0.0421 | N14: 48976 | O14: 35 | P14: 271563.84 | Q14: 0 | R14: 4992966 | S14: 47 | T14: 6 | U14: 28 | V14: 13 | W14: 0 | X14: 0
B15: BLD_NT | C15: Natalia Terrace | D15: 3550 S.E. Marine Drive | E15: Vancouver | F15: 2025 | G15: Active | I15: Vancity | J15: 2051 | K15: 2027 | L15: BCHMC | M15: 0.0424 | N15: 46508 | O15: 3 | P15: 274351.8 | Q15: 0 | R15: 485006.87 | S15: 40 | T15: 0 | U15: 0 | V15: 24 | W15: 12 | X15: 4
B16: BLD_NG | C16: Newton Green | D16: 12725 63rd Avenue | E16: Surrey | F16: 2025 | G16: Active | I16: BCH | J16: 2058 | K16: 2026 | L16: CMLS | M16: 0.04465 | N16: 49096 | O16: 9 | P16: 443187 | Q16: 0 | R16: 3432387.1 | S16: 49 | T16: 0 | U16: 0 | V16: 22 | W16: 25 | X16: 2
B17: BLD_RG | C17: Rosemary Green | D17: 2880 152nd Street | E17: Surrey | F17: 2025 | G17: Active | I17: Surrey | J17: 2054 | K17: 2054 | L17: Peoples Group | M17: 0.024 | N17: 46143 | O17: 10 | P17: 291146.28 | Q17: 0 | R17: 1976761.2 | S17: 38 | T17: 0 | U17: 0 | V17: 18 | W17: 16 | X17: 4
B18: BLD_AS | C18: 1656 Adanac Street | D18: 1656 Adanac Street | E18: Vancouver | F18: 2028 | G18: New Dev | I18: Owned | J18: 2058 | K18: 2058 | L18: BCH CHF | S18: 97 | T18: 6 | U18: 42 | V18: 33 | W18: 14 | X18: 2
B19: BLD_PS | C19: 450 Pacific Street | D19: 450 Pacific Street | E19: Vancouver | F19: 2028 | G19: New Dev | I19: Owned | J19: 2058 | K19: 2058 | L19: BCH CHF | S19: 91 | T19: 32 | U19: 25 | V19: 23 | W19: 11 | X19: 0
B20: BLD_PM | C20: The Creek, Port Moody | D20: 300 Angela Drive | E20: Port Moody | F20: 2027 | G20: New Dev | I20: Owned | J20: 2057 | K20: 2057 | L20: CMHC | S20: 328 | T20: 0 | U20: 72 | V20: 140 | W20: 116 | X20: 0
B21: BLD_CD | C21: 800 Commercial Drive | D21: 800 Commercial Drive | E21: Vancouver | F21: 2029 | G21: New Dev | I21: Owned | J21: 2059 | K21: 2059 | L21: BCH CHF | S21: 93 | T21: 26 | U21: 29 | V21: 26 | W21: 12 | X21: 0
B23: Notes:
B24: Source: shared by NGO B operator.
B31: Property
B32: Tab ID | C32: Property | D32: Address | E32: City | F32: Start Yr. (Current Yr. if Active) | G32: Status | I32: 2025 | J32: 2026 | K32: 2027 | L32: 2028 | M32: 2029 | N32: 2030 | O32: 2031 | P32: 2032 | Q32: 2033 | R32: 2034 | S32: 2035 | T32: 2036 | U32: 2037 | V32: 2038 | W32: 2039 | X32: 2040 | Y32: 2041 | Z32: 2042 | AA32: 2043 | AB32: 2044 | AC32: 2045
B33: BLD_AB | C33: Alma Blackwell | D33: 1656 Adanac Street | E33: Vancouver | F33: 2025 | G33: Active | I33: =INDEX(BLD_AB!$E$41:$Y$41,MATCH(I$32,BLD_AB!$E$12:$Y$12,0)) -> 436078.4 | J33: =INDEX(BLD_AB!$E$41:$Y$41,MATCH(J$32,BLD_AB!$E$12:$Y$12,0)) -> 441788.59 | K33: =INDEX(BLD_AB!$E$41:$Y$41,MATCH(K$32,BLD_AB!$E$12:$Y$12,0)) -> 608477.74 | L33: =INDEX(BLD_AB!$E$41:$Y$41,MATCH(L$32,BLD_AB!$E$12:$Y$12,0)) -> 617390.19 | M33: =INDEX(BLD_AB!$E$41:$Y$41,MATCH(M$32,BLD_AB!$E$12:$Y$12,0)) -> 626350.6 | N33: =INDEX(BLD_AB!$E$41:$Y$41,MATCH(N$32,BLD_AB!$E$12:$Y$12,0)) -> 635354.73 | O33: =INDEX(BLD_AB!$E$41:$Y$41,MATCH(O$32,BLD_AB!$E$12:$Y$12,0)) -> 644398.02 | P33: =INDEX(BLD_AB!$E$41:$Y$41,MATCH(P$32,BLD_AB!$E$12:$Y$12,0)) -> 653475.62 | ... AC33: =INDEX(BLD_AB!$E$41:$Y$41,MATCH(AC$32,BLD_AB!$E$12:$Y$12,0)) -> 820464.84
B34: BLD_AC | C34: Antkiw Court | D34: 1534 E. 4th Avenue | E34: Vancouver | F34: 2025 | G34: Active | I34: =INDEX(BLD_AC!$E$41:$Y$41,MATCH(I$32,BLD_AC!$E$12:$Y$12,0)) -> 172856.48 | J34: =INDEX(BLD_AC!$E$41:$Y$41,MATCH(J$32,BLD_AC!$E$12:$Y$12,0)) -> 172215.63 | K34: =INDEX(BLD_AC!$E$41:$Y$41,MATCH(K$32,BLD_AC!$E$12:$Y$12,0)) -> 171441.5 | L34: =INDEX(BLD_AC!$E$41:$Y$41,MATCH(L$32,BLD_AC!$E$12:$Y$12,0)) -> 245496.04 | M34: =INDEX(BLD_AC!$E$41:$Y$41,MATCH(M$32,BLD_AC!$E$12:$Y$12,0)) -> 245931.96 | N34: =INDEX(BLD_AC!$E$41:$Y$41,MATCH(N$32,BLD_AC!$E$12:$Y$12,0)) -> 246241.11 | O34: =INDEX(BLD_AC!$E$41:$Y$41,MATCH(O$32,BLD_AC!$E$12:$Y$12,0)) -> 246415.53 | P34: =INDEX(BLD_AC!$E$41:$Y$41,MATCH(P$32,BLD_AC!$E$12:$Y$12,0)) -> 246446.88 | ... AC34: =INDEX(BLD_AC!$E$41:$Y$41,MATCH(AC$32,BLD_AC!$E$12:$Y$12,0)) -> 223647.95
B35: BLD_BT | C35: Beatrice Terrace | D35: 1877 E. Georgia Street | E35: Vancouver | F35: 2025 | G35: Active | I35: =INDEX(BLD_BT!$E$41:$Y$41,MATCH(I$32,BLD_BT!$E$12:$Y$12,0)) -> 259166.84 | J35: =INDEX(BLD_BT!$E$41:$Y$41,MATCH(J$32,BLD_BT!$E$12:$Y$12,0)) -> 259732.11 | K35: =INDEX(BLD_BT!$E$41:$Y$41,MATCH(K$32,BLD_BT!$E$12:$Y$12,0)) -> 260212.4 | L35: =INDEX(BLD_BT!$E$41:$Y$41,MATCH(L$32,BLD_BT!$E$12:$Y$12,0)) -> 320850.32 | M35: =INDEX(BLD_BT!$E$41:$Y$41,MATCH(M$32,BLD_BT!$E$12:$Y$12,0)) -> 322348.73 | N35: =INDEX(BLD_BT!$E$41:$Y$41,MATCH(N$32,BLD_BT!$E$12:$Y$12,0)) -> 323768.81 | O35: =INDEX(BLD_BT!$E$41:$Y$41,MATCH(O$32,BLD_BT!$E$12:$Y$12,0)) -> 325104.68 | P35: =INDEX(BLD_BT!$E$41:$Y$41,MATCH(P$32,BLD_BT!$E$12:$Y$12,0)) -> 326350.13 | ... AC35: =INDEX(BLD_BT!$E$41:$Y$41,MATCH(AC$32,BLD_BT!$E$12:$Y$12,0)) -> 259261.36
B36: BLD_CH | C36: Capilano House | D36: 1551 Bridgman Avenue | E36: DNV | F36: 2025 | G36: Active | I36: =INDEX(BLD_CH!$E$41:$Y$41,MATCH(I$32,BLD_CH!$E$12:$Y$12,0)) -> 225686.19 | J36: =INDEX(BLD_CH!$E$41:$Y$41,MATCH(J$32,BLD_CH!$E$12:$Y$12,0)) -> 220425.04 | K36: =INDEX(BLD_CH!$E$41:$Y$41,MATCH(K$32,BLD_CH!$E$12:$Y$12,0)) -> 475975.22 | L36: =INDEX(BLD_CH!$E$41:$Y$41,MATCH(L$32,BLD_CH!$E$12:$Y$12,0)) -> 474922.22 | M36: =INDEX(BLD_CH!$E$41:$Y$41,MATCH(M$32,BLD_CH!$E$12:$Y$12,0)) -> 473425.25 | N36: =INDEX(BLD_CH!$E$41:$Y$41,MATCH(N$32,BLD_CH!$E$12:$Y$12,0)) -> 471458.53 | O36: =INDEX(BLD_CH!$E$41:$Y$41,MATCH(O$32,BLD_CH!$E$12:$Y$12,0)) -> 468995.07 | P36: =INDEX(BLD_CH!$E$41:$Y$41,MATCH(P$32,BLD_CH!$E$12:$Y$12,0)) -> 466006.62 | ... AC36: =INDEX(BLD_CH!$E$41:$Y$41,MATCH(AC$32,BLD_CH!$E$12:$Y$12,0)) -> 522083.69
B37: BLD_CC | C37: Constance Court | D37: 2518 E. Hastings Street | E37: Vancouver | F37: 2025 | G37: Active | I37: =INDEX(BLD_CC!$E$41:$Y$41,MATCH(I$32,BLD_CC!$E$12:$Y$12,0)) -> 343316.33 | J37: =INDEX(BLD_CC!$E$41:$Y$41,MATCH(J$32,BLD_CC!$E$12:$Y$12,0)) -> 342478.44 | K37: =INDEX(BLD_CC!$E$41:$Y$41,MATCH(K$32,BLD_CC!$E$12:$Y$12,0)) -> 467983.07 | L37: =INDEX(BLD_CC!$E$41:$Y$41,MATCH(L$32,BLD_CC!$E$12:$Y$12,0)) -> 290793.38 | M37: =INDEX(BLD_CC!$E$41:$Y$41,MATCH(M$32,BLD_CC!$E$12:$Y$12,0)) -> 291958.99 | N37: =INDEX(BLD_CC!$E$41:$Y$41,MATCH(N$32,BLD_CC!$E$12:$Y$12,0)) -> 292961.9 | O37: =INDEX(BLD_CC!$E$41:$Y$41,MATCH(O$32,BLD_CC!$E$12:$Y$12,0)) -> 293791.43 | P37: =INDEX(BLD_CC!$E$41:$Y$41,MATCH(P$32,BLD_CC!$E$12:$Y$12,0)) -> 294436.35 | ... AC37: =INDEX(BLD_CC!$E$41:$Y$41,MATCH(AC$32,BLD_CC!$E$12:$Y$12,0)) -> 346735.34
B38: BLD_EA | C38: Evergreen Apartments | D38: 815 5th Avenue | E38: New Westminster | F38: 2025 | G38: Active | I38: =INDEX(BLD_EA!$E$41:$Y$41,MATCH(I$32,BLD_EA!$E$12:$Y$12,0)) -> 579873.69 | J38: =INDEX(BLD_EA!$E$41:$Y$41,MATCH(J$32,BLD_EA!$E$12:$Y$12,0)) -> 583200.51 | K38: =INDEX(BLD_EA!$E$41:$Y$41,MATCH(K$32,BLD_EA!$E$12:$Y$12,0)) -> 586263.03 | L38: =INDEX(BLD_EA!$E$41:$Y$41,MATCH(L$32,BLD_EA!$E$12:$Y$12,0)) -> 589042.75 | M38: =INDEX(BLD_EA!$E$41:$Y$41,MATCH(M$32,BLD_EA!$E$12:$Y$12,0)) -> 591520.23 | N38: =INDEX(BLD_EA!$E$41:$Y$41,MATCH(N$32,BLD_EA!$E$12:$Y$12,0)) -> 593675.14 | O38: =INDEX(BLD_EA!$E$41:$Y$41,MATCH(O$32,BLD_EA!$E$12:$Y$12,0)) -> 595486.12 | P38: =INDEX(BLD_EA!$E$41:$Y$41,MATCH(P$32,BLD_EA!$E$12:$Y$12,0)) -> 596930.82 | ... AC38: =INDEX(BLD_EA!$E$41:$Y$41,MATCH(AC$32,BLD_EA!$E$12:$Y$12,0)) -> 703873.72
B39: BLD_EE | C39: Evelyn Estates | D39: 9155 136A Street | E39: Surrey | F39: 2025 | G39: Active | I39: =INDEX(BLD_EE!$E$41:$Y$41,MATCH(I$32,BLD_EE!$E$12:$Y$12,0)) -> 207537.01 | J39: =INDEX(BLD_EE!$E$41:$Y$41,MATCH(J$32,BLD_EE!$E$12:$Y$12,0)) -> 207348.17 | K39: =INDEX(BLD_EE!$E$41:$Y$41,MATCH(K$32,BLD_EE!$E$12:$Y$12,0)) -> 206981.97 | L39: =INDEX(BLD_EE!$E$41:$Y$41,MATCH(L$32,BLD_EE!$E$12:$Y$12,0)) -> 289501.41 | M39: =INDEX(BLD_EE!$E$41:$Y$41,MATCH(M$32,BLD_EE!$E$12:$Y$12,0)) -> 290410 | N39: =INDEX(BLD_EE!$E$41:$Y$41,MATCH(N$32,BLD_EE!$E$12:$Y$12,0)) -> 291141.51 | O39: =INDEX(BLD_EE!$E$41:$Y$41,MATCH(O$32,BLD_EE!$E$12:$Y$12,0)) -> 291684.57 | P39: =INDEX(BLD_EE!$E$41:$Y$41,MATCH(P$32,BLD_EE!$E$12:$Y$12,0)) -> 292027.31 | ... AC39: =INDEX(BLD_EE!$E$41:$Y$41,MATCH(AC$32,BLD_EE!$E$12:$Y$12,0)) -> 341921.29
B40: BLD_JP | C40: Jessica Place | D40: 9883 140th Street | E40: Surrey | F40: 2025 | G40: Active | I40: =INDEX(BLD_JP!$E$41:$Y$41,MATCH(I$32,BLD_JP!$E$12:$Y$12,0)) -> 141364.12 | J40: =INDEX(BLD_JP!$E$41:$Y$41,MATCH(J$32,BLD_JP!$E$12:$Y$12,0)) -> 236702.4 | K40: =INDEX(BLD_JP!$E$41:$Y$41,MATCH(K$32,BLD_JP!$E$12:$Y$12,0)) -> 236138.76 | L40: =INDEX(BLD_JP!$E$41:$Y$41,MATCH(L$32,BLD_JP!$E$12:$Y$12,0)) -> 235351.92 | M40: =INDEX(BLD_JP!$E$41:$Y$41,MATCH(M$32,BLD_JP!$E$12:$Y$12,0)) -> 234328.97 | N40: =INDEX(BLD_JP!$E$41:$Y$41,MATCH(N$32,BLD_JP!$E$12:$Y$12,0)) -> 233056.36 | O40: =INDEX(BLD_JP!$E$41:$Y$41,MATCH(O$32,BLD_JP!$E$12:$Y$12,0)) -> 231519.93 | P40: =INDEX(BLD_JP!$E$41:$Y$41,MATCH(P$32,BLD_JP!$E$12:$Y$12,0)) -> 229704.87 | ... AC40: =INDEX(BLD_JP!$E$41:$Y$41,MATCH(AC$32,BLD_JP!$E$12:$Y$12,0)) -> 255069.16
B41: BLD_MH | C41: Margaret Heights | D41: 1800 Rufus Drive | E41: CNV | F41: 2025 | G41: Active | I41: =INDEX(BLD_MH!$E$41:$Y$41,MATCH(I$32,BLD_MH!$E$12:$Y$12,0)) -> 146321.51 | J41: =INDEX(BLD_MH!$E$41:$Y$41,MATCH(J$32,BLD_MH!$E$12:$Y$12,0)) -> 210980.64 | K41: =INDEX(BLD_MH!$E$41:$Y$41,MATCH(K$32,BLD_MH!$E$12:$Y$12,0)) -> 211367.32 | L41: =INDEX(BLD_MH!$E$41:$Y$41,MATCH(L$32,BLD_MH!$E$12:$Y$12,0)) -> 211608.4 | M41: =INDEX(BLD_MH!$E$41:$Y$41,MATCH(M$32,BLD_MH!$E$12:$Y$12,0)) -> 211694.86 | N41: =INDEX(BLD_MH!$E$41:$Y$41,MATCH(N$32,BLD_MH!$E$12:$Y$12,0)) -> 211617.22 | O41: =INDEX(BLD_MH!$E$41:$Y$41,MATCH(O$32,BLD_MH!$E$12:$Y$12,0)) -> 211365.57 | P41: =INDEX(BLD_MH!$E$41:$Y$41,MATCH(P$32,BLD_MH!$E$12:$Y$12,0)) -> 210929.52 | ... AC41: =INDEX(BLD_MH!$E$41:$Y$41,MATCH(AC$32,BLD_MH!$E$12:$Y$12,0)) -> 242415.52
B42: BLD_MM | C42: Murray Manor | D42: 6435 Royal Oak Avenue | E42: Burnaby | F42: 2025 | G42: Active | I42: =INDEX(BLD_MM!$E$41:$Y$41,MATCH(I$32,BLD_MM!$E$12:$Y$12,0)) -> 502606.51 | J42: =INDEX(BLD_MM!$E$41:$Y$41,MATCH(J$32,BLD_MM!$E$12:$Y$12,0)) -> 507090.76 | K42: =INDEX(BLD_MM!$E$41:$Y$41,MATCH(K$32,BLD_MM!$E$12:$Y$12,0)) -> 511441.98 | L42: =INDEX(BLD_MM!$E$41:$Y$41,MATCH(L$32,BLD_MM!$E$12:$Y$12,0)) -> 515648.61 | M42: =INDEX(BLD_MM!$E$41:$Y$41,MATCH(M$32,BLD_MM!$E$12:$Y$12,0)) -> 519698.47 | N42: =INDEX(BLD_MM!$E$41:$Y$41,MATCH(N$32,BLD_MM!$E$12:$Y$12,0)) -> 523578.81 | O42: =INDEX(BLD_MM!$E$41:$Y$41,MATCH(O$32,BLD_MM!$E$12:$Y$12,0)) -> 527276.21 | P42: =INDEX(BLD_MM!$E$41:$Y$41,MATCH(P$32,BLD_MM!$E$12:$Y$12,0)) -> 530776.59 | ... AC42: =INDEX(BLD_MM!$E$41:$Y$41,MATCH(AC$32,BLD_MM!$E$12:$Y$12,0)) -> 640622.54
B43: BLD_NT | C43: Natalia Terrace | D43: 3550 S.E. Marine Drive | E43: Vancouver | F43: 2025 | G43: Active | I43: =INDEX(BLD_NT!$E$41:$Y$41,MATCH(I$32,BLD_NT!$E$12:$Y$12,0)) -> 310204.72 | J43: =INDEX(BLD_NT!$E$41:$Y$41,MATCH(J$32,BLD_NT!$E$12:$Y$12,0)) -> 310630.17 | K43: =INDEX(BLD_NT!$E$41:$Y$41,MATCH(K$32,BLD_NT!$E$12:$Y$12,0)) -> 440733.09 | L43: =INDEX(BLD_NT!$E$41:$Y$41,MATCH(L$32,BLD_NT!$E$12:$Y$12,0)) -> 443297.58 | M43: =INDEX(BLD_NT!$E$41:$Y$41,MATCH(M$32,BLD_NT!$E$12:$Y$12,0)) -> 445663.34 | N43: =INDEX(BLD_NT!$E$41:$Y$41,MATCH(N$32,BLD_NT!$E$12:$Y$12,0)) -> 447816.42 | O43: =INDEX(BLD_NT!$E$41:$Y$41,MATCH(O$32,BLD_NT!$E$12:$Y$12,0)) -> 449742.15 | P43: =INDEX(BLD_NT!$E$41:$Y$41,MATCH(P$32,BLD_NT!$E$12:$Y$12,0)) -> 451425.17 | ... AC43: =INDEX(BLD_NT!$E$41:$Y$41,MATCH(AC$32,BLD_NT!$E$12:$Y$12,0)) -> 536232.03
