Workbook

Sheet Business Rules
A1: IREI MVP v2.0 Engineering Template — Business Rules
A2: V2 preserves the live V1 calculation and canonical-data architecture, but extends the product from a one-time readiness assessment into a persistent portfolio stewardship record with versioning, change detection, action/decision tracking, evidence provenance, and controlled report snapshots.
A4: Colour | B4: Meaning | C4: Who may edit? | D4: MVP v1 treatment | E4: Example tabs | F4: Rule
A5: Blue | B5: Writable input zones | C5: Human / AI / analyst | D5: Manual or import data entry | E5: DATA_* input tabs | F5: Only blue cells are user-write zones.
A6: Black / no fill | B6: Live formula cells | C6: No direct edit | D6: Keep formulas live | E6: DATA_METRIC_LONG, DATA_QUALITY_CHECKS | F6: Do not overwrite formulas.
A7: Purple | B7: Generated bridge data | C7: No direct edit unless documented | D7: Formula-generated from inputs | E7: DATA_PROPERTY_MASTER, DATA_DEBT_MASTER | F7: Can be generated by future digital engine.
A8: Orange | B8: Review / unresolved / assumptions | C8: Analyst may update status/note | D8: Used for assumptions and flags | E8: ASSUMPTIONS_FLAGS | F8: Must include reviewer rationale.
A9: Grey | B9: Legacy / reference | C9: Reference only | D9: Not MVP engine | E9: NGO B v12 source workbook | F9: Do not build software from legacy tabs directly.
A10: Green | B10: Output | C10: No direct edit to formulas | D10: Dashboard / recurring stewardship outputs | E10: OUT_STAGE1_READINESS_SNAPSHOT + DASH_01–08 | F10: Output pulls from data and checks.
A11: Control note | B11: DATA_DEBT_SCHEDULE | C11: Controlled input table | D11: Principal and interest may be imported or manually transcribed from a named source; Total Debt Service remains formula-driven. | E11: Engineer action | F11: Do not assume external source workbooks update this table automatically.
A13: Rule ID | B13: Area | C13: Business Rule | D13: MVP v1 implementation
A14: BR-MVP-001 | B14: Purpose | C14: MVP v2 keeps the V1 readiness review but adds recurring use: establish a baseline, preserve approved versions, compare new information, identify material changes, track actions/decisions, and regenerate controlled reports. | D14: Do not rebuild the live analytical core. Add persistence and workflow around it.
A15: BR-MVP-002 | B15: Source hierarchy | C15: Source precedence remains controlled by STG_SOURCE_INTAKE and MVP_CONTROL. Every critical output must remain traceable to source, reporting period, and review status. | D15: Retain current source hierarchy and add version/effective-date context where available.
A16: BR-MVP-003 | B16: Build principle | C16: Build V2 as an extension of the reusable V1 template; do not rebuild the NGO B legacy model or replace existing live formulas. | D16: Existing DATA_* and calculation logic remain authoritative unless a V2 change is explicitly listed in V2_CHANGE_SPEC.
A17: BR-MVP-004 | B17: Input control | C17: Human / AI / analyst may write only in controlled input/review zones. Generated history/change fields and dashboards are not manual output-entry areas. | D17: Blue=input; black=formula; purple=generated; orange=review; green=output.
A18: BR-MVP-005 | B18: Live calculations | C18: Existing metric, quality-check, trend and readiness formulas remain live. New dashboards must reference workbook tables/formulas rather than hardcoded presentation numbers. | D18: Every dashboard KPI must drill back conceptually to a data or workflow record.
A19: BR-MVP-006 | B19: V2 workflow | C19: Preserve V1: intake → canonical DATA tables → checks/metrics → readiness output. Extend to: assessment version → field/change history → actions/decisions → report snapshot → next update. | D19: This recurring loop is the primary V2 product change.
A20: BR-MVP-007 | B20: Auditability | C20: Source conflicts, manual overrides, material changes, action outcomes, and approved report versions must remain visible historically. | D20: Do not overwrite prior approved records when a new review is created.
A21: BR-MVP-008 | B21: Outcome | C21: V2 user experience consists of eight linked dashboard pages: Portfolio; Organization/Governance; Properties; Financial; Mission/Public Value; Decisions/Risks/Actions; Evidence/Data Quality; Reports/Authorized Use. | D21: The eight pages are presentation/workflow views over the same controlled data model.
A22: BR-MVP-009 | B22: Template/demo structure | C22: This workbook is the reusable V2 blank template. Client/demo data should be loaded only into controlled input tables; formulas and dashboard structures are reusable. | D22: Digital implementation must support multiple organizations and recurring assessment versions.
A23: Preserved NGO B v12 business-rule excerpt
A24: Original row | B24: Original Business Rules text
A25: 1 | B25: IREI Underwriting Template Prototype
A26: 3 | B26: Business Rules Organized by Epics and User Stories
A27: 5 | B27: 1. Purpose of the Model
A28: 7 | B28: The model is designed to convert non-profit / Indigenous / mission-driven housing organization data into a standardized, auditable underwriting structure.
A29: 9 | B29: It has two purposes:
A30: 11 | B30: 1. Current use: underwrite NGO B’s portfolio using the existing live Excel calculation engine.
A31: 13 | B31: 2. Future platform use: establish the data architecture and business rules for an AI / analyst-assisted IREI underwriting platform.
A32: 15 | B32: The model is not yet a fully automated platform engine. The current financial calculations still rely on legacy NGO B tabs, while the new DATA and OUT layers define the future standardized model structure.
A33: 19 | B33: Epic 1 — Workbook Navigation and User Control
A34: 21 | B34: Business Objective
A35: 23 | B35: Ensure analysts and AI agents understand where to enter data, where formulas live, what not to overwrite, and how to follow the workbook structure.
A36: 25 | B36: Key Tabs
... A64: 81 | B64: Formula and output areas are clearly marked as non-editable.
A85: MVP v1.0 reconciliation additions
A86: BR-MVP-010 | B86: Reporting period | C86: All financial output must filter to the selected fiscal year in MVP_CONTROL. | D86: Do not mix stabilized future-project debt with current-year operations.
A87: BR-MVP-011 | B87: Debt time dimension | C87: Instrument master data and annual debt-service schedule are separate. | D87: DATA_DEBT_MASTER stores instrument facts; DATA_DEBT_SCHEDULE stores annual principal and interest.
A88: BR-MVP-012 | B88: Unit categories | C88: Mission/affordability chart categories must be mutually exclusive. | D88: Deep subsidy + subsidized + market + commercial + unclassified must reconcile to modeled units.
A89: BR-MVP-013 | B89: Cash and reserves | C89: Cash, restricted reserves and available liquidity are not interchangeable. | D89: Keep availability conditional until source definitions and restrictions are mapped.
...

Sheet 00_CHANGE_LOG
A1: 00_CHANGE_LOG — IREI MVP Blank Template v0.3
A2: Audit trail for extracting/simplifying NGO B v12 into the MVP v1 build template. Keep this sheet current with every workbook revision.
A4: Change ID | B4: Date | C4: Type | D4: Sheet / Range | E4: Issue | F4: Change Made | G4: Assumption Changed? | H4: Calculation Impact | I4: Status | J4: Next Step
A5: CL-001 | B5: 2026-07-07 | C5: Governance | D5: 00_CHANGE_LOG | E5: No workbook-level audit trail existed. | F5: Added change log sheet with change IDs and affected ranges. | G5: No | H5: None; documentation only. | I5: Complete | J5: Use for every future model revision.
A6: CL-002 | B6: 2026-07-07 | C6: Governance | D6: 00_MODEL_CONTROL | E6: Portfolio inclusion logic was embedded in rollup row 8 only. | F6: Added central scope-control sheet and linked rollup toggles to it. | G6: No | H6: No intended output change; BLD_AB remains excluded and all other assets remain included. | I6: Complete | J6: Use this tab for future include/exclude decisions.
A7: CL-003 | B7: 2026-07-07 | C7: Governance | D7: 00_MODEL_CHECKS | E7: No live structural checks tab existed. | F7: Added live checks for scope, register totals, label references, and bucket reconciliation. | G7: No | H7: None; documentation/checking only. | I7: Complete | J7: Expand with debt and development checks in next pass.
A8: CL-004 | B8: 2026-07-07 | C8: Formula Fix | D8: 00_PORTFOLIO_REGISTER!C5:C21 | E8: City lookup matched BLD_ID against property name, causing #N/A results. | F8: Changed lookup to match BLD_ID against Property Summary Tab ID. | G8: No | H8: Register city field now calculates live from Property Summary. | I8: Complete | J8: Review other register columns for full institutionalization.
A9: CL-005 | B9: 2026-07-07 | C9: Formula Addition | D9: 00_PORTFOLIO_REGISTER!D5:I21 | E9: Register had blank units, NOI, lender, and debt-term fields. | F9: Added live formulas for units, 2025/2029/2035 NOI, lender/program, and debt term. | G9: No | H9: Register now ties to Property Summary, property tabs, and Debt Engine. | I9: Complete | J9: Later replace hardcoded bucket and issue narrative with formula-controlled classification.
A10: CL-006 | B10: 2026-07-07 | C10: Formula Fix | D10: 00_PORTFOLIO_REGISTER!E23:G23 | E10: Portfolio total formulas contained #REF!. | F10: Replaced with SUM formulas over live NOI detail rows. | G10: No | H10: Register totals now calculate live. | I10: Complete | J10: Cross-check against portfolio rollup inclusion logic if the register is meant to be scoped.
A11: CL-007 | B11: 2026-07-07 | C11: Formatting Fix | D11: 00_PORTFOLIO SUMMARY!C5 | E11: Current year formula displayed as an Excel serial date. | F11: Changed number format to year/number display. | G11: No | H11: Presentation only. | I11: Complete | J11: None.
A12: CL-008 | B12: 2026-07-07 | C12: Formula Fix | D12: 00_PORTFOLIO ROLLUP!C72 | E12: GAV label referenced rollup toggle instead of cap-rate assumption. | F12: Changed label to reference Exit Cap Rate and format as %. | G12: No | H12: Presentation only; GAV formulas unchanged. | I12: Complete | J12: None.
A13: CL-009 | B13: 2026-07-07 | C13: Formula Fix | D13: 00_PORTFOLIO ROLLUP!C79,E79:Y79,C86,E86:Y86 | E13: Yield labels/markers referenced wrong cells. | F13: Changed labels and STAB. YR. markers to reference stabilization year assumption. | G13: No | H13: Presentation only; yield formulas unchanged. | I13: Complete | J13: None.
A14: CL-010 | B14: 2026-07-07 | C14: Formula Fix | D14: 00_PORTFOLIO ROLLUP!E60:Y60,E75:Y75 | E14: Refi marker rows referenced payout ratio instead of actual event rows. | F14: Changed markers to flag when balloon, loan proceeds, or net refi/gap rows are non-zero. | G14: No | H14: Presentation only; underlying refi rows unchanged. | I14: Complete | J14: Later separate residual funding gaps from equity-return language.
A15: CL-011 | B15: 2026-07-07 | C15: Control Fix | D15: 00_PORTFOLIO SUMMARY!C5; 00_MODEL_CONTROL!B31 | E15: Current year used volatile TODAY() and displayed as a serial date. | F15: Moved selected current year to an explicit control input and linked the summary output to it. | G15: No | H15: Controls display-year selection only; formulas remain live off the selected year. | I15: Complete | J15: Change B31 if a different current-year test is required.
A16: CL-012 | B16: 2026-07-07 | C16: Platform Architecture | D16: 00_PLATFORM_INDEX | E16: No platform architecture layer existed. | F16: Added platform index and model-layer map. | G16: No | H16: Documentation/governance only.
A17: CL-013 | B17: 2026-07-07 | C17: Intake Architecture | D17: STG_SOURCE_INTAKE | E17: Future NGO/Yardi files had no intake log. | F17: Added source intake register. | G17: No | H17: No model output change.
A18: CL-014 | B18: 2026-07-07 | C18: Mapping Architecture | D18: MAP_FIELD_MAPPING | E18: No field mapping layer existed. | F18: Added source-to-canonical field map. | G18: No | H18: No model output change.
A19: CL-015 | B19: 2026-07-07 | C19: Data Architecture | D19: DATA_PROPERTY_MASTER | E19: Property identity was spread across tabs. | F19: Added live canonical property master. | G19: No | H19: Live links; assumptions unchanged.
A20: CL-016 | B20: 2026-07-07 | C20: Data Architecture | D20: DATA_DEBT_MASTER | E20: Debt profile was not normalized. | F20: Added live canonical debt master. | G20: No | H20: Live links; assumptions unchanged.
A21: CL-017 | B21: 2026-07-07 | C21: Model Architecture | D21: DATA_METRIC_LONG | E21: Outputs were property-tab driven. | F21: Added live long-format property-year-metric table for key years. | G21: No | H21: No intended output change.
A22: CL-018 | B22: 2026-07-07 | C22: Checks | D22: DATA_QUALITY_CHECKS | E22: No platform-readiness checks existed. | F22: Added live checks for platform migration. | G22: No | H22: Flags open migration items.
A23: CL-019 | B23: 2026-07-07 | C23: Output | D23: OUT_PLATFORM_READINESS | E23: No readiness dashboard existed. | F23: Added live platform-readiness dashboard. | G23: No | H23: No model output change.
A24: CL-020 | B24: 2026-07-07 | C24: Calculation Control | D24: Workbook calculation settings | E24: New sheets contain formulas. | F24: Confirmed automatic full recalculation on open. | G24: No | H24: Keeps formulas live.
A25: CL-021 | B25: 2026-07-07 | C25: Model Architecture | D25: DATA_ASSET_CLASSIFICATION | E25: No single authoritative asset-classification table existed. | F25: Added live authoritative classification table for Excluded / Stable / Refi Watch / Workout / New Build. | G25: No | H25: No assumption changes; classification is formula-linked to existing model data. | I25: Complete | J25: Use as single source of truth for classification.
A26: CL-022 | B26: 2026-07-07 | C26: Formula Link | D26: 00_PORTFOLIO SUMMARY!C10:C26 | E26: Portfolio Summary classified assets independently. | F26: Redirected Bucket column to Final Classification from DATA_ASSET_CLASSIFICATION. | G26: No | H26: Output classification now uses single source of truth. | I26: Complete | J26: Do not hardcode classification in Summary.
A27: CL-023 | B27: 2026-07-07 | C27: Formula Link | D27: 00_MODEL_CONTROL!F5:F21 | E27: Model Control Summary Bucket was not authoritative. | F27: Linked Summary Bucket to DATA_ASSET_CLASSIFICATION final classification. | G27: No | H27: Control sheet now uses classification authority. | I27: Complete | J27: Use F for final classification.
A28: CL-024 | B28: 2026-07-07 | C28: Formula Link | D28: 00_PORTFOLIO_REGISTER!J5:J21 | E28: Register Bucket was hardcoded manual text and remained a second source. | F28: Replaced manual bucket text with formula pulling final classification and mapping it to controlled register buckets. | G28: No | H28: Register now follows authority table; no model assumptions changed. | I28: Complete | J28: Protect from manual overwrite.
A29: CL-025 | B29: 2026-07-07 | C29: Governance | D29: DATA_ASSET_CLASSIFICATION!AA7:AB13 | E29: Register bucket mapping was embedded in text rather than governed. | F29: Added visible classification-to-register-bucket mapping table used by Register formulas. | G29: No | H29: Improves auditability; classification values stay live. | I29: Complete | J29: Edit mapping table only if bucket taxonomy changes.
A30: CL-MVP-001 | B30: 2026-07-10 | C30: MVP Extraction | D30: Workbook | E30: Previous MVP template did not preserve v12 build rules, colour coding, live calculations, or change log sufficiently. | F30: Rebuilt as a clean v12-aligned template with Business Rules, input-control map, source log, canonical DATA tabs, formulas, quality checks, and readiness output. | G30: No | H30: Architecture and presentation only; formulas remain live. | I30: Complete | J30: Use this v0.2 template for Uygar handoff.
A31: CL-MVP-002 | B31: 2026-07-10 | C31: Governance | D31: Business Rules | E31: MVP scope needed to be clearly separated from investor dashboard scope. | F31: Added MVP-specific rules while preserving original v12 business-rule excerpt. | G31: No | H31: Documentation only. | I31: Complete | J31: Keep this sheet as first-read tab.
A32: CL-MVP-003 | B32: 2026-07-10 | C32: Input Control | D32: INPUT_CONTROL_MAP; DATA_* | E32: Writable versus generated cells needed to match v12 colour discipline. | F32: Applied blue input zones, purple generated bridge cells, orange review flags, green output, grey legacy/reference indicators. | G32: No | H32: Improves auditability; no calculation logic change. | I32: Complete | J32: Use blue cells for analyst/AI input.
A33: CL-MVP-004 | B33: 2026-07-10 | C33: Live Calculation | D33: DATA_METRIC_LONG; DATA_QUALITY_CHECKS; OUT_STAGE1_READINESS_SNAPSHOT | E33: Output needed to be formula-driven, not static. | F33: Added live formulas for property count, included count, units, new projects, source flags, revenue, expenses, NOI, debt service, AFFO, DSCR, and readiness status. | G33: No | H33: Output updates when input tabs change. | I33: Complete | J33: Review formulas before digital translation.
A34: CL-MVP-005 | B34: 2026-07-10 | C34: Source Conflict | D34: ASSUMPTIONS_FLAGS | E34: Port Moody unit count remains 245 vs 328. | F34: Added explicit unresolved issue flag for Port Moody. | G34: No | H34: Does not change final source assumption; flag remains open. | I34: Open | J34: Confirm with ENF before final demo.
A35: 2026-07-10 | B35: v0.3 | C35: DATA_DEBT_MASTER | D35: Fixed omission | E35: Restored legacy mortgage principal/rate/amortization/source annual debt service from v12/v0.1 extraction for included existing properties. | F35: Kelly review / ChatGPT | G35: OpenAI | H35: High | I35: Completed | J35: Corrects DSCR/AFFO blind spot.
A36: 2026-07-10 | B36: v0.3 | C36: DATA_QUALITY_CHECKS | D36: Formula control | E36: Tightened QC-MVP-006 to count included rows still marked Partial instead of passing when any debt row is Ready. | F36: Kelly review / ChatGPT | G36: OpenAI | H36: High | I36: Completed | J36: Prevents silent debt completeness gaps.
... A52: CL-MVP-018 | B52: 2026-07-26 | C52: Metric Definition | D52: DATA_METRIC_LONG; DATA_QUALITY_CHECKS | E52: Unit Mix Coverage label did not disclose the commercial unit in the numerator. | F52: Renamed to Known Classification Coverage and documented the numerator. | G52: No | H52: Definition is explicit and auditable. | I52: Complete | J52: 541 / 1,008 includes 307 affordable, 233 market and 1 commercial.

Sheet 00_PLATFORM_INDEX
A1: 00_PLATFORM_INDEX — IREI MVP v2.0 Engineering Build Map
A2: V2 preserves the live V1 data/calculation layers and adds persistence, change tracking, action/decision workflow, report snapshots, and eight formula-linked dashboard pages.
A4: Layer | B4: Tab | C4: Role | D4: Edit rule | E4: Colour | F4: Feeds / Uses | G4: MVP status | H4: Notes
A5: Governance | B5: Business Rules | C5: Business rules and source hierarchy | D5: Read only except rule updates | E5: Grey | F5: All tabs | G5: Required | H5: Start here.
A6: Governance | B6: MVP_CONTROL | C6: Reporting year and calculation basis | D6: Blue controlled inputs | E6: Blue | F6: Metrics, checks, outputs | G6: Required | H6: Single source for reporting period.
A7: Governance | B7: 00_CHANGE_LOG | C7: Audit trail | D7: Update on every revision | E7: Grey | F7: Workbook governance | G7: Required | H7: Includes reconciliation changes.
A8: Governance | B8: INPUT_CONTROL_MAP | C8: Analyst / AI write map | D8: Read before editing | E8: Grey | F8: All DATA tabs | G8: Required | H8: Defines writable zones.
A9: Source intake | B9: STG_SOURCE_INTAKE | C9: Source package and hierarchy | D9: Blue input | E9: Blue | F9: Confidence and audit trail | G9: Required | H9: Log source names, versions, hierarchy and review status.
A10: Reconciliation | B10: RECONCILIATION_SUMMARY | C10: Prior-versus-latest crosswalk | D10: Read only | E10: Green/Grey | F10: Phase 1 report | G10: Required | H10: Use for case-specific prior-versus-current reconciliation.
A11: Canonical data | B11: DATA_PROPERTY_MASTER | C11: One row per property/project | D11: Blue input + generated checks | E11: Blue/Purple | F11: Metrics and snapshot | G11: Required | H11: One row per portfolio property or project.
A12: Canonical data | B12: DATA_UNIT_MIX | C12: Mutually exclusive unit categories | D12: Blue input | E12: Blue | F12: Mission metrics | G12: Required | H12: Use mutually exclusive unit classifications; retain unclassified units.
A13: Canonical data | B13: DATA_OPERATING_ACTUALS | C13: Annual operating and reserve source rows | D13: Blue input | E13: Blue | F13: Financial metrics and trends | G13: Required | H13: Load annual operating and reserve rows with explicit fiscal years.
A14: Canonical data | B14: DATA_DEBT_MASTER | C14: Debt instrument master | D14: Blue input | E14: Blue/Purple | F14: Debt profile | G14: Required | H14: Separate instrument-level debt detail from annual portfolio debt service.
A15: Canonical data | B15: DATA_DEBT_SCHEDULE | C15: Annual principal and interest schedule | D15: Blue inputs + formula total | E15: Blue/Black | F15: DSCR and cash flow | G15: Required | H15: Annual debt values are controlled inputs; total debt service is formula-driven.
... A40: Dashboard | B40: DASH_08_REPORTS_SHARING | C40: Reports and authorized use | D40: Formula-driven | E40: Green | F40: User UI | G40: P0 | H40: Versioned outputs, approval and sharing.

Sheet INPUT_CONTROL_MAP
A1: INPUT_CONTROL_MAP — MVP v1.0 analyst / AI write map
A2: Blue cells are controlled inputs. Black cells are formulas. Purple cells are generated checks. Orange cells are unresolved review items. Green sheets are outputs.
A4: Zone | B4: Tab | C4: Range / Columns | D4: Field / Purpose | E4: Write Permission | F4: Table Exists? | G4: Feeds To | H4: Notes
A5: CONTROL | B5: MVP_CONTROL | C5: B5:B15 | D5: Reporting year, source hierarchy and calculation basis | E5: Human / analyst may update blue values | F5: Yes | G5: Metrics, checks and outputs | H5: Change reporting year here only.
A6: PRIMARY INPUT | B6: STG_SOURCE_INTAKE | C6: A5:J206 | D6: Source file log and hierarchy | E6: Human / AI may write blue cells | F6: Yes | G6: Confidence and audit trail | H6: Log sources before data entry.
A7: PRIMARY INPUT | B7: DATA_PROPERTY_MASTER | C7: A7:Q206 | D7: Property identity, inclusion, units and source confidence | E7: Human / AI may write blue cells | F7: Yes | G7: Metrics and snapshot | H7: Alternate counts remain visible.
A8: PRIMARY INPUT | B8: DATA_UNIT_MIX | C8: A7:Q206 | D8: Mutually exclusive unit / affordability categories | E8: Human / AI may write blue cells | F8: Yes | G8: Mission metrics | H8: Unclassified units are allowed.
A9: PRIMARY INPUT | B9: DATA_OPERATING_ACTUALS | C9: A7:M306 | D9: Annual operating, debt and reserve source rows | E9: Human / AI may write blue cells | F9: Yes | G9: Financial metrics and trend | H9: Use standardized categories.
A10: PRIMARY INPUT | B10: DATA_DEBT_MASTER | C10: A7:T206 | D10: Instrument facts, reporting-year and stabilized debt service | E10: Human / AI may write blue cells | F10: Yes | G10: Debt profile | H10: Do not use stabilized debt for current-year DSCR.
A11: PRIMARY INPUT | B11: DATA_DEBT_SCHEDULE | C11: A5:D206; F:H | D11: Annual principal and interest by fiscal year | E11: Human / AI may write blue cells; total is formula | F11: Yes | G11: DSCR and AFFO | H11: Time-dimensioned.
A12: PRIMARY INPUT | B12: DATA_CASH_RESERVES | C12: A7:L206 | D12: Cash / reserve balances and availability | E12: Human / AI may write blue cells | F12: Yes | G12: Readiness flags | H12: Unknown availability remains conditional.
A13: PRIMARY INPUT | B13: DATA_AGREEMENTS | C13: A7:N206 | D13: Operating agreements and restrictions | E13: Human / AI may write blue cells | F13: Yes | G13: Mission review | H13: Placeholder acceptable.
A14: PRIMARY INPUT | B14: DATA_CAPITAL_NEEDS | C14: A7:N206 | D14: Capital repairs and funding status | E14: Human / AI may write blue cells | F14: Yes | G14: Capital readiness | H14: Placeholder acceptable.
A15: CONTROLLED REVIEW | B15: ASSUMPTIONS_FLAGS | C15: A7:J206 | D15: Conflicts, overrides, owners and status | E15: Human / AI may write orange review cells | F15: Yes | G15: Checks and snapshot | H15: Every unresolved issue must be logged.
... A29: V2 OUTPUT | B29: DASH_01_PORTFOLIO to DASH_08_REPORTS_SHARING | C29: Dashboard ranges | D29: Formula-driven UI specification | E29: No direct manual KPI entry | F29: Yes | G29: Output | H29: Eight pages are views over controlled tables.

Sheet STG_SOURCE_INTAKE
A1: STG_SOURCE_INTAKE — Source Package Log v0.3
A2: Log every source before loading data. Identify which file governs operating cash flow, annual debt schedule, instrument detail and project assumptions.
A4: Source_ID | B4: File / Source Name | C4: Source Type | D4: Version / Date | E4: Priority | F4: Used For | G4: Review Status | H4: Owner | I4: Notes | J4: Supersedes / Related

Sheet MAP_FIELD_MAPPING
A1: MAP_FIELD_MAPPING — Source to Canonical MVP Fields
A2: Shows how NGO source material maps into the simplified digital MVP template. Purple rows are generated/structured fields; orange rows require review.
A4: Map_ID | B4: Source / Document Field | C4: Canonical Tab | D4: Canonical Field | E4: Required for MVP? | F4: Current MVP Source | G4: Status | H4: Notes
A5: MAP-001 | B5: Property name / project name | C5: DATA_PROPERTY_MASTER | D5: Property_Name | E5: Yes | F5: NGO B v12 property master | G5: Live | H5: One row per property/project.
A6: MAP-002 | B6: Property ID / tab ID | C6: DATA_PROPERTY_MASTER | D6: Property_ID | E6: Yes | F6: NGO B v12 | G6: Live | H6: Preserves v12 BLD_* identifiers for traceability.
A7: MAP-003 | B7: Included / excluded scope | C7: DATA_PROPERTY_MASTER | D7: Included? | E7: Yes | F7: v12 model control | G7: Live | H7: Alma Blackwell remains excluded unless changed.
A8: MAP-004 | B8: Unit count | C8: DATA_PROPERTY_MASTER | D8: Modeled_Unit_Count | E8: Yes | F8: v12 + Tapestry where updated | G8: Review | H8: Port Moody 245 vs 328 unresolved; 800 Commercial source update should be documented.
A9: MAP-005 | B9: Affordability / unit bands | C9: DATA_UNIT_MIX | D9: Affordability_Band; Unit_Count | E9: Yes, if available | F9: Tapestry / rent roll / NGO data | G9: Partial | H9: Can be partial in MVP.
A10: MAP-006 | B10: Operating budget / actuals | C10: DATA_OPERATING_ACTUALS | D10: IREI_Category; Amount | E10: Yes | F10: Tapestry / budgets | G10: Partial | H10: Core financial snapshot input.
A11: MAP-007 | B11: Mortgage / debt schedule | C11: DATA_DEBT_MASTER | D11: Principal; Rate; Amortization; Debt Service | E11: Yes | F11: Tapestry + amortization schedule | G11: Partial | H11: Use latest Tapestry assumptions for four projects.
A12: MAP-008 | B12: Cash balance / reserves | C12: DATA_CASH_RESERVES | D12: Restricted / unrestricted / available flags | E12: Yes | F12: Tapestry / financials | G12: Review | H12: Restricted cash may remain unknown.
A13: MAP-009 | B13: Capital plan / BCA | C13: DATA_CAPITAL_NEEDS | D13: Estimated cost; timing; funded status | E13: Placeholder | F13: Not fully available | G13: Open | H13: MVP should flag the gap, not hide it.
A14: MAP-010 | B14: Operating agreements / covenants | C14: DATA_AGREEMENTS | D14: Restriction fields | E14: Placeholder | F14: Not fully reviewed | G14: Open | H14: Mission/restriction review remains partial.
A15: MAP-011 | B15: Quality checks | C15: DATA_QUALITY_CHECKS | D15: Status | E15: Yes | F15: Formulas | G15: Live | H15: Calculates from source logs and flags.
A16: MAP-012 | B16: Readiness outcome | C16: OUT_STAGE1_READINESS_SNAPSHOT | D16: Overall status | E16: Yes | F16: Formulas | G16: Live | H16: MVP final output.

Sheet DATA_PROPERTY_MASTER
A1: DATA_PROPERTY_MASTER — MVP Property / Project Master
A2: Blue cells are analyst/AI input. Purple columns are generated checks. Extracted from NGO B v12 and simplified for the MVP template.
A6: Property_ID | B6: Property_Name | C6: City | D6: Status | E6: Included? | F6: Final Classification | G6: Register Bucket Mapping | H6: Total Units | I6: Modeled Unit Count | J6: Alternate Unit Count | K6: Unit Conflict? | L6: Start Year | M6: Lender / Program | N6: Source Confidence | O6: Source Document ID | P6: Review Note | Q6: Data Status
K7: =IF(A7="","",IF(J7="","No",IF(I7=J7,"No","Yes"))) | Q7: =IF(A7="","",IF(K7="Yes","Review",IF(COUNTA(A7:I7)>=8,"Ready","Partial")))
K8: =IF(A8="","",IF(J8="","No",IF(I8=J8,"No","Yes"))) | Q8: =IF(A8="","",IF(K8="Yes","Review",IF(COUNTA(A8:I8)>=8,"Ready","Partial")))
K9: =IF(A9="","",IF(J9="","No",IF(I9=J9,"No","Yes"))) | Q9: =IF(A9="","",IF(K9="Yes","Review",IF(COUNTA(A9:I9)>=8,"Ready","Partial")))
K10: =IF(A10="","",IF(J10="","No",IF(I10=J10,"No","Yes"))) | Q10: =IF(A10="","",IF(K10="Yes","Review",IF(COUNTA(A10:I10)>=8,"Ready","Partial")))
K11: =IF(A11="","",IF(J11="","No",IF(I11=J11,"No","Yes"))) | Q11: =IF(A11="","",IF(K11="Yes","Review",IF(COUNTA(A11:I11)>=8,"Ready","Partial")))
K12: =IF(A12="","",IF(J12="","No",IF(I12=J12,"No","Yes"))) | Q12: =IF(A12="","",IF(K12="Yes","Review",IF(COUNTA(A12:I12)>=8,"Ready","Partial")))
K13: =IF(A13="","",IF(J13="","No",IF(I13=J13,"No","Yes"))) | Q13: =IF(A13="","",IF(K13="Yes","Review",IF(COUNTA(A13:I13)>=8,"Ready","Partial")))
K14: =IF(A14="","",IF(J14="","No",IF(I14=J14,"No","Yes"))) | Q14: =IF(A14="","",IF(K14="Yes","Review",IF(COUNTA(A14:I14)>=8,"Ready","Partial")))
K15: =IF(A15="","",IF(J15="","No",IF(I15=J15,"No","Yes"))) | Q15: =IF(A15="","",IF(K15="Yes","Review",IF(COUNTA(A15:I15)>=8,"Ready","Partial")))
K16: =IF(A16="","",IF(J16="","No",IF(I16=J16,"No","Yes"))) | Q16: =IF(A16="","",IF(K16="Yes","Review",IF(COUNTA(A16:I16)>=8,"Ready","Partial")))
K17: =IF(A17="","",IF(J17="","No",IF(I17=J17,"No","Yes"))) | Q17: =IF(A17="","",IF(K17="Yes","Review",IF(COUNTA(A17:I17)>=8,"Ready","Partial")))
K18: =IF(A18="","",IF(J18="","No",IF(I18=J18,"No","Yes"))) | Q18: =IF(A18="","",IF(K18="Yes","Review",IF(COUNTA(A18:I18)>=8,"Ready","Partial")))
... K206: =IF(A206="","",IF(J206="","No",IF(I206=J206,"No","Yes"))) | Q206: =IF(A206="","",IF(K206="Yes","Review",IF(COUNTA(A206:I206)>=8,"Ready","Partial")))

Sheet DATA_UNIT_MIX
A1: DATA_UNIT_MIX — Unit Mix / Affordability Inputs
A2: Blue cells are writable input zones. This tab mirrors v12 canonical input logic and remains separate from live calculations until mapped.
A6: Record_ID | B6: Property_ID | C6: Property_Name | D6: Unit_Group_ID | E6: Bedroom_Type | F6: Unit_Type | G6: Affordability_Band | H6: Unit_Count | I6: Affordable_Units | J6: Market_Units | K6: Supportive_Units | L6: Avg_Current_Rent | M6: Avg_Market_Rent | N6: Source_File_ID | O6: Review_Status | P6: Unclassified_Units | Q6: Commercial_Units

Sheet DATA_RENT_ROLL
A1: DATA_RENT_ROLL — Optional Rent Roll Detail
A2: Blue cells are writable. MVP v1 can work from operating forecast if detailed rent roll is unavailable.
A6: Record_ID | B6: Property_ID | C6: Property_Name | D6: Rent_Record_Level | E6: Unit_ID_or_Group | F6: Bedroom_Type | G6: Unit_Type | H6: Unit_Count | I6: Tenant_Status | J6: Vacancy_Status | K6: Current_Monthly_Rent | L6: Market_Monthly_Rent | M6: Source_File_ID

Sheet DATA_OPERATING_ACTUALS
A1: DATA_OPERATING_ACTUALS — Operating Budgets / Actuals / Forecasts
A2: Blue cells are writable. Standardize source lines into IREI categories for live MVP metrics.
A6: Record_ID | B6: Property_ID | C6: Property_Name | D6: Fiscal_Year | E6: Period | F6: Scenario | G6: Actual_Budget_Projection | H6: Source_Line_Item | I6: IREI_Category | J6: Amount | K6: Cash_or_Accrual | L6: Source_File_ID | M6: Review_Status

Sheet DATA_DEBT_MASTER
A1: DATA_DEBT_MASTER — Debt / Mortgage / Financing Inputs
A2: Blue cells are writable. Purple columns are formula checks. Use Tapestry / ENF for updated demo assumptions where it supersedes v12 generic assumptions.
A6: Debt_ID | B6: Property_ID | C6: Property_Name | D6: Included? | E6: Debt_Type | F6: Lender / Program | G6: Principal_Amount | H6: Interest_Rate | I6: Term_Years | J6: Amortization_Years | K6: Reporting_Year_Principal | L6: Reporting_Year_Interest | M6: Reporting_Year_Debt_Service | N6: Source_Annual_Debt_Service | O6: Source_File_ID | P6: Review_Status | Q6: Debt_Status | R6: Notes | S6: Stabilized_Annual_Debt_Service | T6: First_Full_Service_Year
K7: =IF(N7<>"","",IF(AND(G7<>"",H7<>"",J7<>""),ROUND(PPMT(H7,1,J7,-G7),0),"")) | L7: =IF(N7<>"","",IF(AND(G7<>"",H7<>""),ROUND(G7*H7,0),"")) | M7: =IF(N7<>"",N7,IF(AND(G7<>"",H7<>"",J7<>""),ROUND(PMT(H7,J7,-G7),0),"")) | Q7: =IF(A7="","",IF(D7="No","Excluded",IF(AND(OR(F7="N/A",E7="No Debt / N/A"),G7=""),"No Debt / N/A",IF(M7<>"","Ready","Partial"))))
K8: =IF(N8<>"","",IF(AND(G8<>"",H8<>"",J8<>""),ROUND(PPMT(H8,1,J8,-G8),0),"")) | L8: =IF(N8<>"","",IF(AND(G8<>"",H8<>""),ROUND(G8*H8,0),"")) | M8: =IF(N8<>"",N8,IF(AND(G8<>"",H8<>"",J8<>""),ROUND(PMT(H8,J8,-G8),0),"")) | Q8: =IF(A8="","",IF(D8="No","Excluded",IF(AND(OR(F8="N/A",E8="No Debt / N/A"),G8=""),"No Debt / N/A",IF(M8<>"","Ready","Partial"))))
K9: =IF(N9<>"","",IF(AND(G9<>"",H9<>"",J9<>""),ROUND(PPMT(H9,1,J9,-G9),0),"")) | L9: =IF(N9<>"","",IF(AND(G9<>"",H9<>""),ROUND(G9*H9,0),"")) | M9: =IF(N9<>"",N9,IF(AND(G9<>"",H9<>"",J9<>""),ROUND(PMT(H9,J9,-G9),0),"")) | Q9: =IF(A9="","",IF(D9="No","Excluded",IF(AND(OR(F9="N/A",E9="No Debt / N/A"),G9=""),"No Debt / N/A",IF(M9<>"","Ready","Partial"))))
K10: =IF(N10<>"","",IF(AND(G10<>"",H10<>"",J10<>""),ROUND(PPMT(H10,1,J10,-G10),0),"")) | L10: =IF(N10<>"","",IF(AND(G10<>"",H10<>""),ROUND(G10*H10,0),"")) | M10: =IF(N10<>"",N10,IF(AND(G10<>"",H10<>"",J10<>""),ROUND(PMT(H10,J10,-G10),0),"")) | Q10: =IF(A10="","",IF(D10="No","Excluded",IF(AND(OR(F10="N/A",E10="No Debt / N/A"),G10=""),"No Debt / N/A",IF(M10<>"","Ready","Partial"))))
K11: =IF(N11<>"","",IF(AND(G11<>"",H11<>"",J11<>""),ROUND(PPMT(H11,1,J11,-G11),0),"")) | L11: =IF(N11<>"","",IF(AND(G11<>"",H11<>""),ROUND(G11*H11,0),"")) | M11: =IF(N11<>"",N11,IF(AND(G11<>"",H11<>"",J11<>""),ROUND(PMT(H11,J11,-G11),0),"")) | Q11: =IF(A11="","",IF(D11="No","Excluded",IF(AND(OR(F11="N/A",E11="No Debt / N/A"),G11=""),"No Debt / N/A",IF(M11<>"","Ready","Partial"))))
K12: =IF(N12<>"","",IF(AND(G12<>"",H12<>"",J12<>""),ROUND(PPMT(H12,1,J12,-G12),0),"")) | L12: =IF(N12<>"","",IF(AND(G12<>"",H12<>""),ROUND(G12*H12,0),"")) | M12: =IF(N12<>"",N12,IF(AND(G12<>"",H12<>"",J12<>""),ROUND(PMT(H12,J12,-G12),0),"")) | Q12: =IF(A12="","",IF(D12="No","Excluded",IF(AND(OR(F12="N/A",E12="No Debt / N/A"),G12=""),"No Debt / N/A",IF(M12<>"","Ready","Partial"))))
K13: =IF(N13<>"","",IF(AND(G13<>"",H13<>"",J13<>""),ROUND(PPMT(H13,1,J13,-G13),0),"")) | L13: =IF(N13<>"","",IF(AND(G13<>"",H13<>""),ROUND(G13*H13,0),"")) | M13: =IF(N13<>"",N13,IF(AND(G13<>"",H13<>"",J13<>""),ROUND(PMT(H13,J13,-G13),0),"")) | Q13: =IF(A13="","",IF(D13="No","Excluded",IF(AND(OR(F13="N/A",E13="No Debt / N/A"),G13=""),"No Debt / N/A",IF(M13<>"","Ready","Partial"))))
K14: =IF(N14<>"","",IF(AND(G14<>"",H14<>"",J14<>""),ROUND(PPMT(H14,1,J14,-G14),0),"")) | L14: =IF(N14<>"","",IF(AND(G14<>"",H14<>""),ROUND(G14*H14,0),"")) | M14: =IF(N14<>"",N14,IF(AND(G14<>"",H14<>"",J14<>""),ROUND(PMT(H14,J14,-G14),0),"")) | Q14: =IF(A14="","",IF(D14="No","Excluded",IF(AND(OR(F14="N/A",E14="No Debt / N/A"),G14=""),"No Debt / N/A",IF(M14<>"","Ready","Partial"))))
K15: =IF(N15<>"","",IF(AND(G15<>"",H15<>"",J15<>""),ROUND(PPMT(H15,1,J15,-G15),0),"")) | L15: =IF(N15<>"","",IF(AND(G15<>"",H15<>""),ROUND(G15*H15,0),"")) | M15: =IF(N15<>"",N15,IF(AND(G15<>"",H15<>"",J15<>""),ROUND(PMT(H15,J15,-G15),0),"")) | Q15: =IF(A15="","",IF(D15="No","Excluded",IF(AND(OR(F15="N/A",E15="No Debt / N/A"),G15=""),"No Debt / N/A",IF(M15<>"","Ready","Partial"))))
K16: =IF(N16<>"","",IF(AND(G16<>"",H16<>"",J16<>""),ROUND(PPMT(H16,1,J16,-G16),0),"")) | L16: =IF(N16<>"","",IF(AND(G16<>"",H16<>""),ROUND(G16*H16,0),"")) | M16: =IF(N16<>"",N16,IF(AND(G16<>"",H16<>"",J16<>""),ROUND(PMT(H16,J16,-G16),0),"")) | Q16: =IF(A16="","",IF(D16="No","Excluded",IF(AND(OR(F16="N/A",E16="No Debt / N/A"),G16=""),"No Debt / N/A",IF(M16<>"","Ready","Partial"))))
K17: =IF(N17<>"","",IF(AND(G17<>"",H17<>"",J17<>""),ROUND(PPMT(H17,1,J17,-G17),0),"")) | L17: =IF(N17<>"","",IF(AND(G17<>"",H17<>""),ROUND(G17*H17,0),"")) | M17: =IF(N17<>"",N17,IF(AND(G17<>"",H17<>"",J17<>""),ROUND(PMT(H17,J17,-G17),0),"")) | Q17: =IF(A17="","",IF(D17="No","Excluded",IF(AND(OR(F17="N/A",E17="No Debt / N/A"),G17=""),"No Debt / N/A",IF(M17<>"","Ready","Partial"))))
K18: =IF(N18<>"","",IF(AND(G18<>"",H18<>"",J18<>""),ROUND(PPMT(H18,1,J18,-G18),0),"")) | L18: =IF(N18<>"","",IF(AND(G18<>"",H18<>""),ROUND(G18*H18,0),"")) | M18: =IF(N18<>"",N18,IF(AND(G18<>"",H18<>"",J18<>""),ROUND(PMT(H18,J18,-G18),0),"")) | Q18: =IF(A18="","",IF(D18="No","Excluded",IF(AND(OR(F18="N/A",E18="No Debt / N/A"),G18=""),"No Debt / N/A",IF(M18<>"","Ready","Partial"))))
... K206: =IF(N206<>"","",IF(AND(G206<>"",H206<>"",J206<>""),ROUND(PPMT(H206,1,J206,-G206),0),"")) | L206: =IF(N206<>"","",IF(AND(G206<>"",H206<>""),ROUND(G206*H206,0),"")) | M206: =IF(N206<>"",N206,IF(AND(G206<>"",H206<>"",J206<>""),ROUND(PMT(H206,J206,-G206),0),"")) | Q206: =IF(A206="","",IF(D206="No","Excluded",IF(AND(OR(F206="N/A",E206="No Debt / N/A"),G206=""),"No Debt / N/A",IF(M206<>"","Ready","Partial"))))

Sheet DATA_CASH_RESERVES
A1: DATA_CASH_RESERVES — Cash / Reserve Availability Inputs
A2: Blue cells are writable. Restricted cash treatment is a key MVP flag if not confirmed.
A6: Cash_ID | B6: Organization_ID | C6: Property_ID | D6: Year | E6: Opening_Cash | F6: Closing_Cash | G6: Restricted_Cash | H6: Unrestricted_Cash | I6: Available_for_Operations | J6: Available_for_Debt_Service | K6: Source_File_ID | L6: Review_Status

Sheet DATA_AGREEMENTS
A1: DATA_AGREEMENTS — Agreements / Restrictions Inputs
A2: Blue cells are writable. This tab tracks mission-lock, affordability, covenant, cash, refinance, and disposition restrictions. Placeholder is acceptable in MVP v1.
A6: Agreement_ID | B6: Property_ID | C6: Property_Name | D6: Agreement_Type | E6: Counterparty | F6: Start_Date | G6: End_Date | H6: Affordability_Requirement | I6: Rent_Restriction | J6: Use_Restriction | K6: Refinance_Restriction | L6: Disposition_Restriction | M6: Source_File_ID | N6: Review_Status

Sheet DATA_CAPITAL_NEEDS
A1: DATA_CAPITAL_NEEDS — Capital Needs / Deferred Maintenance Inputs
A2: Blue cells are writable. Purple unfunded amount formula remains live. Missing capital plan should be flagged, not hidden.
A6: Capital_Item_ID | B6: Property_ID | C6: Property_Name | D6: Capital_Item | E6: Capital_Category | F6: Required_or_Discretionary | G6: Year_Needed | H6: Estimated_Cost | I6: Funded_Amount | J6: Unfunded_Amount | K6: Funding_Source | L6: Deferred_Maintenance_Flag | M6: Source_File_ID | N6: Review_Status
J7: =IF(H7="","",MAX(H7-I7,0))
J8: =IF(H8="","",MAX(H8-I8,0))
J9: =IF(H9="","",MAX(H9-I9,0))
J10: =IF(H10="","",MAX(H10-I10,0))
J11: =IF(H11="","",MAX(H11-I11,0))
J12: =IF(H12="","",MAX(H12-I12,0))
J13: =IF(H13="","",MAX(H13-I13,0))
J14: =IF(H14="","",MAX(H14-I14,0))
J15: =IF(H15="","",MAX(H15-I15,0))
J16: =IF(H16="","",MAX(H16-I16,0))
J17: =IF(H17="","",MAX(H17-I17,0))
J18: =IF(H18="","",MAX(H18-I18,0))
... J206: =IF(H206="","",MAX(H206-I206,0))

Sheet ASSUMPTIONS_FLAGS
A1: ASSUMPTIONS_FLAGS — Review Flags / Source Conflicts / Assumptions
A2: Orange cells are controlled review areas. Keep unresolved issues visible until confirmed.
A6: Flag_ID | B6: Category | C6: Property_ID | D6: Issue / Assumption | E6: Current Treatment | F6: Severity | G6: Requires Confirmation? | H6: Owner | I6: Status | J6: Reviewer Note

Sheet DATA_METRIC_LONG
A1: DATA_METRIC_LONG — Live MVP Metrics
A2: Formula-driven output metrics. Column D intentionally mirrors the live formula output for QA; Column E is the output value used by the snapshot. Plain-English documentation belongs in CALC_RULES / Notes.
A6: Metric_ID | B6: Metric_Name | C6: Metric_Category | D6: Live Formula Mirror | E6: Metric_Value | F6: Metric_Status | G6: Source_Confidence | H6: Notes
A7: MET-001 | B7: Total Portfolio Records | C7: Portfolio | D7: =COUNTA(DATA_PROPERTY_MASTER!A7:A206) -> 0 | E7: =COUNTA(DATA_PROPERTY_MASTER!A7:A206) -> 0 | F7: Live | G7: Formula-linked | H7: Includes excluded portfolio records.
A8: MET-002 | B8: Included Properties | C8: Portfolio | D8: =COUNTIF(DATA_PROPERTY_MASTER!E7:E206,"Yes") -> 0 | E8: =COUNTIF(DATA_PROPERTY_MASTER!E7:E206,"Yes") -> 0 | F8: Live | G8: Formula-linked | H8: Financial-model scope.
A9: MET-003 | B9: Existing Assets | C9: Portfolio | D9: =COUNTIF(DATA_PROPERTY_MASTER!D7:D206,"Active") -> 0 | E9: =COUNTIF(DATA_PROPERTY_MASTER!D7:D206,"Active") -> 0 | F9: Live | G9: Formula-linked | H9: All existing assets, including excluded record.
A10: MET-004 | B10: Existing Included Assets | C10: Portfolio | D10: =COUNTIFS(DATA_PROPERTY_MASTER!D7:D206,"Active",DATA_PROPERTY_MASTER!E7:E206,"Yes") -> 0 | E10: =COUNTIFS(DATA_PROPERTY_MASTER!D7:D206,"Active",DATA_PROPERTY_MASTER!E7:E206,"Yes") -> 0 | F10: Live | G10: Formula-linked | H10: Existing assets included in calculations.
A11: MET-005 | B11: New / Future Projects | C11: Portfolio | D11: =COUNTIFS(DATA_PROPERTY_MASTER!D7:D206,"New Dev",DATA_PROPERTY_MASTER!E7:E206,"Yes") -> 0 | E11: =COUNTIFS(DATA_PROPERTY_MASTER!D7:D206,"New Dev",DATA_PROPERTY_MASTER!E7:E206,"Yes") -> 0 | F11: Live | G11: Formula-linked | H11: Four new/future projects.
A12: MET-006 | B12: Modeled Units | C12: Portfolio | D12: =SUMIFS(DATA_PROPERTY_MASTER!I7:I206,DATA_PROPERTY_MASTER!E7:E206,"Yes") -> 0 | E12: =SUMIFS(DATA_PROPERTY_MASTER!I7:I206,DATA_PROPERTY_MASTER!E7:E206,"Yes") -> 0 | F12: Review | G12: Source conflict | H12: Latest modeled in-scope units.
A13: MET-007 | B13: Total Portfolio Units incl Excluded | C13: Portfolio | D13: =SUM(DATA_PROPERTY_MASTER!I7:I206) -> 0 | E13: =SUM(DATA_PROPERTY_MASTER!I7:I206) -> 0 | F13: Review | G13: Formula-linked | H13: Includes Alma Blackwell.
A14: MET-008 | B14: Unit Count Conflicts | C14: Data Readiness | D14: =COUNTIF(DATA_PROPERTY_MASTER!K7:K206,"Yes") -> 0 | E14: =COUNTIF(DATA_PROPERTY_MASTER!K7:K206,"Yes") -> 0 | F14: Review | G14: Formula-linked | H14: Port Moody and 800 Commercial.
A15: MET-009 | B15: Source Documents Logged | C15: Data Readiness | D15: =COUNTA(STG_SOURCE_INTAKE!A5:A206) -> 0 | E15: =COUNTA(STG_SOURCE_INTAKE!A5:A206) -> 0 | F15: Live | G15: Formula-linked | H15: Latest source package.
A16: MET-010 | B16: Open Assumption Flags | C16: Data Readiness | D16: =COUNTIF(ASSUMPTIONS_FLAGS!I7:I206,"Open") -> 0 | E16: =COUNTIF(ASSUMPTIONS_FLAGS!I7:I206,"Open") -> 0 | F16: Review | G16: Formula-linked | H16: Unresolved items only.
A17: MET-011 | B17: Revenue | C17: Financial | D17: =SUMIFS(DATA_OPERATING_ACTUALS!J7:J306,DATA_OPERATING_ACTUALS!D7:D306,MVP_CONTROL!B5,DATA_OPERATING_ACTUALS!I7:I306,"Revenue") -> 0 | E17: =SUMIFS(DATA_OPERATING_ACTUALS!J7:J306,DATA_OPERATING_ACTUALS!D7:D306,MVP_CONTROL!B5,DATA_OPERATING_ACTUALS!I7:I306,"Revenue") -> 0 | F17: Live | G17: Source-linked | H17: Selected reporting year.
A18: MET-012 | B18: Society Operating Expenses | C18: Financial | D18: =SUMIFS(DATA_OPERATING_ACTUALS!J7:J306,DATA_OPERATING_ACTUALS!D7:D306,MVP_CONTROL!B5,DATA_OPERATING_ACTUALS!H7:H306,"Society operating expenses") -> 0 | E18: =SUMIFS(DATA_OPERATING_ACTUALS!J7:J306,DATA_OPERATING_ACTUALS!D7:D306,MVP_CONTROL!B5,DATA_OPERATING_ACTUALS!H7:H306,"Society operating expenses") -> 0 | F18: Live | G18: Source-linked | H18: Selected reporting year.
A19: MET-013 | B19: Building Operating Expenses | C19: Financial | D19: =SUMIFS(DATA_OPERATING_ACTUALS!J7:J306,DATA_OPERATING_ACTUALS!D7:D306,MVP_CONTROL!B5,DATA_OPERATING_ACTUALS!H7:H306,"Building operating expenses") -> 0 | E19: =SUMIFS(DATA_OPERATING_ACTUALS!J7:J306,DATA_OPERATING_ACTUALS!D7:D306,MVP_CONTROL!B5,DATA_OPERATING_ACTUALS!H7:H306,"Building operating expenses") -> 0 | F19: Live | G19: Source-linked | H19: Selected reporting year.
A20: MET-014 | B20: Operating Expenses | C20: Financial | D20: =SUMIFS(DATA_OPERATING_ACTUALS!J7:J306,DATA_OPERATING_ACTUALS!D7:D306,MVP_CONTROL!B5,DATA_OPERATING_ACTUALS!I7:I306,"Operating Expense") -> 0 | E20: =SUMIFS(DATA_OPERATING_ACTUALS!J7:J306,DATA_OPERATING_ACTUALS!D7:D306,MVP_CONTROL!B5,DATA_OPERATING_ACTUALS!I7:I306,"Operating Expense") -> 0 | F20: Live | G20: Formula-linked | H20: Society plus building operating expenses before debt.
A21: MET-015 | B21: NOI / Cash Before Debt | C21: Financial | D21: =E17-E20 -> 0 | E21: =E17-E20 -> 0 | F21: Live | G21: Formula-linked | H21: Revenue less operating expenses.
A22: MET-016 | B22: Debt Service | C22: Financial | D22: =SUMIFS(DATA_DEBT_SCHEDULE!E5:E206,DATA_DEBT_SCHEDULE!B5:B206,MVP_CONTROL!B5) -> 0 | E22: =SUMIFS(DATA_DEBT_SCHEDULE!E5:E206,DATA_DEBT_SCHEDULE!B5:B206,MVP_CONTROL!B5) -> 0 | F22: Live | G22: Source-linked | H22: Selected-year principal plus interest.
A23: MET-017 | B23: AFFO / Cash Flow After Debt | C23: Financial | D23: =E21-E22 -> 0 | E23: =E21-E22 -> 0 | F23: Review | G23: Formula-linked | H23: Simplified cash flow before capital-reserve contribution.
A24: MET-018 | B24: DSCR | C24: Financial | D24: =IFERROR(E21/E22,"") | E24: =IFERROR(E21/E22,"") | F24: Review | G24: Formula-linked | H24: NOI / selected-year debt service.
A25: MET-019 | B25: Source Net Society Income | C25: Financial | D25: =SUMIFS(DATA_OPERATING_ACTUALS!J7:J306,DATA_OPERATING_ACTUALS!D7:D306,MVP_CONTROL!B5,DATA_OPERATING_ACTUALS!I7:I306,"Source Net Income") -> 0 | E25: =SUMIFS(DATA_OPERATING_ACTUALS!J7:J306,DATA_OPERATING_ACTUALS!D7:D306,MVP_CONTROL!B5,DATA_OPERATING_ACTUALS!I7:I306,"Source Net Income") -> 0 | F25: Control | G25: Source-linked | H25: Reconciliation control from Bond v18 row 82.
A26: MET-020 | B26: Closing Reserve / Net Balance | C26: Cash / Reserves | D26: =SUMIFS(DATA_OPERATING_ACTUALS!J7:J306,DATA_OPERATING_ACTUALS!D7:D306,MVP_CONTROL!B5,DATA_OPERATING_ACTUALS!I7:I306,"Reserve Closing") -> 0 | E26: =SUMIFS(DATA_OPERATING_ACTUALS!J7:J306,DATA_OPERATING_ACTUALS!D7:D306,MVP_CONTROL!B5,DATA_OPERATING_ACTUALS!I7:I306,"Reserve Closing") -> 0 | F26: Review | G26: Source-linked | H26: Definition differs from historical balance-sheet cash.
A27: MET-021 | B27: Deep Subsidy Units | C27: Mission / Affordability | D27: =SUMIFS(DATA_UNIT_MIX!H7:H206,DATA_UNIT_MIX!G7:G206,"Deep Subsidy") -> 0 | E27: =SUMIFS(DATA_UNIT_MIX!H7:H206,DATA_UNIT_MIX!G7:G206,"Deep Subsidy") -> 0 | F27: Partial | G27: Source-linked | H27: Known new-project units.
A28: MET-022 | B28: Subsidized Units | C28: Mission / Affordability | D28: =SUMIFS(DATA_UNIT_MIX!H7:H206,DATA_UNIT_MIX!G7:G206,"Subsidized") -> 0 | E28: =SUMIFS(DATA_UNIT_MIX!H7:H206,DATA_UNIT_MIX!G7:G206,"Subsidized") -> 0 | F28: Partial | G28: Source-linked | H28: Known new-project units.
A29: MET-023 | B29: Known Affordable Units | C29: Mission / Affordability | D29: =SUM(DATA_UNIT_MIX!I7:I206) -> 0 | E29: =SUM(DATA_UNIT_MIX!I7:I206) -> 0 | F29: Partial | G29: Source-linked | H29: Deep subsidy plus subsidized.
A30: MET-024 | B30: Known Market Units | C30: Mission / Affordability | D30: =SUM(DATA_UNIT_MIX!J7:J206) -> 0 | E30: =SUM(DATA_UNIT_MIX!J7:J206) -> 0 | F30: Partial | G30: Source-linked | H30: Known new-project units.
A31: MET-025 | B31: Unclassified Existing Units | C31: Mission / Affordability | D31: =SUM(DATA_UNIT_MIX!P7:P206) -> 0 | E31: =SUM(DATA_UNIT_MIX!P7:P206) -> 0 | F31: Review | G31: Source-linked | H31: Existing units not yet classified by affordability.
A32: MET-026 | B32: Commercial Units | C32: Mission / Affordability | D32: =SUM(DATA_UNIT_MIX!Q7:Q206) -> 0 | E32: =SUM(DATA_UNIT_MIX!Q7:Q206) -> 0 | F32: Partial | G32: Source-linked | H32: 800 Commercial project.
A33: MET-027 | B33: Known Classification Coverage | C33: Mission / Affordability | D33: =IFERROR((E29+E30+E32)/E12,"") | E33: =D33 | F33: Review | G33: Formula-linked | H33: Known affordable + market + 1 commercial unit / modeled units.
A34: MET-028 | B34: Agreement Review Status | C34: Mission / Restrictions | D34: =IF(COUNTA(DATA_AGREEMENTS!A7:A206)=0,"Not reviewed","Partial / reviewed") -> Not reviewed | E34: =IF(COUNTA(DATA_AGREEMENTS!A7:A206)=0,"Not reviewed","Partial / reviewed") -> Not reviewed | F34: Review | G34: Formula-linked | H34: Agreement inventory not yet populated.
A35: MET-029 | B35: Capital Needs Review Status | C35: Capital Needs | D35: =IF(COUNTA(DATA_CAPITAL_NEEDS!A7:A206)=0,"Not reviewed","Partial / reviewed") -> Not reviewed | E35: =IF(COUNTA(DATA_CAPITAL_NEEDS!A7:A206)=0,"Not reviewed","Partial / reviewed") -> Not reviewed | F35: Review | G35: Formula-linked | H35: Placeholder remains open.

Sheet DATA_QUALITY_CHECKS
A1: DATA_QUALITY_CHECKS — Live MVP Quality / Readiness Checks
A2: Formula-driven checks. Open items are not always failures; they show what must be confirmed before investor-facing outputs.
A6: Check_ID | B6: Check Area | C6: Expected / Rule | D6: Actual | E6: Status | F6: Why It Matters | G6: Next Step
A7: QC-MVP-001 | B7: Portfolio record count | C7: >=1 | D7: =COUNTA(DATA_PROPERTY_MASTER!A7:A206) -> 0 | E7: =IF(D7>=1,"PASS","OPEN") -> OPEN | F7: Total portfolio count must be explicit. | G7: Review property register.
A8: QC-MVP-002 | B8: Included property count | C8: >=1 | D8: =COUNTIF(DATA_PROPERTY_MASTER!E7:E206,"Yes") -> 0 | E8: =IF(D8>=1,"PASS","OPEN") -> OPEN | F8: Financial scope must be explicit. | G8: Review Included? field.
A9: QC-MVP-003 | B9: Unit count conflicts | C9: 0 ideal | D9: =COUNTIF(DATA_PROPERTY_MASTER!K7:K206,"Yes") -> 0 | E9: =IF(D9=0,"PASS","OPEN") -> PASS | F9: Conflicts must remain visible. | G9: Confirm Port Moody and 800 Commercial.
A10: QC-MVP-004 | B10: Unit table reconciliation | C10: Property master = unit mix | D10: =SUMIFS(DATA_PROPERTY_MASTER!I7:I206,DATA_PROPERTY_MASTER!E7:E206,"Yes")-SUM(DATA_UNIT_MIX!H7:H206) -> 0 | E10: =IF(ABS(D10)<0.01,"PASS","FAIL") -> PASS | F10: Mission categories must reconcile to modeled units. | G10: Correct unit rows.
A11: QC-MVP-005 | B11: Source files logged | C11: >=1 | D11: =COUNTA(STG_SOURCE_INTAKE!A5:A206) -> 0 | E11: =IF(D11>=1,"PASS","OPEN") -> OPEN | F11: Auditability requires a source log. | G11: Maintain source hierarchy.
A12: QC-MVP-006 | B12: Operating data for selected year | C12: At least 3 core rows | D12: =COUNTIFS(DATA_OPERATING_ACTUALS!D7:D306,MVP_CONTROL!B5,DATA_OPERATING_ACTUALS!I7:I306,"Revenue")+COUNTIFS(DATA_OPERATING_ACTUALS!D7:D306,MVP_CONTROL!B5,DATA_OPERATING_ACTUALS!I7:I306,"Operating Expense") -> 0 | E12: =IF(D12>=3,"PASS","OPEN") -> OPEN | F12: Snapshot needs selected-year revenue and expenses. | G12: Load current forecast.
A13: QC-MVP-007 | B13: Debt schedule for selected year | C13: Exactly 1 portfolio row | D13: =COUNTIF(DATA_DEBT_SCHEDULE!B5:B206,MVP_CONTROL!B5) -> 0 | E13: =IF(D13=1,"PASS","OPEN") -> OPEN | F13: Prevents period mismatch in DSCR. | G13: Maintain annual debt schedule.
A14: QC-MVP-008 | B14: Financial reconciliation | C14: Calculated CF = source net income | D14: =INDEX(DATA_METRIC_LONG!E:E,MATCH("AFFO / Cash Flow After Debt",DATA_METRIC_LONG!B:B,0))-INDEX(DATA_METRIC_LONG!E:E,MATCH("Source Net Society Income",DATA_METRIC_LONG!B:B,0)) -> 0 | E14: =IF(COUNTA(DATA_OPERATING_ACTUALS!A7:A306)=0,"N/A",IF(ABS(D14)<1,"PASS","FAIL")) -> N/A | F14: Output should tie to source model. | G14: Investigate any difference.
A15: QC-MVP-009 | B15: Cash restriction / definition | C15: Known preferred | D15: =COUNTIF(DATA_CASH_RESERVES!I7:J206,"Unknown") -> 0 | E15: =IF(D15=0,"PASS","OPEN") -> PASS | F15: Cash is not automatically available liquidity. | G15: Confirm definitions and restrictions.
A16: QC-MVP-010 | B16: Known classification coverage | C16: 100% ideal | D16: =INDEX(DATA_METRIC_LONG!E:E,MATCH("Known Classification Coverage",DATA_METRIC_LONG!B:B,0)) | E16: =IF(D16>=1,"PASS","OPEN") -> PASS | F16: Affordability conclusions require full coverage. | G16: Classify existing units.
A17: QC-MVP-011 | B17: Capital needs reviewed | C17: At least one completed record | D17: =COUNTIFS(DATA_CAPITAL_NEEDS!A7:A206,"<>",DATA_CAPITAL_NEEDS!N7:N206,"<>Open") -> 0 | E17: =IF(D17>=1,"PASS","OPEN") -> OPEN | F17: Capital readiness cannot be inferred without a plan. | G17: Review BCA/capital plan.
A18: QC-MVP-012 | B18: Agreement review | C18: At least one reviewed record | D18: =COUNTA(DATA_AGREEMENTS!A7:A206) -> 0 | E18: =IF(D18>=1,"PARTIAL","OPEN") -> OPEN | F18: Mission restrictions and refinancing limits matter. | G18: Build agreement inventory.
A19: QC-MVP-013 | B19: Open material assumption flags | C19: 0 ideal | D19: =COUNTIF(ASSUMPTIONS_FLAGS!I7:I206,"Open") -> 0 | E19: =IF(D19=0,"PASS","OPEN") -> PASS | F19: Open flags drive conditional readiness. | G19: Resolve targeted confirmations.

Sheet OUT_STAGE1_READINESS_SNAPSHOT
A1: IREI Stage 1 Readiness Snapshot
A2: Reusable Stage 1 Readiness Snapshot — populate source and data tabs before use
A4: Portfolio Records | C4: Existing Assets | F4: New / Future Projects | I4: Overall Status
A5: =DATA_METRIC_LONG!E7 -> 0 | C5: =DATA_METRIC_LONG!E9 -> 0 | F5: =DATA_METRIC_LONG!E11 -> 0 | I5: =IF(COUNTIF(DATA_QUALITY_CHECKS!E7:E19,"OPEN")>0,"Conditional","Ready") -> Conditional
A8: 1. Portfolio Profile | F8: 2. Data Readiness
A9: Organization | C9: =IF(MVP_CONTROL!B18="","Organization / Demo",MVP_CONTROL!B18) -> Organization / Demo | F9: Property List | I9: Complete
A10: Review Type | C10: ="Stage 1 Readiness Review" -> Stage 1 Readiness Review | F10: Unit Counts | I10: Partial / Conflict
A11: Reporting Period | C11: =MVP_CONTROL!B5 -> 0 | F11: Operating Forecast | I11: Complete
A12: Primary Source Package | C12: Source package not yet loaded | F12: Debt / Mortgage Data | I12: Complete / Time-aligned
A13: Data Confidence | C13: =IF(COUNTIF(DATA_QUALITY_CHECKS!E7:E19,"OPEN")>0,"Partial / Conditional","Complete") -> Partial / Conditional | F13: Cash / Reserves | I13: Conditional
A14: Financial Scope | C14: =DATA_METRIC_LONG!E8&" included / "&DATA_METRIC_LONG!E7&" portfolio records" -> 0 included / 0 portfolio records | F14: Capital Needs | I14: Conditional
F15: Agreements / Restrictions | I15: Partial
F16: Source Documents | I16: Complete
A17: 3. Financial Snapshot (CAD) | G17: 4. Mission / Affordability Snapshot
A18: Metric | C18: Value | D18: Notes
A19: Revenue | C19: =DATA_METRIC_LONG!E17 -> 0 | D19: Bond v18, selected year | G19: Modeled Units | J19: =DATA_METRIC_LONG!E12 -> 0
A20: Operating Expenses | C20: =DATA_METRIC_LONG!E20 -> 0 | D20: Society + building, before debt | G20: Known Affordable Units | J20: =DATA_METRIC_LONG!E29 -> 0
A21: NOI / Cash Before Debt | C21: =DATA_METRIC_LONG!E21 -> 0 | D21: Revenue less operating expenses | G21: Known Market Units | J21: =DATA_METRIC_LONG!E30 -> 0
A22: Debt Service | C22: =DATA_METRIC_LONG!E22 -> 0 | D22: Selected-year principal + interest | G22: Unclassified Existing Units | J22: =DATA_METRIC_LONG!E31 -> 0
A23: Cash Flow After Debt | C23: =DATA_METRIC_LONG!E23 -> 0 | D23: Before capital-reserve contribution | G23: Known Classification Coverage* | J23: =DATA_METRIC_LONG!E33
A24: DSCR | C24: =DATA_METRIC_LONG!E24 | D24: NOI / debt service | G24: Agreement Review | J24: =DATA_METRIC_LONG!E34 -> Not reviewed
G25: *Includes affordable, market and the 1 commercial unit as classified.
A26: 5. Key Flags / Unresolved Items
A27: =IF(ASSUMPTIONS_FLAGS!D7="","","• "&ASSUMPTIONS_FLAGS!D7)
A28: =IF(ASSUMPTIONS_FLAGS!D8="","","• "&ASSUMPTIONS_FLAGS!D8)
A29: =IF(ASSUMPTIONS_FLAGS!D9="","","• "&ASSUMPTIONS_FLAGS!D9)
A30: =IF(ASSUMPTIONS_FLAGS!D10="","","• "&ASSUMPTIONS_FLAGS!D10)
A31: =IF(ASSUMPTIONS_FLAGS!D11="","","• "&ASSUMPTIONS_FLAGS!D11)
A32: =IF(ASSUMPTIONS_FLAGS!D12="","","• "&ASSUMPTIONS_FLAGS!D12)
A34: 6. Readiness Conclusion
A35: Data Readiness | C35: Financial Readiness | F35: Mission / Restriction Review | I35: Overall Stage 1 Readiness
A36: =IF(COUNTIF(DATA_QUALITY_CHECKS!E7:E19,"OPEN")>0,"Conditional","Ready") -> Conditional | C36: =IF(OR(DATA_METRIC_LONG!E23<0,DATA_METRIC_LONG!E24<1),"Conditional","Ready") -> Ready | F36: =IF(OR(DATA_METRIC_LONG!E33<1,DATA_METRIC_LONG!E34="Not reviewed"),"Partial","Complete") -> Partial | I36: =I5 -> Conditional
A37: =IF(A36="Conditional","Key data conflicts and evidence gaps remain","Core data checks passed") -> Key data conflicts and evidence gaps remain | C37: =IF(C36="Conditional","Selected-year cash flow or DSCR remains below threshold","Selected-year financial metrics meet the initial threshold") -> Selected-year financial metrics meet the initial threshold | F37: =IF(F36="Partial","Affordability classification or agreement review remains incomplete","Mission and restriction review is complete") -> Affordability classification or agreement review remains incomplete | I37: =IF(I36="Conditional","Not ready for an external capital-readiness conclusion","Ready for the next controlled review") -> Not ready for an external capital-readiness conclusion
A40: Preliminary result is generated from the loaded canonical data and open quality checks. Do not use externally until source provenance and unresolved flags are reviewed.

Sheet _LISTS
A1: Included_Status | B1: Property_Status | C1: Source_Confidence | D1: Review_Status | E1: Debt_Status | F1: Audit_Status | G1: Assumption_Status | H1: Availability_Status | I1: Yes_No_Unknown | J1: Severity | K1: Agreement_Status | L1: Version_Status | M1: Action_Status | N1: Change_Type | O1: Materiality | P1: Report_Status | Q1: Action_Type
A2: Yes | B2: Active | C2: High | D2: Ready | E2: Ready | F2: PASS | G2: Open | H2: Yes | I2: Yes | J2: Low | K2: Reviewed | L2: Draft | M2: New | N2: New | O2: Low | P2: Draft | Q2: Risk Response
A3: No | B3: New Dev | C3: Medium | D3: From v12 / review | E3: Partial | F3: OPEN | G3: Active | H3: No | I3: No | J3: Medium | K3: Partial | L3: Baseline | M3: Under Review | N3: Changed | O3: Medium | P3: Reviewed | Q3: Management Action
B4: Excluded | C4: Low | D4: From v12 Property Summary | E4: No Debt / N/A | F4: REVIEW | G4: Review | H4: Unknown | I4: Unknown | J4: High | K4: Not reviewed | L4: Verified | M4: Management Action | N4: Material Change | O4: High | P4: Approved | Q4: Board Decision
B5: Future | C5: Conflict | D5: Updated source assumption | E5: Excluded | F5: FAIL | G5: Complete | H5: Partial | L5: Approved | M5: Board Decision Required | N5: No Change | O5: Critical | P5: Shared | Q5: Evidence Request
C6: Formula-linked | D6: Partial | F6: PARTIAL | H6: Conditional | L6: Superseded | M6: In Progress | N6: Removed | P6: Superseded | Q6: Monitoring
C7: Source-linked | D7: Open | M7: Resolved | N7: Conflict
M8: Accepted / Monitor

Sheet MVP_CONTROL
A1: MVP_CONTROL — Stage 1 V2 Settings
A2: Single source for reporting period plus V2 baseline/update behavior. Existing V1 controls remain in place.
A4: Control | B4: Selected Value | C4: Rule / Use
A5: Reporting Fiscal Year | C5: All snapshot financial metrics filter to this fiscal year.
A6: Source Cutoff Date | C6: Latest source models included in the reconciliation.
A7: Currency | B7: CAD | C7: No currency conversion applied.
A8: Operating Cash-Flow Source | C8: Named source that governs annual revenue, operating expenses, reserve trajectory and source net income.
A9: Annual Debt Schedule Source | C9: Named source that governs annual principal, interest and total debt service by fiscal year.
A10: Instrument-Level Debt Detail Source | C10: Named source that governs mortgage balances, rates, amortization, maturity and instrument-level review.
A11: Project / Balance-Sheet Source | C11: Named source that governs project capital stacks, unit/rent assumptions and balance-sheet inputs.
A12: Architecture / Legacy Source | C12: Prior workbook or standard used for architecture and legacy data where not superseded.
A13: Property Count Basis | B13: Portfolio records | C13: State whether the top-line count represents all records, included properties or another controlled scope.
A14: Unit Count Basis | B14: Latest verified source | C14: Use the latest verified unit source; retain conflicts and alternates in ASSUMPTIONS_FLAGS.
